Workbook

Sheet Row data
B1: LK내부 환율 | H1: 할인 적용 목록
B2: 화폐 | C2: 기준 환율 | D2: 추가 환율 | E2: 적용 환율
B3: USD-KIP | C3: 23000 | D3: 1000 | E3: =C3+D3 -> 24000 | H3: 라선협 할인 | N3: 지상사협의회 회원사 할인 | U3: 대표님 지인 할인
B4: USD-THB | C4: 33 | D4: 1 | E4: =C4+D4 -> 34 | H4: 해상 | J4: 항공 | N4: 해상 | P4: 항공 | U4: 해상 | W4: 항공
B5: USD-WON | C5: 1515 | D5: 30 | E5: =C5+D5 -> 1545 | H5: 일반 | I5: 기부 | J5: 일반 | K5: 기부 | N5: 일반 | O5: 기부 | P5: 일반 | Q5: 기부 | U5: 일반 | V5: 기부 | W5: 일반 | X5: 기부
H6: 0.2 | I6: 0.3 | J6: 0.05 | K6: 0.1 | N6: 0.1 | O6: 0.2 | P6: 0.05 | Q6: 0.1 | U6: 5~10% | V6: 0.2 | W6: 0.05 | X6: 0.1
B8: 한국 세금 계산서 발급시 계좌번호 | H8: 이름 | J8: 할인율 | K8: 할인금액 | L8: 비 고 | N8: 이름 | P8: 회사 | Q8: 할인율 | R8: 할인금액 | S8: 비 고 | U8: 이름 | W8: 할인율 | X8: 할인금액 | Y8: 비 고
B9: 경남은행 2070133424601 박성호(엘케이무역) | H9: 강병준 | J9: 0.2 | N9: 강병수 | O9: 법인장 | P9: PNPC | Q9: 0.1 | U9: 김인섭 | V9: 요정 투어 (김요셉 형) | W9: 0.1
H10: 김민기 | J10: 0.2 | N10: 고영태 | O10: 부이사장 | P10: 라오스증권거래소 | Q10: 0.1 | U10: 서정진(서이사님) | W10: 0.1
B11: 일반 입금 | H11: 김반석 | I11: 에즈라 | J11: 0.2 | N11: 고중하 | O11: 대표 | P11: 젤라콘 | Q11: 0.1 | U11: 이형준 | V11: 골재 판매 | W11: 0.1
B12: 경남은행 571-22-0330221 박성호 | H12: 김세진 | J12: 0.2 | N12: 김민우 | O12: 법인장 | P12: DGB 라오 리싱 | Q12: 0.1 | U12: 임홍식 | W12: 0.1
H13: 김영진 | J13: 0.2 | N13: 김윤식 | O13: 법인장 | P13: BNK 캐피탈 라오스 | Q13: 0.1 | U13: 정석진 | W13: 0.1
B14: 중국-라오스 육상 xx항차 | H14: 김재광 | J14: 0.2 | N14: 김일재 | O14: 법인장 | P14: 흥화라오스 | Q14: 0.1 | U14: 진정우 | V14: 105호 고객 | W14: 0.2
B15: Total | C15: =SUM('이름(CLxx-xx)'!R1) -> 1 | H15: 김종한 | J15: 0.2 | N15: 박성호 | O15: 대표 | P15: LK Group | Q15: 0.1 | U15: 최성식 | V15: 큐빅 바이크 | W15: 0.1
B16: Amount | C16: =SUM('이름(CLxx-xx)'!R2) -> 0 | H16: 김지훈 | J16: 0.2 | N16: 백지원 | O16: 센터장 | P16: 라오스 EPS센터 | Q16: 0.1 | U16: 최재혁 | W16: 0.1
H17: 김창수 | J17: 0.2 | L17: 지방배송 | N17: 송대영 | O17: 실장 | P17: DSA(K-LAO) | Q17: 0.1 | U17: 최지호 | W17: 0.1
B18: 총 할인 금액 | C18: =K56+R36+X21+X43+X32 -> 0 | H18: 김필립 | J18: 0.2 | N18: 송창현 | O18: 법인장 | P18: DGB 라오 리싱 | Q18: 0.1 | U18: 최현석 | W18: 0.1
H19: 박정민 | J19: 0.2 | N19: 오유근 | O19: 법인장 | P19: 코웨포-라오 인터내셔널 | Q19: 0.1 | S19: 사모: 김연희
H20: 박종복 | J20: 0.2 | N20: 유병문 | O20: 법인장 | P20: 현진라오 | Q20: 0.1
B21: 현지 발생 비용 | H21: 박진경 | I21: 본죽 | J21: 0.2 | N21: 이범주 | O21: 단장, 전무 | P21: 삼안 | Q21: 0.1 | U21: 할인 총합 | X21: =SUM(X9:X20) -> 0
B22: 날짜 | C22: 내 용 | D22: 킵 | H22: 박창성 | J22: 0.2 | N22: 이성한 | O22: 상무 | P22: 한국종합기술 | Q22: 0.1
B23: 2024.10.10 | H23: 백규현 | I23: 샤론스쿨 | J23: 0.2 | N23: 이시경 | O23: 법인장 | P23: KB 코라오 리싱 | Q23: 0.1
B24: 2024.10.11 | H24: 백대식 | J24: 0.2 | N24: 이재원 | O24: 대표 | P24: 그린굿스 | Q24: 0.1 | U24: 아파트 고객 할인
H25: 백상호 | J25: 0.2 | N25: 이재현 | O25: 법인장 | P25: Paul Golden Lao(좋은차닷컴) | Q25: 0.1 | U25: 이름 | W25: 할인율 | X25: 할인금액 | Y25: 비 고
H26: 백운송 | J26: 0.2 | N26: 이제원 | O26: 법인장 | P26: 웰컴 리싱 라오 | Q26: 0.1 | U26: 이동현 | V26: 101호 고객 | W26: 0.05
H27: 백총명 | J27: 0.2 | N27: 이종원 | O27: 팀장 | P27: KOTRA | Q27: 0.1 | U27: 이효열 | V27: 107호 고객 | W27: 0.05
H28: 변종승 | J28: 0.2 | N28: 이창열 | O28: 부장 | P28: 라오스증권거래소 | Q28: 0.1
D29: =SUM(D23:D28) -> 0 | E29: =D29/C4 -> 0 | H29: 손사랑 | J29: 0.2 | L29: 지방배송 | N29: 이현열 | O29: 지점장 | P29: 에어부산 | Q29: 0.1
H30: 신라함 | J30: 0.2 | N30: 임정민 | O30: 지점장 | P30: 제주항공 | Q30: 0.1
H31: 우상봉 | J31: 0.2 | N31: 정석진 | O31: 지사장 | P31: CJ대한통운 라오스사무소 | Q31: 0.1
B32: 총 합산 액 | C32: =C16-E29 -> 0 | H32: 원순연 | J32: 0.2 | N32: 최완식 | O32: 단장 | P32: 솔루텍시스템 라오 | Q32: 0.1 | U32: 할인 총합 | X32: =SUM(X26:X31) -> 0
H33: 이경희 | J33: 0.2 | L33: 지방배송 | N33: 한태원 | O33: CEO | P33: 엘에스엠 | Q33: 0.1
H34: 이관택 | J34: 0.2 | N34: 황헌기 | O34: 대표 | P34: 정원상사 | Q34: 0.1
H35: 이규상 | J35: 0.2 | U35: 기업 할인
H36: 이명숙/임기환 | J36: 0.2 | N36: 할인 총합 | R36: =SUM(R9:R35) -> 0 | U36: 이름 | V36: 제품 | W36: 할인율 | X36: 할인금액 | Y36: 비 고
H37: 이병목/장헤진 | J37: 0.2 | U37: Love STK | V37: 다단계제품 | W37: 0.1
H38: 이상미 | J38: 0.2 | U38: Nice to meat you | W38: 0.1
H39: 이성원 | J39: 0.2 | U39: Peter Kim/Viengchay | V39: 성경책 | W39: 0.15
H40: 이수정 | J40: 0.2 | U40: 라오스 국가대표 야구 감독 | W40: 0.1 | Y40: 대량 15%, 기부품 20% (사진 첨부 필)
H41: 이영상 | J41: 0.2 | U41: 이우용/임태준 | V41: 유투버 | W41: 0.1 | Y41: 지방배송
...

Sheet 이름(CLxx-xx)
C1: China-Lao Trucking 가견적서 | L1: 번호(No.) | M1: LKCL2026xx-xx | R1: =D11 -> 1 | T1: 화폐 | U1: 기준 환율 | V1: 추가 환율 | W1: 적용 환율
A2: 회사명 | B2: 엘케이(LK)무역 | D2: 도착일 | E2: 2026-XX-XX | I2: 고객명/회사명 // 영수 번호 | L2: 고객 이름 | R2: =N16 -> 0 | T2: USD-KIP | U2: ='Row data'!C3 -> 23000 | V2: 1000 | W2: =U2+V2 -> 24000
A3: 회사 주소 | B3: 비엔티엔시, 씨싿따낙구, 싸판텅 느아 09, 11번 골목, 엘케이(LK) 빌딩, 1층 LK Trading | T3: USD-THB | U3: ='Row data'!C4 -> 33 | V3: 1 | W3: =U3+V3 -> 34
A4: 전화번호 | B4: 020-9112-6780 | I4: 고객 연락처/회사 연락처 | L4: 전화번호 | T4: USD-WON | U4: ='Row data'!C5 -> 1515 | V4: 30 | W4: =U4+V4 -> 1545
A5: No. | B5: 종류 | C5: 단가 | D5: 수량 | E5: 실제중량(Kg) | F5: 실제중량 합산(kg) | G5: 규격 (cm) | J5: 용적 중량(kg) | K5: 용적중량 합산(Kg) | L5: 실제중량 운임 | M5: 용적중량 운임 | N5: 청구중량 운임
A6: 1 | B6: CLxx-xx | C6: 1.2 | D6: 1 | F6: =D6*E6 -> 0 | J6: =(G6*H6*I6)*0.00022 -> 0 | K6: =J6*D6 -> 0 | L6: =(IF(0=F6*C6,0,IF(1.2>=C6*F6,1.2,C6*F6))) -> 0 | M6: =(IF(0=K6*C6,0,IF(1.2>=K6*C6,1.2,K6*C6))) -> 0 | N6: =MAX(L6:M6) -> 0
A7: 2
A8: 3
A9: 4
A10: 5
A11: 합 계 | D11: =SUM(D6:D10) -> 1 | F11: =SUM(F6:F10) -> 0 | K11: =SUM(K6:K10) -> 0
A12: Remark/비 고 | F12: Inland delivery/시내.지방 배송 | L12: 운임 총합 | N12: =SUM(N6:N11) -> 0
A13: - 동 가견적 운임의 중량 및 크기는 단순 예상치이므로 최종 책정 방법인 기준인 실측시 금액 차이가 발생 할수 있으니, 참고용으로만 확인 부탁 드립니다. - 운임은 USD 기준이며, 이외 화폐는 가견적 안내시의 환율 기준이므로, 최종 운임 책정시의 환율변동으로 인한 운임 차이가 발생할수 있으니, 참고용으로만 확인 부탁 드립니다. | L13: 할인 | M13: =IFERROR(MID($A$13,FIND(" "&$L$13&" ",$A$13)+4,3)," ") | N13: =IFERROR(N12*M13,0) -> 0
L14: 특별할인 | M14: =IFERROR(MID($A$13,FIND(" "&$L$14&" ",$A$13)+6,3)," ") | N14: =IFERROR(N12*M14,0) -> 0
L15: 세금 계산서(VAT) | M15: =IFERROR(IF(FIND("세금 계산서",$A$13),10%," ")," ") | N15: =IFERROR((N12-N13-N14)*M15,0) -> 0
L16: 최종 청구 금액 | M16: USD | N16: =(N12-N13-N14+N15) -> 0
M17: KIP | N17: =ROUNDUP((N16*$W$2),-3) -> 0
M18: THB | N18: =ROUNDUP((N16*$W$3),-1) -> 0
M19: WON | N19: =ROUNDUP((N16*$W$4),-2) -> 0
A21: * 모든 비용은 회사의 내규 및 각 물품의 중량/크기 실측을 기준으로 청구되며 최소 운임은 $1.2/kg 입니다.
A22: * 입.출고지를 떠나시기 전 꼭! 고객님 본인 물품 및 개수 확인 부탁 드립니다. 물품이 출고된 이후 LK그룹은 물품의 파손/분실에 대한 어떠한 책임도 없습니다.
A23: * 물품 도착 및 출고 후 특별한 사유 없이 장기 미수취 물품의 경우 보관료등 기타 추가 비용이 발생 할 수 있습니다.
A24: * 물품 출고 후 1주 후부터 보관료(최소 3불/CBM/day)가 발생하며, 특별한 사유 없이 2달 이상 보관 물품들은 임의로 폐기/처분 될 수 있습니다.
A25: 엘케이 (LK)무역 | H25: * 이용해 주셔서 감사합니다. | K25: 고객사 서명
