Workbook

Sheet Row data
B1: LK내부 환율
B2: 화폐 | C2: 기준 환율 | D2: 추가 환율 | E2: 적용 환율
B3: USD-KIP | C3: 23000 | D3: 1000 | E3: =C3+D3 -> 24000
B4: USD-THB | C4: 33 | D4: 1 | E4: =C4+D4 -> 34
B5: USD-WON | C5: 1515 | D5: 30 | E5: =C5+D5 -> 1545
B7: Kg 구간 | C7: 최소값 | D7: 적용 운임
B8: 0~1kg | C8: 0 | D8: =Sheet1!M3 -> 12.4
B9: 2~5kg | C9: 2 | D9: =Sheet1!M6 -> 5.3
B10: 6~9kg | C10: 6 | D10: =Sheet1!M11 -> 3.6
B11: 10~14kg | C11: 10 | D11: =Sheet1!M15 -> 3.6
B12: 15~17kg | C12: 15 | D12: =Sheet1!M20 -> 3.3
B13: 18~20kg | C13: 18 | D13: =Sheet1!M23 -> 3.4
B14: 21~24kg | C14: 21 | D14: =Sheet1!M26 -> 3.5
B15: 25~29kg | C15: 25 | D15: =Sheet1!M30 -> 3.7
B16: 30~34kg | C16: 30 | D16: =Sheet1!M35 -> 3.8
B17: 35~39kg | C17: 35 | D17: =Sheet1!M40 -> 3.9
B18: 40~44kg | C18: 40 | D18: =Sheet1!M45 -> 4
B19: 45kg 이상 | C19: 45 | D19: =Sheet1!M50 -> 4
B22: 한국 세금 계산서 발급시 계좌번호
B23: 경남은행 2070133424601 박성호(엘케이무역)
B25: 일반 입금
B26: 경남은행 571-22-0330221 박성호
B28: 라오스-태국 내륙 xx항차
B29: Total | C29: =SUM('이름(LTxx-xx)'!R1) -> 1
B30: Amount | C30: =SUM('이름(LTxx-xx)'!R2) -> 0
B32: 총 할인 금액 | C32: =#REF!+#REF!+#REF!+#REF! -> #REF!
B35: 현지 발생 비용
B36: 날짜 | C36: 내 용 | D36: 킵
B37: 2024.10.10
B38: 2024.10.11
D41: =SUM(D37:D40) -> 0 | E41: =D41/C4 -> 0
B44: 총 합산 액 | C44: =C30-E41 -> 0

Sheet 수취인 불명 내역
A1: 영수 번호 | B1: 송장 번호 | C1: Remark
A2: LK81 | B2: 5593-8870-9956 | C2: 김인규??
A3: LK82 | B3: 10-2664-5564-6053, 382-7242-2753
A4: LK83 | B4: 5903-7235-0543, 5903-7199-0220
A5: LK84 | B5: 66597-0117-4099 | C5: 이우용??
A6: LK85 | B6: 6856-8748-0750
A7: LK86 | B7: 66017-0128-0372
A8: LK87 | B8: 65689-0106-6533
A9: LK88 | B9: 5796-5801-8672 | C9: 송인호 고객물류로 추정됨 / 박주유 님이 한국에서 보내신 물건으로 추정
A10: LK89 | B10: 5909-8013-8342 | C10: 폼마린??
A11: LK90 | B11: 65129-0112-6372
A12: LK91 | B12: 64134-0322-0901, 64134-0322-0902 | C12: 박주유
A13: LK92 | B13: 6105072440050, 4107032440085, 3132212443441
A14: LK93 | B14: 10-2672-2107-9721, 10-2672-2107-9964, 10-2672-2107-5613, 10-2672-2107-8553, 10-2672-2107-5731 | C14: 박환영??
B15: 2601-402-015153
A16: LK94 | B16: 2484-9497-0570
A17: LK95 | B17: 3647-7561-7276

Sheet 이름(LTxx-xx)
C1: Lao-Thai Trucking 거래 명세서 | L1: 번호(No.) | M1: LKLT2026xx-xx | R1: =D11 -> 1 | T1: 화폐 | U1: 기준 환율 | V1: 추가 환율 | W1: 적용 환율
A2: 회사명 | B2: 엘케이(LK)무역 | D2: 도착일 | E2: 2026-XX-XX | I2: 고객명/회사명 // 영수 번호 | L2: 고객이름 | R2: =N16 -> 0 | T2: USD-KIP | U2: ='Row data'!C3 -> 23000 | V2: 1000 | W2: =U2+V2 -> 24000
A3: 회사 주소 | B3: 비엔티엔시, 씨싿따낙구, 싸판텅 느아 09, 11번 골목, 엘케이(LK) 빌딩, 1층 LK Trading | T3: USD-THB | U3: ='Row data'!C4 -> 33 | V3: 1 | W3: =U3+V3 -> 34
A4: 전화번호 | B4: 020-9112-6780 | I4: 고객 연락처/회사 연락처 | L4: 전화번호 | T4: USD-WON | U4: ='Row data'!C5 -> 1515 | V4: 30 | W4: =U4+V4 -> 1545
A5: No. | B5: 종류 | C5: 단가 | D5: 수량 | E5: 실제중량(Kg) | F5: 실제중량 합산(kg) | G5: 규격 (cm) | J5: 용적 중량(kg) | K5: 용적중량 합산(Kg) | L5: 실제중량 운임 | M5: 용적중량 운임 | N5: 청구중량 운임
A6: 1 | B6: LT01-01 | C6: =VLOOKUP(MAX(E6,J6),'Row data'!$C$8:$D$19,2,TRUE) -> 12.4 | D6: 1 | F6: =E6*D6 -> 0 | J6: =(G6*H6*I6)*0.00022 -> 0 | K6: =J6*D6 -> 0 | L6: =(IF(0=F6*C6,0,IF('Row data'!$D$8>=C6*F6,'Row data'!$D$8,C6*F6))) -> 0 | M6: =(IF(0=K6*C6,0,IF('Row data'!$D$8>=K6*C6,'Row data'!$D$8,K6*C6))) -> 0 | N6: =MAX(L6:M6) -> 0
A7: 2 | R7: =1800000 -> 1800000
A8: 3 | R8: =R7/26000 -> 69.230769
A9: 4
A10: 5
A11: 합 계 | D11: =SUM(D6:D10) -> 1 | F11: =SUM(F6:F10) -> 0 | K11: =SUM(K6:K10) -> 0
A12: Remark/비 고 | F12: Inland delivery/시내.지방 배송 | L12: 운임 총합 | N12: =SUM(N6:N11) -> 0
L13: 할인 | M13: =IFERROR(MID($A$13,FIND(" "&$L$13&" ",$A$13)+4,3)," ") | N13: =IFERROR(N12*M13,0) -> 0
L14: 특별할인 | M14: =IFERROR(MID($A$13,FIND(" "&$L$14&" ",$A$13)+6,3)," ") | N14: =IFERROR(N12*M14,0) -> 0
L15: 세금 계산서(VAT) | M15: =IFERROR(IF(FIND("세금 계산서",$A$13),10%," ")," ") | N15: =IFERROR((N12-N13-N14)*M15,0) -> 0
L16: 최종 청구 금액 | M16: USD | N16: =(N12-N13-N14+N15) -> 0
M17: KIP | N17: =ROUNDUP((N16*$W$2),-3) -> 0
M18: THB | N18: =ROUNDUP((N16*$W$3),-1) -> 0
M19: WON | N19: =ROUNDUP((N16*$W$4),-2) -> 0
A21: * 모든 비용은 회사의 내규 및 각 물품의 중량/크기 실측을 기준으로 청구되며 최소 운임은 $10/kg 이며, 청구중량에 따라 차등 운임이 적용 됩니다.
A22: * 이용해 주셔서 감사합니다.
A24: 엘케이 (LK)무역 | K24: 고객사 서명

Sheet Sheet1
A1: PSV | C1: 34 | E1: 1.35 | G1: JJ | I1: 32 | K1: 1.35 | O1: TSC | Q1: 32 | S1: 1.35
A2: KG | B2: Rate(THB) | C2: Rate(USD) | D2: per kg(USD) | G2: KG | H2: Rate(THB) | I2: Rate(USD) | J2: per kg(USD) | O2: KG | P2: Rate(THB) | Q2: Rate(USD) | R2: per kg(USD)
A3: 0.5 | B3: 130 | C3: =B3/$C$1 -> 3.8235294 | D3: =C3/A3 -> 7.6470588 | E3: =D3*$E$1 -> 10.323529 | G3: 0.5 | H3: 230 | I3: =H3/$I$1 -> 7.1875 | J3: =I3/G3 -> 14.375 | K3: =J3*$K$1 -> 19.40625 | L3: =(K3+K4+K5)/3 -> 12.375 | M3: =ROUNDUP(L3,1) -> 12.4 | O3: 1 | P3: 355 | Q3: =P3/$Q$1 -> 11.09375 | R3: =Q3/O3 -> 11.09375 | S3: =R3*$S$1 -> 14.976563 | T3: =S3 -> 14.976563 | U3: =ROUNDUP(T3,1) -> 15
A4: 1 | B4: 150 | C4: =B4/$C$1 -> 4.4117647 | D4: =C4/A4 -> 4.4117647 | E4: =D4*$E$1 -> 5.9558824 | G4: 1 | H4: 240 | I4: =H4/$I$1 -> 7.5 | J4: =I4/G4 -> 7.5 | K4: =J4*$K$1 -> 10.125 | O4: 2 | P4: 420 | Q4: =P4/$Q$1 -> 13.125 | R4: =Q4/O4 -> 6.5625 | S4: =R4*$S$1 -> 8.859375 | T4: =S4 -> 8.859375 | U4: =ROUNDUP(T4,1) -> 8.9
A5: 1.5 | B5: 180 | C5: =B5/$C$1 -> 5.2941176 | D5: =C5/A5 -> 3.5294118 | E5: =D5*$E$1 -> 4.7647059 | G5: 1.5 | H5: 270 | I5: =H5/$I$1 -> 8.4375 | J5: =I5/G5 -> 5.625 | K5: =J5*$K$1 -> 7.59375 | O5: 3 | P5: 485 | Q5: =P5/$Q$1 -> 15.15625 | R5: =Q5/O5 -> 5.0520833 | S5: =R5*$S$1 -> 6.8203125 | T5: =S5 -> 6.8203125 | U5: =ROUNDUP(T5,1) -> 6.9
A6: 2 | B6: 210 | C6: =B6/$C$1 -> 6.1764706 | D6: =C6/A6 -> 3.0882353 | E6: =D6*$E$1 -> 4.1691176 | G6: 2 | H6: 330 | I6: =H6/$I$1 -> 10.3125 | J6: =I6/G6 -> 5.15625 | K6: =J6*$K$1 -> 6.9609375 | L6: =(K6+K7+K8+K9+K10)/5 -> 5.2832812 | M6: =ROUNDUP(L6,1) -> 5.3 | O6: 4 | P6: 550 | Q6: =P6/$Q$1 -> 17.1875 | R6: =Q6/O6 -> 4.296875 | S6: =R6*$S$1 -> 5.8007812 | T6: =(S6+S7)/2 -> 5.4949219 | U6: =ROUNDUP(T6,1) -> 5.5
A7: 2.5 | B7: 240 | C7: =B7/$C$1 -> 7.0588235 | D7: =C7/A7 -> 2.8235294 | E7: =D7*$E$1 -> 3.8117647 | G7: 2.5 | H7: 350 | I7: =H7/$I$1 -> 10.9375 | J7: =I7/G7 -> 4.375 | K7: =J7*$K$1 -> 5.90625 | O7: 5 | P7: 615 | Q7: =P7/$Q$1 -> 19.21875 | R7: =Q7/O7 -> 3.84375 | S7: =R7*$S$1 -> 5.1890625 | U7: =ROUNDUP(T7,1) -> 0
A8: 3 | B8: 260 | C8: =B8/$C$1 -> 7.6470588 | D8: =C8/A8 -> 2.5490196 | E8: =D8*$E$1 -> 3.4411765 | G8: 3 | H8: 380 | I8: =H8/$I$1 -> 11.875 | J8: =I8/G8 -> 3.9583333 | K8: =J8*$K$1 -> 5.34375 | O8: 6 | P8: 680 | Q8: =P8/$Q$1 -> 21.25 | R8: =Q8/O8 -> 3.5416667 | S8: =R8*$S$1 -> 4.78125 | T8: =(S8+S9+S10+S11)/4 -> 4.4110631 | U8: =ROUNDUP(T8,1) -> 4.5
A9: 4 | B9: 290 | C9: =B9/$C$1 -> 8.5294118 | D9: =C9/A9 -> 2.1323529 | E9: =D9*$E$1 -> 2.8786765 | G9: 4 | H9: 410 | I9: =H9/$I$1 -> 12.8125 | J9: =I9/G9 -> 3.203125 | K9: =J9*$K$1 -> 4.3242188 | O9: 7 | P9: 745 | Q9: =P9/$Q$1 -> 23.28125 | R9: =Q9/O9 -> 3.3258929 | S9: =R9*$S$1 -> 4.4899554 | U9: =ROUNDUP(T9,1) -> 0
A10: 5 | B10: 330 | C10: =B10/$C$1 -> 9.7058824 | D10: =C10/A10 -> 1.9411765 | E10: =D10*$E$1 -> 2.6205882 | G10: 5 | H10: 460 | I10: =H10/$I$1 -> 14.375 | J10: =I10/G10 -> 2.875 | K10: =J10*$K$1 -> 3.88125 | O10: 8 | P10: 810 | Q10: =P10/$Q$1 -> 25.3125 | R10: =Q10/O10 -> 3.1640625 | S10: =R10*$S$1 -> 4.2714844 | U10: =ROUNDUP(T10,1) -> 0
A11: 6 | B11: 390 | C11: =B11/$C$1 -> 11.470588 | D11: =C11/A11 -> 1.9117647 | E11: =D11*$E$1 -> 2.5808824 | G11: 6 | H11: 510 | I11: =H11/$I$1 -> 15.9375 | J11: =I11/G11 -> 2.65625 | K11: =J11*$K$1 -> 3.5859375 | L11: =(K11+K12+K13+K14)/4 -> 3.5807059 | M11: =ROUNDUP(L11,1) -> 3.6 | O11: 9 | P11: 875 | Q11: =P11/$Q$1 -> 27.34375 | R11: =Q11/O11 -> 3.0381944 | S11: =R11*$S$1 -> 4.1015625 | U11: =ROUNDUP(T11,1) -> 0
A12: 7 | B12: 450 | C12: =B12/$C$1 -> 13.235294 | D12: =C12/A12 -> 1.8907563 | E12: =D12*$E$1 -> 2.552521 | G12: 7 | H12: 610 | I12: =H12/$I$1 -> 19.0625 | J12: =I12/G12 -> 2.7232143 | K12: =J12*$K$1 -> 3.6763393 | O12: 10 | P12: 940 | Q12: =P12/$Q$1 -> 29.375 | R12: =Q12/O12 -> 2.9375 | S12: =R12*$S$1 -> 3.965625 | T12: =(S12+S13+S14+S15+S16)/5 -> 3.7762224 | U12: =ROUNDUP(T12,1) -> 3.8
A13: 8 | B13: 500 | C13: =B13/$C$1 -> 14.705882 | D13: =C13/A13 -> 1.8382353 | E13: =D13*$E$1 -> 2.4816176 | G13: 8 | H13: 690 | I13: =H13/$I$1 -> 21.5625 | J13: =I13/G13 -> 2.6953125 | K13: =J13*$K$1 -> 3.6386719 | O13: 11 | P13: 1005 | Q13: =P13/$Q$1 -> 31.40625 | R13: =Q13/O13 -> 2.8551136 | S13: =R13*$S$1 -> 3.8544034 | U13: =ROUNDUP(T13,1) -> 0
A14: 9 | B14: 550 | C14: =B14/$C$1 -> 16.176471 | D14: =C14/A14 -> 1.7973856 | E14: =D14*$E$1 -> 2.4264706 | G14: 9 | H14: 730 | I14: =H14/$I$1 -> 22.8125 | J14: =I14/G14 -> 2.5347222 | K14: =J14*$K$1 -> 3.421875 | O14: 12 | P14: 1070 | Q14: =P14/$Q$1 -> 33.4375 | R14: =Q14/O14 -> 2.7864583 | S14: =R14*$S$1 -> 3.7617188 | U14: =ROUNDUP(T14,1) -> 0
A15: 10 | B15: 600 | C15: =B15/$C$1 -> 17.647059 | D15: =C15/A15 -> 1.7647059 | E15: =D15*$E$1 -> 2.3823529 | G15: 10 | H15: 840 | I15: =H15/$I$1 -> 26.25 | J15: =I15/G15 -> 2.625 | K15: =J15*$K$1 -> 3.54375 | L15: =(K15+K16+K17+K18+K19)/5 -> 3.5049327 | M15: =ROUNDUP(L15,1) -> 3.6 | O15: 13 | P15: 1135 | Q15: =P15/$Q$1 -> 35.46875 | R15: =Q15/O15 -> 2.7283654 | S15: =R15*$S$1 -> 3.6832933 | U15: =ROUNDUP(T15,1) -> 0
A16: 11 | B16: 660 | C16: =B16/$C$1 -> 19.411765 | D16: =C16/A16 -> 1.7647059 | E16: =D16*$E$1 -> 2.3823529 | G16: 11 | H16: 910 | I16: =H16/$I$1 -> 28.4375 | J16: =I16/G16 -> 2.5852273 | K16: =J16*$K$1 -> 3.4900568 | O16: 14 | P16: 1200 | Q16: =P16/$Q$1 -> 37.5 | R16: =Q16/O16 -> 2.6785714 | S16: =R16*$S$1 -> 3.6160714 | U16: =ROUNDUP(T16,1) -> 0
A17: 12 | B17: 710 | C17: =B17/$C$1 -> 20.882353 | D17: =C17/A17 -> 1.7401961 | E17: =D17*$E$1 -> 2.3492647 | G17: 12 | H17: 1010 | I17: =H17/$I$1 -> 31.5625 | J17: =I17/G17 -> 2.6302083 | K17: =J17*$K$1 -> 3.5507813 | O17: 15 | P17: 1265 | Q17: =P17/$Q$1 -> 39.53125 | R17: =Q17/O17 -> 2.6354167 | S17: =R17*$S$1 -> 3.5578125 | T17: =(S17+S18+S19+S20+S21)/5 -> 3.4668964 | U17: =ROUNDUP(T17,1) -> 3.5
A18: 13 | B18: 780 | C18: =B18/$C$1 -> 22.941176 | D18: =C18/A18 -> 1.7647059 | E18: =D18*$E$1 -> 2.3823529 | G18: 13 | H18: 1080 | I18: =H18/$I$1 -> 33.75 | J18: =I18/G18 -> 2.5961538 | K18: =J18*$K$1 -> 3.5048077 | O18: 16 | P18: 1330 | Q18: =P18/$Q$1 -> 41.5625 | R18: =Q18/O18 -> 2.5976562 | S18: =R18*$S$1 -> 3.5068359 | U18: =ROUNDUP(T18,1) -> 0
A19: 14 | B19: 830 | C19: =B19/$C$1 -> 24.411765 | D19: =C19/A19 -> 1.7436975 | E19: =D19*$E$1 -> 2.3539916 | G19: 14 | H19: 1140 | I19: =H19/$I$1 -> 35.625 | J19: =I19/G19 -> 2.5446429 | K19: =J19*$K$1 -> 3.4352679 | O19: 17 | P19: 1395 | Q19: =P19/$Q$1 -> 43.59375 | R19: =Q19/O19 -> 2.5643382 | S19: =R19*$S$1 -> 3.4618566 | U19: =ROUNDUP(T19,1) -> 0
A20: 15 | B20: 890 | C20: =B20/$C$1 -> 26.176471 | D20: =C20/A20 -> 1.745098 | E20: =D20*$E$1 -> 2.3558824 | G20: 15 | H20: 1190 | I20: =H20/$I$1 -> 37.1875 | J20: =I20/G20 -> 2.4791667 | K20: =J20*$K$1 -> 3.346875 | L20: =(K20+K21+K22)/3 -> 3.2627413 | M20: =ROUNDUP(L20,1) -> 3.3 | O20: 18 | P20: 1460 | Q20: =P20/$Q$1 -> 45.625 | R20: =Q20/O20 -> 2.5347222 | S20: =R20*$S$1 -> 3.421875 | U20: =ROUNDUP(T20,1) -> 0
A21: 16 | B21: 940 | C21: =B21/$C$1 -> 27.647059 | D21: =C21/A21 -> 1.7279412 | E21: =D21*$E$1 -> 2.3327206 | G21: 16 | H21: 1210 | I21: =H21/$I$1 -> 37.8125 | J21: =I21/G21 -> 2.3632812 | K21: =J21*$K$1 -> 3.1904297 | O21: 19 | P21: 1525 | Q21: =P21/$Q$1 -> 47.65625 | R21: =Q21/O21 -> 2.5082237 | S21: =R21*$S$1 -> 3.386102 | U21: =ROUNDUP(T21,1) -> 0
A22: 17 | B22: 1000 | C22: =B22/$C$1 -> 29.411765 | D22: =C22/A22 -> 1.7301038 | E22: =D22*$E$1 -> 2.3356401 | G22: 17 | H22: 1310 | I22: =H22/$I$1 -> 40.9375 | J22: =I22/G22 -> 2.4080882 | K22: =J22*$K$1 -> 3.2509191 | O22: 20 | P22: 1590 | Q22: =P22/$Q$1 -> 49.6875 | R22: =Q22/O22 -> 2.484375 | S22: =R22*$S$1 -> 3.3539063 | T22: =S22 -> 3.3539063 | U22: =ROUNDUP(T22,1) -> 3.4
A23: 18 | B23: 1050 | C23: =B23/$C$1 -> 30.882353 | D23: =C23/A23 -> 1.7156863 | E23: =D23*$E$1 -> 2.3161765 | G23: 18 | H23: 1410 | I23: =H23/$I$1 -> 44.0625 | J23: =I23/G23 -> 2.4479167 | K23: =J23*$K$1 -> 3.3046875 | L23: =(K23+K24+K25)/3 -> 3.3511924 | M23: =ROUNDUP(L23,1) -> 3.4
A24: 19 | B24: 1110 | C24: =B24/$C$1 -> 32.647059 | D24: =C24/A24 -> 1.7182663 | E24: =D24*$E$1 -> 2.3196594 | G24: 19 | H24: 1510 | I24: =H24/$I$1 -> 47.1875 | J24: =I24/G24 -> 2.4835526 | K24: =J24*$K$1 -> 3.3527961 | O24: 50 | P24: 70 | Q24: =P24/$Q$1 -> 2.1875 | S24: =Q24*$S$1 -> 2.953125
A25: 20 | B25: 1160 | C25: =B25/$C$1 -> 34.117647 | D25: =C25/A25 -> 1.7058824 | E25: =D25*$E$1 -> 2.3029412 | G25: 20 | H25: 1610 | I25: =H25/$I$1 -> 50.3125 | J25: =I25/G25 -> 2.515625 | K25: =J25*$K$1 -> 3.3960938
A26: 21 | B26: 1220 | C26: =B26/$C$1 -> 35.882353 | D26: =C26/A26 -> 1.7086835 | E26: =D26*$E$1 -> 2.3067227 | G26: 21 | H26: 1710 | I26: =H26/$I$1 -> 53.4375 | J26: =I26/G26 -> 2.5446429 | K26: =J26*$K$1 -> 3.4352679 | L26: =(K26+K27+K28+K29)/4 -> 3.4856871 | M26: =ROUNDUP(L26,1) -> 3.5
A27: 22 | B27: 1270 | C27: =B27/$C$1 -> 37.352941 | D27: =C27/A27 -> 1.697861 | E27: =D27*$E$1 -> 2.2921123 | G27: 22 | H27: 1810 | I27: =H27/$I$1 -> 56.5625 | J27: =I27/G27 -> 2.5710227 | K27: =J27*$K$1 -> 3.4708807
A28: 23 | B28: 1330 | C28: =B28/$C$1 -> 39.117647 | D28: =C28/A28 -> 1.7007673 | E28: =D28*$E$1 -> 2.2960358 | G28: 23 | H28: 1910 | I28: =H28/$I$1 -> 59.6875 | J28: =I28/G28 -> 2.5951087 | K28: =J28*$K$1 -> 3.5033967
A29: 24 | B29: 1390 | C29: =B29/$C$1 -> 40.882353 | D29: =C29/A29 -> 1.7034314 | E29: =D29*$E$1 -> 2.2996324 | G29: 24 | H29: 2010 | I29: =H29/$I$1 -> 62.8125 | J29: =I29/G29 -> 2.6171875 | K29: =J29*$K$1 -> 3.5332031
A30: 25 | B30: 1450 | C30: =B30/$C$1 -> 42.647059 | D30: =C30/A30 -> 1.7058824 | E30: =D30*$E$1 -> 2.3029412 | G30: 25 | H30: 2110 | I30: =H30/$I$1 -> 65.9375 | J30: =I30/G30 -> 2.6375 | K30: =J30*$K$1 -> 3.560625 | L30: =(K30+K31+K32+K33+K34)/5 -> 3.6044502 | M30: =ROUNDUP(L30,1) -> 3.7
A31: 26 | C31: =B31/$C$1 -> 0 | D31: =C31/A31 -> 0 | E31: =D31*$E$1 -> 0 | G31: 26 | H31: 2200 | I31: =H31/$I$1 -> 68.75 | J31: =I31/G31 -> 2.6442308 | K31: =J31*$K$1 -> 3.5697115
A32: 27 | C32: =B32/$C$1 -> 0 | D32: =C32/A32 -> 0 | E32: =D32*$E$1 -> 0 | G32: 27 | H32: 2310 | I32: =H32/$I$1 -> 72.1875 | J32: =I32/G32 -> 2.6736111 | K32: =J32*$K$1 -> 3.609375
A33: 28 | C33: =B33/$C$1 -> 0 | D33: =C33/A33 -> 0 | E33: =D33*$E$1 -> 0 | G33: 28 | H33: 2410 | I33: =H33/$I$1 -> 75.3125 | J33: =I33/G33 -> 2.6897321 | K33: =J33*$K$1 -> 3.6311384
A34: 29 | C34: =B34/$C$1 -> 0 | D34: =C34/A34 -> 0 | E34: =D34*$E$1 -> 0 | G34: 29 | H34: 2510 | I34: =H34/$I$1 -> 78.4375 | J34: =I34/G34 -> 2.7047414 | K34: =J34*$K$1 -> 3.6514009
A35: 30 | C35: =B35/$C$1 -> 0 | D35: =C35/A35 -> 0 | E35: =D35*$E$1 -> 0 | G35: 30 | H35: 2610 | I35: =H35/$I$1 -> 81.5625 | J35: =I35/G35 -> 2.71875 | K35: =J35*$K$1 -> 3.6703125 | L35: =(K35+K36+K37+K38+K39)/5 -> 3.7539666 | M35: =ROUNDUP(L35,1) -> 3.8
A36: 31 | C36: =B36/$C$1 -> 0 | D36: =C36/A36 -> 0 | E36: =D36*$E$1 -> 0 | G36: 31 | H36: 2710 | I36: =H36/$I$1 -> 84.6875 | J36: =I36/G36 -> 2.7318548 | K36: =J36*$K$1 -> 3.688004
A37: 32 | C37: =B37/$C$1 -> 0 | D37: =C37/A37 -> 0 | E37: =D37*$E$1 -> 0 | G37: 32 | H37: 2810 | I37: =H37/$I$1 -> 87.8125 | J37: =I37/G37 -> 2.7441406 | K37: =J37*$K$1 -> 3.7045898
A38: 33 | C38: =B38/$C$1 -> 0 | D38: =C38/A38 -> 0 | E38: =D38*$E$1 -> 0 | G38: 33 | H38: 3010 | I38: =H38/$I$1 -> 94.0625 | J38: =I38/G38 -> 2.8503788 | K38: =J38*$K$1 -> 3.8480114
A39: 34 | C39: =B39/$C$1 -> 0 | D39: =C39/A39 -> 0 | E39: =D39*$E$1 -> 0 | G39: 34 | H39: 3110 | I39: =H39/$I$1 -> 97.1875 | J39: =I39/G39 -> 2.8584559 | K39: =J39*$K$1 -> 3.8589154
A40: 35 | C40: =B40/$C$1 -> 0 | D40: =C40/A40 -> 0 | E40: =D40*$E$1 -> 0 | G40: 35 | H40: 3210 | I40: =H40/$I$1 -> 100.3125 | J40: =I40/G40 -> 2.8660714 | K40: =J40*$K$1 -> 3.8691964 | L40: =(K40+K41+K42+K43+K44)/5 -> 3.8853265 | M40: =ROUNDUP(L40,1) -> 3.9
...

Sheet Sheet2
A1: Kg 구간 | B1: 적용 운임
A2: 0~1kg | B2: 12.4
A3: 2~5kg | B3: 5.3
A4: 6~9kg | B4: 3.6
A5: 10~14kg | B5: 3.6
A6: 15~17kg | B6: 3.3
A7: 18~20kg | B7: 3.4
A8: 21~24kg | B8: 3.5
A9: 25~29kg | B9: 3.7
A10: 30~34kg | B10: 3.8
A11: 35~39kg | B11: 3.9
A12: 40~44kg | B12: 4
A13: 45kg 이상 | B13: 4
