Workbook

Sheet Row data
B1: LK내부 환율 | H1: 할인 적용 목록
B2: 화폐 | C2: 기준 환율 | D2: 추가 환율 | E2: 적용 환율
B3: USD-KIP | C3: 23000 | D3: 1000 | E3: =C3+D3 -> 24000 | H3: 라선협 할인 | N3: 지상사협의회 회원사 할인 | U3: 대표님 지인 할인
B4: USD-THB | C4: 33 | D4: 1 | E4: =C4+D4 -> 34 | H4: 해상 | J4: 항공 | N4: 해상 | P4: 항공 | U4: 해상 | W4: 항공
B5: USD-WON | C5: 1515 | D5: 30 | E5: =C5+D5 -> 1545 | H5: 일반 | I5: 기부 | J5: 일반 | K5: 기부 | N5: 일반 | O5: 기부 | P5: 일반 | Q5: 기부 | U5: 일반 | V5: 기부 | W5: 일반 | X5: 기부
H6: 0.2 | I6: 0.3 | J6: 0.05 | K6: 0.1 | N6: 0.1 | O6: 0.2 | P6: 0.05 | Q6: 0.1 | U6: 5~10% | V6: 0.2 | W6: 0.05 | X6: 0.1
B7: Kg 구간 | C7: 최소값 | D7: 적용 운임
B8: 0~1kg | C8: 0 | D8: 4 | H8: 이름 | J8: 할인율 | K8: 할인금액 | L8: 비 고 | N8: 이름 | P8: 회사 | Q8: 할인율 | R8: 할인금액 | S8: 비 고 | U8: 이름 | W8: 할인율 | X8: 할인금액 | Y8: 비 고
B9: 2~5kg | C9: 2 | D9: 2.5 | H9: 강병준 | J9: 0.05 | N9: 강병수 | O9: 법인장 | P9: PNPC | Q9: 0.05 | U9: 김인섭 | V9: 요정 투어 (김요셉 형) | W9: 0.05
B10: 6~9kg | C10: 6 | D10: 1.5 | H10: 김민기 | J10: 0.05 | N10: 고영태 | O10: 부이사장 | P10: 라오스증권거래소 | Q10: 0.05 | U10: 서정진(서이사님) | W10: 0.05
B11: 10~14kg | C11: 10 | D11: 1.25 | H11: 김반석 | I11: 에즈라 | J11: 0.05 | N11: 고중하 | O11: 대표 | P11: 젤라콘 | Q11: 0.05 | U11: 이형준 | V11: 골재 판매 | W11: 0.05
B12: 15~17kg | C12: 15 | D12: 1.15 | H12: 김세진 | J12: 0.05 | N12: 김민우 | O12: 법인장 | P12: DGB 라오 리싱 | Q12: 0.05 | U12: 임홍식 | W12: 0.05
B13: 18~20kg | C13: 18 | D13: 1.13 | H13: 김영진 | J13: 0.05 | N13: 김윤식 | O13: 법인장 | P13: BNK 캐피탈 라오스 | Q13: 0.05 | U13: 정석진 | W13: 0.05
B14: 21kg 이상 | C14: 21 | D14: 1.1 | H14: 김재광 | J14: 0.05 | N14: 김일재 | O14: 법인장 | P14: 흥화라오스 | Q14: 0.05 | U14: 진정우 | V14: 105호 고객 | W14: 0.1 | Y14: 기부
H15: 김종한 | J15: 0.05 | N15: 박성호 | O15: 대표 | P15: LK Group | Q15: 0.05 | U15: 최성식 | V15: 큐빅 바이크 | W15: 0.05
H16: 김종훈/김희영 | J16: 0.05 | N16: 백지원 | O16: 센터장 | P16: 라오스 EPS센터 | Q16: 0.05 | U16: 최재혁 | W16: 0.05
B17: 한국 세금 계산서 발급시 계좌번호 | H17: 김지훈 | J17: 0.05 | N17: 송대영 | O17: 실장 | P17: DSA(K-LAO) | Q17: 0.05 | U17: 최지호 | W17: 0.05
B18: 경남은행 2070133424601 박성호(엘케이무역) | H18: 김창수 | J18: 0.05 | L18: 지방배송 | N18: 송창현 | O18: 법인장 | P18: DGB 라오 리싱 | Q18: 0.05 | U18: 최현석 | W18: 0.05
H19: 김필립 | J19: 0.05 | N19: 오유근 | O19: 법인장 | P19: 코웨포-라오 인터내셔널 | Q19: 0.05 | S19: 사모: 김연희
B20: 일반 입금 | H20: 박정민 | J20: 0.05 | N20: 유병문 | O20: 법인장 | P20: 현진라오 | Q20: 0.05
B21: 경남은행 571-22-0330221 박성호 | H21: 박종복 | J21: 0.05 | N21: 이범주 | O21: 단장, 전무 | P21: 삼안 | Q21: 0.05 | U21: 할인 총합 | X21: =SUM(X9:X20) -> 0
H22: 박진경 | I22: 본죽 | J22: 0.05 | N22: 이성한 | O22: 상무 | P22: 한국종합기술 | Q22: 0.05
B23: 태국-라오스 내륙 xx항차 | H23: 박창성 | J23: 0.05 | N23: 이시경 | O23: 법인장 | P23: KB 코라오 리싱 | Q23: 0.05
B24: Total | C24: =SUM('이름(TLxx-xx)'!R1) -> 1 | H24: 백규현 | I24: 샤론스쿨 | J24: 0.05 | N24: 이재원 | O24: 대표 | P24: 그린굿스 | Q24: 0.05 | U24: 기업 할인
B25: Amount | C25: =SUM('이름(TLxx-xx)'!R2) -> 0 | H25: 백대식 | J25: 0.05 | N25: 이재현 | O25: 법인장 | P25: Paul Golden Lao(좋은차닷컴) | Q25: 0.05 | U25: 이름 | V25: 제품 | W25: 할인율 | X25: 할인금액 | Y25: 비 고
H26: 백상호 | J26: 0.05 | N26: 이제원 | O26: 법인장 | P26: 웰컴 리싱 라오 | Q26: 0.05 | U26: Love STK | V26: 다단계제품 | W26: 0.05
B27: 총 할인 금액 | C27: =K59+R36+X21+X32 -> 0 | H27: 백운송 | J27: 0.05 | N27: 이종원 | O27: 팀장 | P27: KOTRA | Q27: 0.05 | U27: Nice to meat you | W27: 0.05
H28: 백총명 | J28: 0.05 | N28: 이창열 | O28: 부장 | P28: 라오스증권거래소 | Q28: 0.05 | U28: Peter Kim/Viengchay | V28: 성경책 | W28: 0.05
H29: 변종승 | J29: 0.05 | N29: 이현열 | O29: 지점장 | P29: 에어부산 | Q29: 0.05 | U29: 라오스 국가대표 야구 감독 | W29: 0.05 | Y29: 대량 5%, 기부품 10% (사진 첨부 필)
B30: 현지 발생 비용 | H30: 손사랑 | J30: 0.05 | L30: 지방배송 | N30: 임정민 | O30: 지점장 | P30: 제주항공 | Q30: 0.05 | U30: 이우용/임태준 | V30: 유투버 | W30: 0.05 | Y30: 지방배송
B31: 날짜 | C31: 내 용 | D31: 킵 | H31: 신라함 | J31: 0.05 | N31: 정석진 | O31: 지사장 | P31: CJ대한통운 라오스사무소 | Q31: 0.05
B32: 2024.10.10 | H32: 우상봉 | J32: 0.05 | N32: 최완식 | O32: 단장 | P32: 솔루텍시스템 라오 | Q32: 0.05 | U32: 할인 총합 | X32: =SUM(X26:X31) -> 0
B33: 2024.10.11 | H33: 원순연 | J33: 0.05 | N33: 한태원 | O33: CEO | P33: 엘에스엠 | Q33: 0.05
H34: 이경희 | J34: 0.05 | L34: 지방배송 | N34: 황헌기 | O34: 대표 | P34: 정원상사 | Q34: 0.05
H35: 이관택 | J35: 0.05
D36: =SUM(D32:D35) -> 0 | E36: =D36/C4 -> 0 | H36: 이규상 | J36: 0.05 | N36: 할인 총합 | R36: =SUM(R9:R35) -> 0
H37: 이명숙/임기환 | J37: 0.05
H38: 이병목/장헤진 | J38: 0.05
B39: 총 합산 액 | C39: =C25-E36 -> 0 | H39: 이상미 | J39: 0.05
H40: 이성원 | J40: 0.05
...

Sheet 수취인 불명 내역
A1: 영수 번호 | B1: 송장 번호 | C1: Remark
A2: LK81 | B2: 5593-8870-9956 | C2: 김인규??
A3: LK82 | B3: 10-2664-5564-6053, 382-7242-2753
A4: LK83 | B4: 5903-7235-0543, 5903-7199-0220
A5: LK84 | B5: 66597-0117-4099 | C5: 이우용??
A6: LK85 | B6: 6856-8748-0750
A7: LK86 | B7: 66017-0128-0372
A8: LK87 | B8: 65689-0106-6533
A9: LK88 | B9: 5796-5801-8672 | C9: 송인호 고객물류로 추정됨 / 박주유 님이 한국에서 보내신 물건으로 추정
A10: LK89 | B10: 5909-8013-8342 | C10: 폼마린??
A11: LK90 | B11: 65129-0112-6372
A12: LK91 | B12: 64134-0322-0901, 64134-0322-0902 | C12: 박주유
A13: LK92 | B13: 6105072440050, 4107032440085, 3132212443441
A14: LK93 | B14: 10-2672-2107-9721, 10-2672-2107-9964, 10-2672-2107-5613, 10-2672-2107-8553, 10-2672-2107-5731 | C14: 박환영??
B15: 2601-402-015153
A16: LK94 | B16: 2484-9497-0570
A17: LK95 | B17: 3647-7561-7276

Sheet 이름(TLxx-xx)
C1: Thai-Lao Trucking 가견적 | L1: 번호(No.) | M1: LKTL2026xx-xx | R1: =D11 -> 1 | T1: 화폐 | U1: 기준 환율 | V1: 추가 환율 | W1: 적용 환율
A2: 회사명 | B2: 엘케이(LK)무역 | D2: 도착일 | E2: 2026-XX-XX | I2: 고객명/회사명 // 영수 번호 | L2: 고객이름 | R2: =N16 -> 0 | T2: USD-KIP | U2: ='Row data'!C3 -> 23000 | V2: 1000 | W2: =U2+V2 -> 24000
A3: 회사 주소 | B3: 비엔티엔시, 씨싿따낙구, 싸판텅 느아 09, 11번 골목, 엘케이(LK) 빌딩, 1층 LK Trading | T3: USD-THB | U3: ='Row data'!C4 -> 33 | V3: 1 | W3: =U3+V3 -> 34
A4: 전화번호 | B4: 020-9112-6780 | I4: 고객 연락처/회사 연락처 | L4: 전화번호 | T4: USD-WON | U4: ='Row data'!C5 -> 1515 | V4: 30 | W4: =U4+V4 -> 1545
A5: No. | B5: 종류 | C5: 단가 | D5: 수량 | E5: 실제중량(Kg) | F5: 실제중량 합산(kg) | G5: 규격 (cm) | J5: 용적 중량(kg) | K5: 용적중량 합산(Kg) | L5: 실제중량 운임 | M5: 용적중량 운임 | N5: 청구중량 운임
A6: 1 | B6: TL01-01 | C6: =VLOOKUP(MAX(E6,J6),'Row data'!$C$8:$D$14,2,TRUE) -> 4 | D6: 1 | F6: =E6*D6 -> 0 | J6: =(G6*H6*I6)*0.00022 -> 0 | K6: =J6*D6 -> 0 | L6: =(IF(0=F6*C6,0,IF('Row data'!$D$8>=C6*F6,'Row data'!$D$8,C6*F6))) -> 0 | M6: =(IF(0=K6*C6,0,IF('Row data'!$D$8>=K6*C6,'Row data'!$D$8,K6*C6))) -> 0 | N6: =MAX(L6:M6) -> 0
A7: 2
A8: 3
A9: 4
A10: 5
A11: 합 계 | D11: =SUM(D6:D10) -> 1 | F11: =SUM(F6:F10) -> 0 | K11: =SUM(K6:K10) -> 0
A12: Remark/비 고 | F12: Inland delivery/시내.지방 배송 | L12: 운임 총합 | N12: =SUM(N6:N11) -> 0
A13: - 동 가견적 운임의 중량 및 크기는 단순 예상치이므로 최종 책정 방법인 기준인 실측시 금액 차이가 발생 할수 있으니, 참고용으로만 확인 부탁 드립니다. - 운임은 USD 기준이며, 이외 화폐는 가견적 안내시의 환율 기준이므로, 최종 운임 책정시의 환율변동으로 인한 운임 차이가 발생할수 있으니, 참고용으로만 확인 부탁 드립니다. | L13: 할인 | M13: =IFERROR(MID($A$13,FIND(" "&$L$13&" ",$A$13)+4,3)," ") | N13: =IFERROR(N12*M13,0) -> 0
L14: 특별할인 | M14: =IFERROR(MID($A$13,FIND(" "&$L$14&" ",$A$13)+6,3)," ") | N14: =IFERROR(N12*M14,0) -> 0
L15: 세금 계산서(VAT) | M15: =IFERROR(IF(FIND("세금 계산서",$A$13),10%," ")," ") | N15: =IFERROR((N12-N13-N14)*M15,0) -> 0
L16: 최종 청구 금액 | M16: USD | N16: =(N12-N13-N14+N15) -> 0
M17: KIP | N17: =ROUNDUP((N16*$W$2),-3) -> 0
M18: THB | N18: =ROUNDUP((N16*$W$3),-1) -> 0
M19: WON | N19: =ROUNDUP((N16*$W$4),-2) -> 0
A21: * 모든 비용은 회사의 내규 및 각 물품의 중량/크기 실측을 기준으로 청구되며 최소 운임은 $4/kg 이며, 청구중량에 따라 차등 운임이 적용 됩니다.
A22: * 입.출고지를 떠나시기 전 꼭! 고객님 본인 물품 및 개수 확인 부탁 드립니다. 물품이 출고된 이후 LK그룹은 물품의 파손/분실에 대한 어떠한 책임도 없습니다.
A23: * 물품 도착 및 출고 후 특별한 사유 없이 장기 미수취 물품의 경우 보관료등 기타 추가 비용이 발생 할 수 있습니다.
A24: * 물품 출고 후 1주 후부터 보관료(최소 3불/CBM/day)가 발생하며, 특별한 사유 없이 2달 이상 보관 물품들은 임의로 폐기/처분 될 수 있습니다.
A25: 엘케이 (LK)무역 | H25: * 이용해 주셔서 감사합니다. | K25: 고객사 서명

Sheet Sheet1
A1: PSV | C1: 32 | E1: 1.35 | H1: JJ | J1: 32 | L1: 1.35
A2: KG | B2: Rate(THB) | C2: Rate(USD) | D2: per kg(USD) | H2: KG | I2: Rate(THB) | J2: Rate(USD) | K2: per kg(USD)
A3: 0.5 | B3: 50 | C3: =B3/$C$1 -> 1.5625 | D3: =C3/A3 -> 3.125 | E3: =D3*$E$1 -> 4.21875 | H3: 0.5 | I3: 50 | J3: =I3/$J$1 -> 1.5625 | K3: =J3/H3 -> 3.125 | L3: =K3*$L$1 -> 4.21875
A4: 1 | B4: 60 | C4: =B4/$C$1 -> 1.875 | D4: =C4/A4 -> 1.875 | E4: =D4*$E$1 -> 2.53125 | H4: 1 | I4: 70 | J4: =I4/$J$1 -> 2.1875 | K4: =J4/H4 -> 2.1875 | L4: =K4*$L$1 -> 2.953125
A5: 1.5 | B5: 70 | C5: =B5/$C$1 -> 2.1875 | D5: =C5/A5 -> 1.4583333 | E5: =D5*$E$1 -> 1.96875 | H5: 1.5 | I5: 80 | J5: =I5/$J$1 -> 2.5 | K5: =J5/H5 -> 1.6666667 | L5: =K5*$L$1 -> 2.25
A6: 2 | B6: 80 | C6: =B6/$C$1 -> 2.5 | D6: =C6/A6 -> 1.25 | E6: =D6*$E$1 -> 1.6875 | H6: 2 | I6: 90 | J6: =I6/$J$1 -> 2.8125 | K6: =J6/H6 -> 1.40625 | L6: =K6*$L$1 -> 1.8984375
A7: 2.5 | B7: 90 | C7: =B7/$C$1 -> 2.8125 | D7: =C7/A7 -> 1.125 | E7: =D7*$E$1 -> 1.51875 | H7: 2.5 | I7: 100 | J7: =I7/$J$1 -> 3.125 | K7: =J7/H7 -> 1.25 | L7: =K7*$L$1 -> 1.6875
A8: 3 | B8: 120 | C8: =B8/$C$1 -> 3.75 | D8: =C8/A8 -> 1.25 | E8: =D8*$E$1 -> 1.6875 | H8: 3 | I8: 110 | J8: =I8/$J$1 -> 3.4375 | K8: =J8/H8 -> 1.1458333 | L8: =K8*$L$1 -> 1.546875
A9: 4 | B9: 145 | C9: =B9/$C$1 -> 4.53125 | D9: =C9/A9 -> 1.1328125 | E9: =D9*$E$1 -> 1.5292969 | H9: 4 | I9: 125 | J9: =I9/$J$1 -> 3.90625 | K9: =J9/H9 -> 0.9765625 | L9: =K9*$L$1 -> 1.3183594
A10: 5 | B10: 170 | C10: =B10/$C$1 -> 5.3125 | D10: =C10/A10 -> 1.0625 | E10: =D10*$E$1 -> 1.434375 | H10: 5 | I10: 140 | J10: =I10/$J$1 -> 4.375 | K10: =J10/H10 -> 0.875 | L10: =K10*$L$1 -> 1.18125
A11: 6 | B11: 195 | C11: =B11/$C$1 -> 6.09375 | D11: =C11/A11 -> 1.015625 | E11: =D11*$E$1 -> 1.3710938 | H11: 6 | I11: 160 | J11: =I11/$J$1 -> 5 | K11: =J11/H11 -> 0.83333333 | L11: =K11*$L$1 -> 1.125
A12: 7 | B12: 220 | C12: =B12/$C$1 -> 6.875 | D12: =C12/A12 -> 0.98214286 | E12: =D12*$E$1 -> 1.3258929 | H12: 7 | I12: 175 | J12: =I12/$J$1 -> 5.46875 | K12: =J12/H12 -> 0.78125 | L12: =K12*$L$1 -> 1.0546875
A13: 8 | B13: 240 | C13: =B13/$C$1 -> 7.5 | D13: =C13/A13 -> 0.9375 | E13: =D13*$E$1 -> 1.265625 | H13: 8 | I13: 200 | J13: =I13/$J$1 -> 6.25 | K13: =J13/H13 -> 0.78125 | L13: =K13*$L$1 -> 1.0546875
A14: 9 | B14: 265 | C14: =B14/$C$1 -> 8.28125 | D14: =C14/A14 -> 0.92013889 | E14: =D14*$E$1 -> 1.2421875 | H14: 9 | I14: 220 | J14: =I14/$J$1 -> 6.875 | K14: =J14/H14 -> 0.76388889 | L14: =K14*$L$1 -> 1.03125
... A55: 50 | B55: 1040 | C55: =B55/$C$1 -> 32.5 | D55: =C55/A55 -> 0.65 | E55: =D55*$E$1 -> 0.8775 | H55: 50 | I55: 1100 | J55: =I55/$J$1 -> 34.375 | K55: =J55/H55 -> 0.6875 | L55: =K55*$L$1 -> 0.928125

Sheet Sheet2
A1: Kg 구간 | B1: 적용 운임
A2: 0~1kg | B2: 4
A3: 2~5kg | B3: 2.5
A4: 6~9kg | B4: 1.5
A5: 10~14kg | B5: 1.25
A6: 15~17kg | B6: 1.15
A7: 18~20kg | B7: 1.13
A8: 21kg 이상 | B8: 1.1
