Workbook

Sheet Row data
B1: LK내부 환율 | H1: 할인 적용 목록
B2: 화폐 | C2: 기준 환율 | D2: 추가 환율 | E2: 적용 환율
B3: USD-KIP | C3: 23000 | D3: 1000 | E3: =C3+D3 -> 24000 | H3: 라선협 할인 | N3: 지상사협의회 회원사 할인 | U3: 대표님 지인 할인
B4: USD-THB | C4: 33 | D4: 1 | E4: =C4+D4 -> 34 | H4: 해상 | J4: 항공 | N4: 해상 | P4: 항공 | U4: 해상 | W4: 항공
B5: USD-WON | C5: 1515 | D5: 30 | E5: =C5+D5 -> 1545 | H5: 일반 | I5: 기부 | J5: 일반 | K5: 기부 | N5: 일반 | O5: 기부 | P5: 일반 | Q5: 기부 | U5: 일반 | V5: 기부 | W5: 일반 | X5: 기부
H6: 0.2 | I6: 0.3 | J6: 0.05 | K6: 0.1 | N6: 0.1 | O6: 0.2 | P6: 0.05 | Q6: 0.1 | U6: 5~10% | V6: 0.2 | W6: 0.05 | X6: 0.1
B8: Kg 구간 | C8: 최소값 | D8: 적용 운임 | H8: 이름 | J8: 할인율 | K8: 할인금액 | L8: 비 고 | N8: 이름 | P8: 회사 | Q8: 할인율 | R8: 할인금액 | S8: 비 고 | U8: 이름 | W8: 할인율 | X8: 할인금액 | Y8: 비 고
B9: 0~1kg | C9: 0 | D9: =ROUNDUP(Sheet1!R4,1)+D7 -> 13.4 | H9: 강병준 | J9: 0.05 | N9: 강병수 | O9: 법인장 | P9: PNPC | Q9: 0.05 | U9: 김인섭 | V9: 요정 투어 (김요셉 형) | W9: 0.05
B10: 2~4kg | C10: 2 | D10: =ROUNDUP(Sheet1!R5,1)+D7 -> 10.6 | H10: 김민기 | J10: 0.05 | N10: 고영태 | O10: 부이사장 | P10: 라오스증권거래소 | Q10: 0.05 | U10: 서정진(서이사님) | W10: 0.05
B11: 5~8kg | C11: 5 | D11: =ROUNDUP(Sheet1!R8,1)+D7 -> 9 | H11: 김반석 | I11: 에즈라 | J11: 0.05 | N11: 고중하 | O11: 대표 | P11: 젤라콘 | Q11: 0.05 | U11: 이형준 | V11: 골재 판매 | W11: 0.05
B12: 9~12kg | C12: 9 | D12: =ROUNDUP(Sheet1!R12,1)+D7 -> 8.5 | H12: 김세진 | J12: 0.05 | N12: 김민우 | O12: 법인장 | P12: DGB 라오 리싱 | Q12: 0.05 | U12: 임홍식 | W12: 0.05
B13: 13~16kg | C13: 13 | D13: =ROUNDUP(Sheet1!R16,1)+D7 -> 8.3 | H13: 김영진 | J13: 0.05 | N13: 김윤식 | O13: 법인장 | P13: BNK 캐피탈 라오스 | Q13: 0.05 | U13: 정석진 | W13: 0.05
B14: 17~19kg | C14: 17 | D14: =ROUNDUP(Sheet1!R20,1)+D7 -> 8.2 | H14: 김재광 | J14: 0.05 | N14: 김일재 | O14: 법인장 | P14: 흥화라오스 | Q14: 0.05 | U14: 진정우 | V14: 105호 고객 | W14: 0.1 | Y14: 기부
B15: 20kg 이상 | C15: 20 | D15: =ROUNDUP(Sheet1!R23,1)+D7 -> 8.1 | H15: 김종한 | J15: 0.05 | N15: 박성호 | O15: 대표 | P15: LK Group | Q15: 0.05 | U15: 최성식 | V15: 큐빅 바이크 | W15: 0.05
H16: 김종훈/김희영 | J16: 0.05 | N16: 백지원 | O16: 센터장 | P16: 라오스 EPS센터 | Q16: 0.05 | U16: 최재혁 | W16: 0.05
H17: 김지훈 | J17: 0.05 | N17: 송대영 | O17: 실장 | P17: DSA(K-LAO) | Q17: 0.05 | U17: 최지호 | W17: 0.05
H18: 김창수 | J18: 0.05 | L18: 지방배송 | N18: 송창현 | O18: 법인장 | P18: DGB 라오 리싱 | Q18: 0.05 | U18: 최현석 | W18: 0.05
H19: 김필립 | J19: 0.05 | N19: 오유근 | O19: 법인장 | P19: 코웨포-라오 인터내셔널 | Q19: 0.05 | S19: 사모: 김연희
B20: 한국 세금 계산서 발급시 계좌번호 | H20: 박정민 | J20: 0.05 | N20: 유병문 | O20: 법인장 | P20: 현진라오 | Q20: 0.05
B21: 경남은행 2070133424601 박성호(엘케이무역) | H21: 박종복 | J21: 0.05 | N21: 이범주 | O21: 단장, 전무 | P21: 삼안 | Q21: 0.05 | U21: 할인 총합 | X21: =SUM(X9:X20) -> 0
H22: 박진경 | I22: 본죽 | J22: 0.05 | N22: 이성한 | O22: 상무 | P22: 한국종합기술 | Q22: 0.05
B23: 일반 입금 | H23: 박창성 | J23: 0.05 | N23: 이시경 | O23: 법인장 | P23: KB 코라오 리싱 | Q23: 0.05
B24: 경남은행 571-22-0330221 박성호 | H24: 백규현 | I24: 샤론스쿨 | J24: 0.05 | N24: 이재원 | O24: 대표 | P24: 그린굿스 | Q24: 0.05 | U24: 기업 할인
H25: 백대식 | J25: 0.05 | N25: 이재현 | O25: 법인장 | P25: Paul Golden Lao(좋은차닷컴) | Q25: 0.05 | U25: 이름 | V25: 제품 | W25: 할인율 | X25: 할인금액 | Y25: 비 고
B26: 라오스-중국 내륙 xx항차 | H26: 백상호 | J26: 0.05 | N26: 이제원 | O26: 법인장 | P26: 웰컴 리싱 라오 | Q26: 0.05 | U26: Love STK | V26: 다단계제품 | W26: 0.05
B27: Total | C27: =SUM('이름(LCxx-xx)'!R1) -> 1 | H27: 백운송 | J27: 0.05 | N27: 이종원 | O27: 팀장 | P27: KOTRA | Q27: 0.05 | U27: Nice to meat you | W27: 0.05
B28: Amount | C28: =SUM('이름(LCxx-xx)'!R2) -> 0 | H28: 백총명 | J28: 0.05 | N28: 이창열 | O28: 부장 | P28: 라오스증권거래소 | Q28: 0.05 | U28: Peter Kim/Viengchay | V28: 성경책 | W28: 0.05
H29: 변종승 | J29: 0.05 | N29: 이현열 | O29: 지점장 | P29: 에어부산 | Q29: 0.05 | U29: 라오스 국가대표 야구 감독 | W29: 0.05 | Y29: 대량 5%, 기부품 10% (사진 첨부 필)
B30: 총 할인 금액 | C30: =K58+R36+X21+X32 -> 0 | H30: 손사랑 | J30: 0.05 | L30: 지방배송 | N30: 임정민 | O30: 지점장 | P30: 제주항공 | Q30: 0.05 | U30: 이우용/임태준 | V30: 유투버 | W30: 0.05 | Y30: 지방배송
H31: 신라함 | J31: 0.05 | N31: 정석진 | O31: 지사장 | P31: CJ대한통운 라오스사무소 | Q31: 0.05
H32: 우상봉 | J32: 0.05 | N32: 최완식 | O32: 단장 | P32: 솔루텍시스템 라오 | Q32: 0.05 | U32: 할인 총합 | X32: =SUM(X26:X31) -> 0
B33: 현지 발생 비용 | H33: 원순연 | J33: 0.05 | N33: 한태원 | O33: CEO | P33: 엘에스엠 | Q33: 0.05
B34: 날짜 | C34: 내 용 | D34: 킵 | H34: 이경희 | J34: 0.05 | L34: 지방배송 | N34: 황헌기 | O34: 대표 | P34: 정원상사 | Q34: 0.05
B35: 2024.10.10 | H35: 이관택 | J35: 0.05
B36: 2024.10.11 | H36: 이규상 | J36: 0.05 | N36: 할인 총합 | R36: =SUM(R9:R35) -> 0
H37: 이명숙/임기환 | J37: 0.05
H38: 이병목/장헤진 | J38: 0.05
D39: =SUM(D35:D38) -> 0 | E39: =D39/C4 -> 0 | H39: 이상미 | J39: 0.05
H40: 이성원 | J40: 0.05
H41: 이수정 | J41: 0.05
...

Sheet 수취인 불명 내역
A1: 영수 번호 | B1: 송장 번호 | C1: Remark
A2: LK81 | B2: 5593-8870-9956 | C2: 김인규??
A3: LK82 | B3: 10-2664-5564-6053, 382-7242-2753
A4: LK83 | B4: 5903-7235-0543, 5903-7199-0220
A5: LK84 | B5: 66597-0117-4099 | C5: 이우용??
A6: LK85 | B6: 6856-8748-0750
A7: LK86 | B7: 66017-0128-0372
A8: LK87 | B8: 65689-0106-6533
A9: LK88 | B9: 5796-5801-8672 | C9: 송인호 고객물류로 추정됨 / 박주유 님이 한국에서 보내신 물건으로 추정
A10: LK89 | B10: 5909-8013-8342 | C10: 폼마린??
A11: LK90 | B11: 65129-0112-6372
A12: LK91 | B12: 64134-0322-0901, 64134-0322-0902 | C12: 박주유
A13: LK92 | B13: 6105072440050, 4107032440085, 3132212443441
A14: LK93 | B14: 10-2672-2107-9721, 10-2672-2107-9964, 10-2672-2107-5613, 10-2672-2107-8553, 10-2672-2107-5731 | C14: 박환영??
B15: 2601-402-015153
A16: LK94 | B16: 2484-9497-0570
A17: LK95 | B17: 3647-7561-7276

Sheet 이름(LCxx-xx)
C1: Lao-Chia 가견적 | L1: 번호(No.) | M1: LC2026xx-xx | R1: =D11 -> 1 | T1: 화폐 | U1: 기준 환율 | V1: 추가 환율 | W1: 적용 환율
A2: 회사명 | B2: 엘케이(LK)무역 | D2: 도착일 | E2: 2026-XX-XX | I2: 고객명/회사명 // 영수 번호 | L2: 고객이름 | R2: =N16 -> 0 | T2: USD-KIP | U2: ='Row data'!C3 -> 23000 | V2: 1000 | W2: =U2+V2 -> 24000
A3: 회사 주소 | B3: 비엔티엔시, 씨싿따낙구, 싸판텅 느아 09, 11번 골목, 엘케이(LK) 빌딩, 1층 LK Trading | T3: USD-THB | U3: ='Row data'!C4 -> 33 | V3: 1 | W3: =U3+V3 -> 34
A4: 전화번호 | B4: 020-9112-6780 | I4: 고객 연락처/회사 연락처 | L4: 전화번호 | T4: USD-WON | U4: ='Row data'!C5 -> 1515 | V4: 30 | W4: =U4+V4 -> 1545
A5: No. | B5: 종류 | C5: 단가 | D5: 수량 | E5: 실제중량(Kg) | F5: 실제중량 합산(kg) | G5: 규격 (cm) | J5: 용적 중량(kg) | K5: 용적중량 합산(Kg) | L5: 실제중량 운임 | M5: 용적중량 운임 | N5: 청구중량 운임
A6: 1 | B6: LC01-01 | C6: =VLOOKUP(MAX(E6,J6),'Row data'!$C$9:$D$15,2,TRUE) -> 13.4 | D6: 1 | F6: =E6*D6 -> 0 | J6: =(G6*H6*I6)*0.00022 -> 0 | K6: =J6*D6 -> 0 | L6: =(IF(0=F6*C6,0,IF('Row data'!$D$9>=C6*F6,'Row data'!$D$9,C6*F6))) -> 0 | M6: =(IF(0=K6*C6,0,IF('Row data'!$D$9>=K6*C6,'Row data'!$D$9,K6*C6))) -> 0 | N6: =MAX(L6:M6) -> 0
A7: 2
A8: 3
A9: 4
A10: 5
A11: 합 계 | D11: =SUM(D6:D10) -> 1 | F11: =SUM(F6:F10) -> 0 | K11: =SUM(K6:K10) -> 0
A12: Remark/비 고 | F12: Inland delivery/시내.지방 배송 | L12: 운임 총합 | N12: =SUM(N6:N11) -> 0
A13: - 기한: 2025년 11월 말, 고객의 요청에 의하여 견적후 배송/출발 지연이 발생할 경우 운임 변동이 있을수 있으니 참고 부탁 드립니다.- 동 가견적 운임의 중량 및 크기는 단순 예상치이므로 최종 책정 방법인 기준인 실측시 금액 차이가 발생 할수 있으니, 참고용으로만 확인 부탁 드립니다. - 운임은 USD 기준이며, 이외 화폐는 가견적 안내시의 환율 기준이므로, 최종 운임 책정시의 환율변동으로 인한 운임 차이가 발생할수 있으니, 참고용으로만 확인 부탁 드립니다. | L13: 할인 | M13: =IFERROR(MID($A$13,FIND(" "&$L$13&" ",$A$13)+4,3)," ") | N13: =IFERROR(N12*M13,0) -> 0
L14: 특별할인 | M14: =IFERROR(MID($A$13,FIND(" "&$L$14&" ",$A$13)+6,3)," ") | N14: =IFERROR(N12*M14,0) -> 0
L15: 세금 계산서(VAT) | M15: =IFERROR(IF(FIND("세금 계산서",$A$13),10%," ")," ") | N15: =IFERROR((N12-N13-N14)*M15,0) -> 0
L16: 최종 청구 금액 | M16: USD | N16: =(N12-N13-N14+N15) -> 0
M17: KIP | N17: =ROUNDUP((N16*$W$2),-3) -> 0
M18: THB | N18: =ROUNDUP((N16*$W$3),-1) -> 0
M19: WON | N19: =ROUNDUP((N16*$W$4),-2) -> 0
A21: * 모든 비용은 회사의 내규 및 각 물품의 중량/크기 실측을 기준으로 청구되며 최소 운임은 $13.4/kg 이며, 청구중량에 따라 차등 운임이 적용 됩니다.
A22: * 이용해 주셔서 감사합니다.
A24: 엘케이 (LK)무역 | K24: 고객사 서명

Sheet Sheet1
A1: 훙아룬 | C1: 20000 | E1: 1.35 | H1: RNP | J1: 32 | L1: 1.35 | N1: TSC | P1: 6.9 | R1: 1.35
A2: 비엔티엔-루앙남타
A3: KG | B3: Rate(KIP) | C3: Rate(USD) | D3: per kg(USD) | H3: KG | I3: Rate(THB) | J3: Rate(USD) | K3: per kg(USD) | N3: KG | O3: Rate(CNY) | P3: Rate(USD) | Q3: per kg(USD)
A4: 1 | B4: 12000 | C4: =B4/$C$1 -> 0.6 | D4: =C4/A4 -> 0.6 | E4: =D4*$E$1 -> 0.81 | F4: =E4 -> 0.81 | H4: 1 | I4: 1270 | J4: =I4/$J$1 -> 39.6875 | K4: =J4/H4 -> 39.6875 | L4: =K4*$L$1 -> 53.578125 | N4: 1 | O4: 68 | P4: =O4/$P$1 -> 9.8550725 | Q4: =P4/N4 -> 9.8550725 | R4: =Q4*$R$1 -> 13.304348 | T4: =R4-Q4 -> 3.4492754
A5: 2 | B5: 14000 | C5: =B5/$C$1 -> 0.7 | D5: =C5/A5 -> 0.35 | E5: =D5*$E$1 -> 0.4725 | F5: =E5 -> 0.4725 | H5: 1.5 | I5: 1505 | J5: =I5/$J$1 -> 47.03125 | K5: =J5/H5 -> 31.354167 | L5: =K5*$L$1 -> 42.328125 | N5: 2 | O5: 108 | P5: =O5/$P$1 -> 15.652174 | Q5: =P5/N5 -> 7.826087 | R5: =Q5*$R$1 -> 10.565217 | T5: =R5-Q5 -> 2.7391304
A6: 3 | B6: 16000 | C6: =B6/$C$1 -> 0.8 | D6: =C6/A6 -> 0.26666667 | E6: =D6*$E$1 -> 0.36 | F6: =(E6+E7)/2 -> 0.3571875 | H6: 2 | I6: 1590 | J6: =I6/$J$1 -> 49.6875 | K6: =J6/H6 -> 24.84375 | L6: =K6*$L$1 -> 33.539062 | N6: 3 | O6: 148 | P6: =O6/$P$1 -> 21.449275 | Q6: =P6/N6 -> 7.1497585 | R6: =Q6*$R$1 -> 9.6521739 | T6: =R6-Q6 -> 2.5024155
A7: 4 | B7: 21000 | C7: =B7/$C$1 -> 1.05 | D7: =C7/A7 -> 0.2625 | E7: =D7*$E$1 -> 0.354375 | H7: 2.5 | I7: 1675 | J7: =I7/$J$1 -> 52.34375 | K7: =J7/H7 -> 20.9375 | L7: =K7*$L$1 -> 28.265625 | N7: 4 | O7: 188 | P7: =O7/$P$1 -> 27.246377 | Q7: =P7/N7 -> 6.8115942 | R7: =Q7*$R$1 -> 9.1956522 | T7: =R7-Q7 -> 2.384058
A8: 5 | B8: 25000 | C8: =B8/$C$1 -> 1.25 | D8: =C8/A8 -> 0.25 | E8: =D8*$E$1 -> 0.3375 | F8: =(E8+E9)/2 -> 0.32625 | H8: 3 | I8: 1760 | J8: =I8/$J$1 -> 55 | K8: =J8/H8 -> 18.333333 | L8: =K8*$L$1 -> 24.75 | N8: 5 | O8: 228 | P8: =O8/$P$1 -> 33.043478 | Q8: =P8/N8 -> 6.6086957 | R8: =Q8*$R$1 -> 8.9217391 | T8: =R8-Q8 -> 2.3130435
A9: 6 | B9: 28000 | C9: =B9/$C$1 -> 1.4 | D9: =C9/A9 -> 0.23333333 | E9: =D9*$E$1 -> 0.315 | H9: 3.5 | I9: 1845 | J9: =I9/$J$1 -> 57.65625 | K9: =J9/H9 -> 16.473214 | L9: =K9*$L$1 -> 22.238839 | N9: 6 | O9: 268 | P9: =O9/$P$1 -> 38.84058 | Q9: =P9/N9 -> 6.47343 | R9: =Q9*$R$1 -> 8.7391304 | T9: =R9-Q9 -> 2.2657005
A10: 7 | B10: 31000 | C10: =B10/$C$1 -> 1.55 | D10: =C10/A10 -> 0.22142857 | E10: =D10*$E$1 -> 0.29892857 | F10: =(E10+E11+E12)/3 -> 0.28776786 | H10: 4 | I10: 1930 | J10: =I10/$J$1 -> 60.3125 | K10: =J10/H10 -> 15.078125 | L10: =K10*$L$1 -> 20.355469 | N10: 7 | O10: 308 | P10: =O10/$P$1 -> 44.637681 | Q10: =P10/N10 -> 6.3768116 | R10: =Q10*$R$1 -> 8.6086957 | T10: =R10-Q10 -> 2.2318841
A11: 8 | B11: 34000 | C11: =B11/$C$1 -> 1.7 | D11: =C11/A11 -> 0.2125 | E11: =D11*$E$1 -> 0.286875 | H11: 4.5 | I11: 2165 | J11: =I11/$J$1 -> 67.65625 | K11: =J11/H11 -> 15.034722 | L11: =K11*$L$1 -> 20.296875 | N11: 8 | O11: 348 | P11: =O11/$P$1 -> 50.434783 | Q11: =P11/N11 -> 6.3043478 | R11: =Q11*$R$1 -> 8.5108696 | T11: =R11-Q11 -> 2.2065217
A12: 9 | B12: 37000 | C12: =B12/$C$1 -> 1.85 | D12: =C12/A12 -> 0.20555556 | E12: =D12*$E$1 -> 0.2775 | H12: 5 | I12: 2250 | J12: =I12/$J$1 -> 70.3125 | K12: =J12/H12 -> 14.0625 | L12: =K12*$L$1 -> 18.984375 | N12: 9 | O12: 388 | P12: =O12/$P$1 -> 56.231884 | Q12: =P12/N12 -> 6.2479871 | R12: =Q12*$R$1 -> 8.4347826 | T12: =R12-Q12 -> 2.1867955
A13: 10 | B13: 40000 | C13: =B13/$C$1 -> 2 | D13: =C13/A13 -> 0.2 | E13: =D13*$E$1 -> 0.27 | F13: =(E13+E14+E15)/3 -> 0.26420455 | H13: 5.5 | I13: 2453 | J13: =I13/$J$1 -> 76.65625 | K13: =J13/H13 -> 13.9375 | L13: =K13*$L$1 -> 18.815625 | N13: 10 | O13: 428 | P13: =O13/$P$1 -> 62.028986 | Q13: =P13/N13 -> 6.2028986 | R13: =Q13*$R$1 -> 8.373913 | T13: =R13-Q13 -> 2.1710145
A14: 11 | B14: 43000 | C14: =B14/$C$1 -> 2.15 | D14: =C14/A14 -> 0.19545455 | E14: =D14*$E$1 -> 0.26386364 | H14: 6 | I14: 2657 | J14: =I14/$J$1 -> 83.03125 | K14: =J14/H14 -> 13.838542 | L14: =K14*$L$1 -> 18.682031 | N14: 11 | O14: 468 | P14: =O14/$P$1 -> 67.826087 | Q14: =P14/N14 -> 6.1660079 | R14: =Q14*$R$1 -> 8.3241107 | T14: =R14-Q14 -> 2.1581028
A15: 12 | B15: 46000 | C15: =B15/$C$1 -> 2.3 | D15: =C15/A15 -> 0.19166667 | E15: =D15*$E$1 -> 0.25875 | H15: 6.5 | I15: 2860 | J15: =I15/$J$1 -> 89.375 | K15: =J15/H15 -> 13.75 | L15: =K15*$L$1 -> 18.5625 | N15: 12 | O15: 508 | P15: =O15/$P$1 -> 73.623188 | Q15: =P15/N15 -> 6.1352657 | R15: =Q15*$R$1 -> 8.2826087 | T15: =R15-Q15 -> 2.147343
A16: 13 | B16: 49000 | C16: =B16/$C$1 -> 2.45 | D16: =C16/A16 -> 0.18846154 | E16: =D16*$E$1 -> 0.25442308 | F16: =(E16+E17+E18)/3 -> 0.25087912 | H16: 7 | I16: 3063 | J16: =I16/$J$1 -> 95.71875 | K16: =J16/H16 -> 13.674107 | L16: =K16*$L$1 -> 18.460045 | N16: 13 | O16: 548 | P16: =O16/$P$1 -> 79.42029 | Q16: =P16/N16 -> 6.1092531 | R16: =Q16*$R$1 -> 8.2474916 | T16: =R16-Q16 -> 2.1382386
A17: 14 | B17: 52000 | C17: =B17/$C$1 -> 2.6 | D17: =C17/A17 -> 0.18571429 | E17: =D17*$E$1 -> 0.25071429 | H17: 7.5 | I17: 3267 | J17: =I17/$J$1 -> 102.09375 | K17: =J17/H17 -> 13.6125 | L17: =K17*$L$1 -> 18.376875 | N17: 14 | O17: 588 | P17: =O17/$P$1 -> 85.217391 | Q17: =P17/N17 -> 6.0869565 | R17: =Q17*$R$1 -> 8.2173913 | T17: =R17-Q17 -> 2.1304348
A18: 15 | B18: 55000 | C18: =B18/$C$1 -> 2.75 | D18: =C18/A18 -> 0.18333333 | E18: =D18*$E$1 -> 0.2475 | H18: 8 | I18: 3470 | J18: =I18/$J$1 -> 108.4375 | K18: =J18/H18 -> 13.554688 | L18: =K18*$L$1 -> 18.298828 | N18: 15 | O18: 628 | P18: =O18/$P$1 -> 91.014493 | Q18: =P18/N18 -> 6.0676329 | R18: =Q18*$R$1 -> 8.1913043 | T18: =R18-Q18 -> 2.1236715
A19: 16 | B19: 58000 | C19: =B19/$C$1 -> 2.9 | D19: =C19/A19 -> 0.18125 | E19: =D19*$E$1 -> 0.2446875 | F19: =(E19+E20+E21+E22+E23)/5 -> 0.24023394 | H19: 8.5 | I19: 3673 | J19: =I19/$J$1 -> 114.78125 | K19: =J19/H19 -> 13.503676 | L19: =K19*$L$1 -> 18.229963 | N19: 16 | O19: 668 | P19: =O19/$P$1 -> 96.811594 | Q19: =P19/N19 -> 6.0507246 | R19: =Q19*$R$1 -> 8.1684783 | T19: =R19-Q19 -> 2.1177536
A20: 17 | B20: 61000 | C20: =B20/$C$1 -> 3.05 | D20: =C20/A20 -> 0.17941176 | E20: =D20*$E$1 -> 0.24220588 | H20: 9 | I20: 3877 | J20: =I20/$J$1 -> 121.15625 | K20: =J20/H20 -> 13.461806 | L20: =K20*$L$1 -> 18.173438 | N20: 17 | O20: 708 | P20: =O20/$P$1 -> 102.6087 | Q20: =P20/N20 -> 6.0358056 | R20: =Q20*$R$1 -> 8.1483376 | T20: =R20-Q20 -> 2.112532
A21: 18 | B21: 64000 | C21: =B21/$C$1 -> 3.2 | D21: =C21/A21 -> 0.17777778 | E21: =D21*$E$1 -> 0.24 | H21: 9.5 | I21: 4080 | J21: =I21/$J$1 -> 127.5 | K21: =J21/H21 -> 13.421053 | L21: =K21*$L$1 -> 18.118421 | N21: 18 | O21: 748 | P21: =O21/$P$1 -> 108.4058 | Q21: =P21/N21 -> 6.0225443 | R21: =Q21*$R$1 -> 8.1304348 | T21: =R21-Q21 -> 2.1078905
A22: 19 | B22: 67000 | C22: =B22/$C$1 -> 3.35 | D22: =C22/A22 -> 0.17631579 | E22: =D22*$E$1 -> 0.23802632 | H22: 10 | I22: 4283 | J22: =I22/$J$1 -> 133.84375 | K22: =J22/H22 -> 13.384375 | L22: =K22*$L$1 -> 18.068906 | N22: 19 | O22: 788 | P22: =O22/$P$1 -> 114.2029 | Q22: =P22/N22 -> 6.0106789 | R22: =Q22*$R$1 -> 8.1144165 | T22: =R22-Q22 -> 2.1037376
A23: 20 | B23: 70000 | C23: =B23/$C$1 -> 3.5 | D23: =C23/A23 -> 0.175 | E23: =D23*$E$1 -> 0.23625 | H23: 10.5 | I23: 4487 | J23: =I23/$J$1 -> 140.21875 | K23: =J23/H23 -> 13.354167 | L23: =K23*$L$1 -> 18.028125 | N23: 20 | O23: 828 | P23: =O23/$P$1 -> 120 | Q23: =P23/N23 -> 6 | R23: =Q23*$R$1 -> 8.1 | T23: =R23-Q23 -> 2.1
A24: 21 | B24: 73000 | C24: =B24/$C$1 -> 3.65 | D24: =C24/A24 -> 0.17380952 | E24: =D24*$E$1 -> 0.23464286 | F24: =(E24+E25+E26+E27+E28)/5 -> 0.2319595 | H24: 11 | I24: 4690 | J24: =I24/$J$1 -> 146.5625 | K24: =J24/H24 -> 13.323864 | L24: =K24*$L$1 -> 17.987216
A25: 22 | B25: 76000 | C25: =B25/$C$1 -> 3.8 | D25: =C25/A25 -> 0.17272727 | E25: =D25*$E$1 -> 0.23318182 | H25: 11.5 | I25: 4893 | J25: =I25/$J$1 -> 152.90625 | K25: =J25/H25 -> 13.296196 | L25: =K25*$L$1 -> 17.949864
A26: 23 | B26: 79000 | C26: =B26/$C$1 -> 3.95 | D26: =C26/A26 -> 0.17173913 | E26: =D26*$E$1 -> 0.23184783 | H26: 12 | I26: 5097 | J26: =I26/$J$1 -> 159.28125 | K26: =J26/H26 -> 13.273438 | L26: =K26*$L$1 -> 17.919141
A27: 24 | B27: 82000 | C27: =B27/$C$1 -> 4.1 | D27: =C27/A27 -> 0.17083333 | E27: =D27*$E$1 -> 0.230625 | H27: 12.5 | I27: 5300 | J27: =I27/$J$1 -> 165.625 | K27: =J27/H27 -> 13.25 | L27: =K27*$L$1 -> 17.8875
A28: 25 | B28: 85000 | C28: =B28/$C$1 -> 4.25 | D28: =C28/A28 -> 0.17 | E28: =D28*$E$1 -> 0.2295 | H28: 13 | I28: 5503 | J28: =I28/$J$1 -> 171.96875 | K28: =J28/H28 -> 13.228365 | L28: =K28*$L$1 -> 17.858293
H29: 13.5 | I29: 5707 | J29: =I29/$J$1 -> 178.34375 | K29: =J29/H29 -> 13.210648 | L29: =K29*$L$1 -> 17.834375
H30: 14 | I30: 5910 | J30: =I30/$J$1 -> 184.6875 | K30: =J30/H30 -> 13.191964 | L30: =K30*$L$1 -> 17.809152
A31: Ms.Tadam | C31: 7 | E31: 1.35 | H31: 14.5 | I31: 6113 | J31: =I31/$J$1 -> 191.03125 | K31: =J31/H31 -> 13.174569 | L31: =K31*$L$1 -> 17.785668
A32: 루앙남타-중국 국경통관 | H32: 15 | I32: 6317 | J32: =I32/$J$1 -> 197.40625 | K32: =J32/H32 -> 13.160417 | L32: =K32*$L$1 -> 17.766562
A33: KG | B33: Rate(CNY) | C33: Rate(USD) | D33: per kg(USD) | H33: 15.5 | I33: 6520 | J33: =I33/$J$1 -> 203.75 | K33: =J33/H33 -> 13.145161 | L33: =K33*$L$1 -> 17.745968
A34: 1 | B34: 30 | C34: =B34/$C$31 -> 4.2857143 | D34: =C34/A34 -> 4.2857143 | E34: =D34*$E$31 -> 5.7857143 | H34: 16 | I34: 6723 | J34: =I34/$J$1 -> 210.09375 | K34: =J34/H34 -> 13.130859 | L34: =K34*$L$1 -> 17.72666
A35: 1 | B35: 50 | C35: =B35/$C$31 -> 7.1428571 | D35: =C35/A35 -> 7.1428571 | E35: =D35*$E$31 -> 9.6428571 | H35: 16.5 | I35: 6927 | J35: =I35/$J$1 -> 216.46875 | K35: =J35/H35 -> 13.119318 | L35: =K35*$L$1 -> 17.71108
H36: 17 | I36: 7130 | J36: =I36/$J$1 -> 222.8125 | K36: =J36/H36 -> 13.106618 | L36: =K36*$L$1 -> 17.693934
H37: 17.5 | I37: 7333 | J37: =I37/$J$1 -> 229.15625 | K37: =J37/H37 -> 13.094643 | L37: =K37*$L$1 -> 17.677768
A38: Ms.Tadam | H38: 18 | I38: 7537 | J38: =I38/$J$1 -> 235.53125 | K38: =J38/H38 -> 13.085069 | L38: =K38*$L$1 -> 17.664844
A39: 중국 국경-중국내 운송 | H39: 18.5 | I39: 7740 | J39: =I39/$J$1 -> 241.875 | K39: =J39/H39 -> 13.074324 | L39: =K39*$L$1 -> 17.650338
A40: KG | B40: Rate(CNY) | C40: Rate(USD) | D40: per kg(USD) | H40: 19 | I40: 7943 | J40: =I40/$J$1 -> 248.21875 | K40: =J40/H40 -> 13.064145 | L40: =K40*$L$1 -> 17.636595
...
