Workbook

Sheet Row data
B1: LK내부 환율 | H1: 할인 적용 목록
B2: 화폐 | C2: 기준 환율 | D2: 추가 환율 | E2: 적용 환율
B3: USD-KIP | C3: 23000 | D3: 1000 | E3: =C3+D3 -> 24000 | H3: 라선협 할인 | N3: 지상사협의회 회원사 할인 | U3: 대표님 지인 할인
B4: USD-THB | C4: 33 | D4: 1 | E4: =C4+D4 -> 34 | H4: 해상 | J4: 항공 | N4: 해상 | P4: 항공 | U4: 해상 | W4: 항공
B5: USD-WON | C5: 1515 | D5: 30 | E5: =C5+D5 -> 1545 | H5: 일반 | I5: 기부 | J5: 일반 | K5: 기부 | N5: 일반 | O5: 기부 | P5: 일반 | Q5: 기부 | U5: 일반 | V5: 기부 | W5: 일반 | X5: 기부
H6: 0.2 | I6: 0.3 | J6: 0.05 | K6: 0.1 | N6: 0.1 | O6: 0.2 | P6: 0.05 | Q6: 0.1 | U6: 5~10% | V6: 0.2 | W6: 0.05 | X6: 0.1
B7: Kg 구간 | C7: 최소값 | D7: 적용 운임
B8: 0~1kg | C8: 0 | D8: 18 | H8: 이름 | J8: 할인율 | K8: 할인금액 | L8: 비 고 | N8: 이름 | P8: 회사 | Q8: 할인율 | R8: 할인금액 | S8: 비 고 | U8: 이름 | W8: 할인율 | X8: 할인금액 | Y8: 비 고
B9: 2~5kg | C9: 2 | D9: 16 | H9: 강병준 | J9: 0.05 | N9: 강병수 | O9: 법인장 | P9: PNPC | Q9: 0.05 | U9: 김인섭 | V9: 요정 투어 (김요셉 형) | W9: 0.05
B10: 6~9kg | C10: 6 | D10: 14 | H10: 김민기 | J10: 0.05 | N10: 고영태 | O10: 부이사장 | P10: 라오스증권거래소 | Q10: 0.05 | U10: 서정진(서이사님) | W10: 0.05
B11: 10~14kg | C11: 10 | D11: 12 | H11: 김재양/김반석 | I11: EZRA | J11: 0.05 | N11: 고중하 | O11: 대표 | P11: 젤라콘 | Q11: 0.05 | U11: 이형준 | V11: 골재 판매 | W11: 0.05
B12: 15kg 이상 | C12: 15 | D12: 10 | H12: 김세진 | J12: 0.05 | N12: 한조운 | O12: 법인장 | P12: DGB 라오 리싱 | Q12: 0.05 | U12: 임홍식 | W12: 0.05
H13: 김양현 | J13: 0.05 | N13: 김지운 | O13: 법인장 | P13: BNK 캐피탈 라오스 | Q13: 0.05 | U13: 정석진 | W13: 0.05
H14: 김영진 | J14: 0.05 | N14: 고현식 | O14: 법인장 | P14: BNK 소액대출 MFI | Q14: 0.05 | U14: 진정우 | V14: 105호 고객 | W14: 0.1 | Y14: 기부
B15: 한국 세금 계산서 발급시 계좌번호 | H15: 김재광 | J15: 0.05 | N15: 김일재 | O15: 법인장 | P15: 흥화라오스 | Q15: 0.05 | U15: 최성식 | V15: 큐빅 바이크 | W15: 0.05
B16: 경남은행 2070133424601 박성호(엘케이무역) | H16: 김종한 | J16: 0.05 | N16: 박성호 | O16: 대표 | P16: LK Group | Q16: 0.05 | U16: 최재혁 | W16: 0.05
H17: 김종훈/김희영 | J17: 0.05 | N17: 백지원 | O17: 센터장 | P17: 라오스 EPS센터 | Q17: 0.05 | U17: 최지호 | W17: 0.05
B18: 일반 입금 | H18: 김지훈 | J18: 0.05 | L18: 지방배송 | N18: 송대영 | O18: 실장 | P18: DSA(K-LAO) | Q18: 0.05 | U18: 최현석 | W18: 0.05
B19: 경남은행 571-22-0330221 박성호 | H19: 김창수 | J19: 0.05 | N19: 김민우 | O19: 법인장 | P19: DGB 라오 리싱 | Q19: 0.05
H20: 김필립 | J20: 0.05 | N20: 오유근/김연희 | O20: 법인장 | P20: 코웨포-라오 인터내셔널 | Q20: 0.05
B21: 라오스-한국 항공 xx항차 | H21: 박정민 | J21: 0.05 | N21: 유병문 | O21: 법인장 | P21: 현진라오 | Q21: 0.05 | U21: 할인 총합 | X21: =SUM(X9:X20) -> 0
B22: Total | C22: =SUM('이름(Bxx-xx)'!R1) -> 1 | H22: 박종복 | J22: 0.05 | N22: 최병한 | O22: 부사장 | P22: 삼안 | Q22: 0.05
B23: Amount | C23: =SUM('이름(Bxx-xx)'!R2) -> 18 | H23: 박진경 | I23: 본죽 | J23: 0.05 | N23: 이범주 | O23: 단장, 전무 | P23: 삼안 | Q23: 0.05
H24: 박창성 | J24: 0.05 | N24: 이성한 | O24: 상무 | P24: 한국종합기술 | Q24: 0.05 | U24: 기업 할인
B25: 총 할인 금액 | C25: =K62+R46+X21+X32 -> 0 | H25: 백규현 | I25: 샤론스쿨 | J25: 0.05 | N25: 주인현 | O25: 법인장 | P25: KB 코라오 리싱 | Q25: 0.05 | U25: 이름 | V25: 제품 | W25: 할인율 | X25: 할인금액 | Y25: 비 고
H26: 백대식 | J26: 0.05 | N26: 이재원 | O26: 대표 | P26: 그린굿스 | Q26: 0.05 | U26: Love STK | V26: 다단계제품 | W26: 0.05
H27: 백상호 | J27: 0.05 | N27: 이재현 | O27: 법인장 | P27: Paul Golden Lao(좋은차닷컴) | Q27: 0.05 | U27: Nice to meat you | W27: 0.05
B28: 현지 발생 비용 | H28: 백운송 | J28: 0.05 | N28: 이제원 | O28: 법인장 | P28: 웰컴 리싱 라오 | Q28: 0.05 | U28: Peter Kim/Viengchay | V28: 성경책 | W28: 0.05
B29: 날짜 | C29: 내 용 | D29: 킵 | H29: 백총명 | J29: 0.05 | N29: 박준규/간현진/ 박세연/이종원 | P29: KOTRA | Q29: 0.05 | U29: 라오스 국가대표 야구 감독 | W29: 0.05 | Y29: 대량 5%, 기부품 10% (사진 첨부 필)
H30: 변종승 | J30: 0.05 | L30: 지방배송 | N30: 이창열 | O30: 부장 | P30: 라오스증권거래소 | Q30: 0.05 | U30: 이우용/임태준 | V30: 유투버 | W30: 0.05 | Y30: 지방배송
H31: 손사랑 | J31: 0.05 | N31: 이현열 | O31: 지점장 | P31: 에어부산 | Q31: 0.05
H32: 신라함 | J32: 0.05 | N32: 임정민 | O32: 지점장 | P32: 제주항공 | Q32: 0.05 | U32: 할인 총합 | X32: =SUM(X26:X31) -> 0
H33: 우상봉 | J33: 0.05 | N33: 정석진 | O33: 지사장 | P33: CJ대한통운 라오스사무소 | Q33: 0.05
D34: =SUM(D30:D33) -> 0 | E34: =D34/C4 -> 0 | H34: 원순연 | J34: 0.05 | L34: 지방배송 | N34: 최완식/고대종 | O34: 단장 | P34: 솔루텍시스템 라오 | Q34: 0.05
H35: 이경희 | J35: 0.05 | N35: 한태원 | O35: CEO | P35: 엘에스엠 | Q35: 0.05
H36: 이관택 | J36: 0.05 | N36: 황헌기 | O36: 대표 | P36: 정원상사 | Q36: 0.05
B37: 총 합산 액 | C37: =C23-E34 -> 18 | H37: 이규상 | J37: 0.05 | N37: 강남규 | O37: 부장 | P37: emart | Q37: 0.05
H38: 이명숙/임기환 | J38: 0.05 | N38: 정길영 | O38: 행장 | P38: 부영라오은행 | Q38: 0.05
H39: 이병목/장혜진 | J39: 0.05 | N39: 박대성 | O39: 차장 | P39: 부영라오 골프장 | Q39: 0.05
H40: 이상미 | J40: 0.05 | N40: 이성한 | O40: 상무 | P40: 한국종합기술 | Q40: 0.05
...

Sheet 수취인 불명 내역
A1: 영수 번호 | B1: 송장 번호 | C1: Remark
A2: LK81 | B2: 5593-8870-9956 | C2: 김인규??
A3: LK82 | B3: 10-2664-5564-6053, 382-7242-2753
A4: LK83 | B4: 5903-7235-0543, 5903-7199-0220
A5: LK84 | B5: 66597-0117-4099 | C5: 이우용??
A6: LK85 | B6: 6856-8748-0750
A7: LK86 | B7: 66017-0128-0372
A8: LK87 | B8: 65689-0106-6533
A9: LK88 | B9: 5796-5801-8672 | C9: 송인호 고객물류로 추정됨 / 박주유 님이 한국에서 보내신 물건으로 추정
A10: LK89 | B10: 5909-8013-8342 | C10: 폼마린??
A11: LK90 | B11: 65129-0112-6372
A12: LK91 | B12: 64134-0322-0901, 64134-0322-0902 | C12: 박주유
A13: LK92 | B13: 6105072440050, 4107032440085, 3132212443441
A14: LK93 | B14: 10-2672-2107-9721, 10-2672-2107-9964, 10-2672-2107-5613, 10-2672-2107-8553, 10-2672-2107-5731 | C14: 박환영??
B15: 2601-402-015153
A16: LK94 | B16: 2484-9497-0570
A17: LK95 | B17: 3647-7561-7276

Sheet 이름(Bxx-xx)
C1: Lao-Kor Air 가견적 | L1: 번호(No.) | M1: LKB2026xx-xx | R1: =D11 -> 1 | T1: 화폐 | U1: 기준 환율 | V1: 추가 환율 | W1: 적용 환율
A2: 회사명 | B2: 엘케이(LK)무역 | D2: 도착일 | E2: 2026-XX-XX | I2: 고객명/회사명 // 영수 번호 | L2: 이름 | R2: =IFERROR(N16,0) -> 18 | T2: USD-KIP | U2: ='Row data'!C3 -> 23000 | V2: 1000 | W2: =U2+V2 -> 24000
A3: 회사 주소 | B3: 비엔티엔시, 씨싿따낙구, 싸판텅 느아 09, 11번 골목, 엘케이(LK) 빌딩, 1층 LK Trading | T3: USD-THB | U3: ='Row data'!C4 -> 33 | V3: 1 | W3: =U3+V3 -> 34
A4: 전화번호 | B4: 020-9112-6780 | I4: 고객 연락처/회사 연락처 | L4: 전화번호 | T4: USD-WON | U4: ='Row data'!C5 -> 1515 | V4: 30 | W4: =U4+V4 -> 1545
A5: No. | B5: 종류 | C5: 단가 | D5: 수량 | E5: 실제중량(Kg) | F5: 실제중량 합산(kg) | G5: 규격 (cm) | J5: 용적 중량(kg) | K5: 용적중량 합산(Kg) | L5: 실제중량 운임 | M5: 용적중량 운임 | N5: 청구중량 운임
A6: 1 | B6: B01-01 | C6: =VLOOKUP(MAX(E6,J6),'Row data'!$C$8:$D$12,2,TRUE) -> 18 | D6: 1 | E6: 1 | F6: =E6*D6 -> 1 | G6: 1 | H6: 1 | I6: 1 | J6: =(G6*H6*I6)*0.00022 -> 0.00022 | K6: =J6*D6 -> 0.00022 | L6: =(IF(0=F6*C6,0,IF('Row data'!$D$8>=C6*F6,'Row data'!$D$8,C6*F6))) -> 18 | M6: =(IF(0=K6*C6,0,IF('Row data'!$D$8>=K6*C6,'Row data'!$D$8,K6*C6))) -> 18 | N6: =MAX(L6:M6) -> 18
A7: 2
A8: 3
A9: 4
A10: 5
A11: 합 계 | D11: =SUM(D6:D10) -> 1 | F11: =SUM(F6:F10) -> 1 | K11: =SUM(K6:K10) -> 0.00022
A12: Remark/비 고 | F12: Inland delivery/시내.지방 배송 | L12: 운임 총합 | N12: =SUM(N6:N11) -> 18
A13: - 동 가견적 운임의 중량 및 크기는 단순 예상치이므로 최종 책정 방법인 기준인 실측시 금액 차이가 발생 할수 있으니, 참고용으로만 확인 부탁 드립니다. - 운임은 USD 기준이며, 이외 화폐는 가견적 안내시의 환율 기준이므로, 최종 운임 책정시의 환율변동으로 인한 운임 차이가 발생할수 있으니, 참고용으로만 확인 부탁 드립니다. | L13: 할인 | M13: =IFERROR(MID($A$13,FIND(" "&$L$13&" ",$A$13)+4,3)," ") | N13: =IFERROR(N12*M13,0) -> 0
L14: 특별할인 | M14: =IFERROR(MID($A$13,FIND(" "&$L$14&" ",$A$13)+6,3)," ") | N14: =IFERROR(N12*M14,0) -> 0
L15: 세금 계산서(VAT) | M15: =IFERROR(IF(FIND("세금 계산서",$A$13),10%," ")," ") | N15: =IFERROR((N12-N13-N14)*M15,0) -> 0
L16: 최종 청구 금액 | M16: USD | N16: =(N12-N13-N14+N15) -> 18
M17: KIP | N17: =ROUNDUP((N16*$W$2),-3) -> 432000
M18: THB | N18: =ROUNDUP((N16*$W$3),-1) -> 620
M19: WON | N19: =ROUNDUP((N16*$W$4),-2) -> 27900
A21: * 모든 비용은 회사의 내규 및 각 물품의 중량/크기 실측을 기준으로 청구되며 최소 운임은 $18/kg 이며, 청구중량에 따라 차등 운임이 적용 됩니다.
A22: * 물품 도착 및 출고 후 특별한 사유 없이 장기 미수취 물품의 경우 보관료등 기타 추가 비용이 발생 할 수 있습니다.
A23: * 물품 출고 후 1주 후부터 보관료(최소 3불/CBM/day)가 발생하며, 특별한 사유 없이 2달 이상 보관 물품들은 임의로 폐기/처분 될 수 있습니다.
A24: 엘케이 (LK)무역 | H24: * 이용해 주셔서 감사합니다. | K24: 고객사 서명
