Workbook

Sheet Row data
B1: LK내부 환율 | H1: 할인 적용 목록
B2: 화폐 | C2: 기준 환율 | D2: 추가 환율 | E2: 적용 환율
B3: USD-KIP | C3: 23000 | D3: 1000 | E3: =C3+D3 -> 24000 | H3: 라선협 할인 | N3: 지상사협의회 회원사 할인 | U3: 법인장 지인 할인
B4: USD-THB | C4: 33 | D4: 1 | E4: =C4+D4 -> 34 | H4: 해상 | J4: 항공 | N4: 해상 | P4: 항공 | U4: 해상 | W4: 항공
B5: USD-WON | C5: 1515 | D5: 30 | E5: =C5+D5 -> 1545 | H5: 일반 | I5: 기부 | J5: 일반 | K5: 기부 | N5: 일반 | O5: 기부 | P5: 일반 | Q5: 기부 | U5: 일반 | V5: 기부 | W5: 일반 | X5: 기부
H6: 0.2 | I6: 0.3 | J6: 0.05 | K6: 0.1 | N6: 0.2 | O6: 0.3 | P6: 0.05 | Q6: 0.1 | U6: 5~10% | V6: 0.2 | W6: 0.05 | X6: 0.1
B8: 한국 세금 계산서 발급시 계좌번호 | H8: 이름 | J8: 할인율 | K8: 할인금액 | L8: 비 고 | N8: 이름 | P8: 회사 | Q8: 할인율 | R8: 할인금액 | S8: 비 고 | U8: 이름 | W8: 할인율 | X8: 할인금액 | Y8: 비 고
B9: 경남은행 2070133424601 박성호(엘케이무역) | H9: 강병준 | J9: 0.05 | N9: 노인철 | O9: 법인장 | P9: PNPC | Q9: 0.05 | U9: 김인섭 | V9: 요정 투어 (김요셉 형) | W9: 0.05
H10: 강성애 | J10: 0.05 | N10: 고영태 | O10: 부이사장 | P10: 라오스증권거래소 | Q10: 0.05 | U10: 서정진(서이사님) | W10: 0.05
B11: 일반 입금 | H11: 김민기 | J11: 0.05 | N11: 고중하 | O11: 대표 | P11: 젤라콘 | Q11: 0.05 | U11: 이형준 | V11: 골재 판매 | W11: 0.05
B12: 경남은행 571-22-0330221 박성호 | H12: 김재양/김반석 | I12: EZRA | J12: 0.05 | N12: 한조운 | O12: 법인장 | P12: iM Leasing | Q12: 0.05 | U12: 임홍식 | W12: 0.05
H13: 김세진 | J13: 0.05 | N13: 김지운 | O13: 법인장 | P13: BNK 캐피탈 라오스 | Q13: 0.05 | U13: 정석진 | W13: 0.3
B14: 한국-라오스 항공 xx항차 | H14: 김양현 | J14: 0.05 | N14: 고현식 | O14: 법인장 | P14: BNK 소액대출 MFI | Q14: 0.05 | U14: 최성식 | V14: 큐빅 바이크 | W14: 0.05
B15: Total | C15: =SUM('LKA 01:LKA XX'!R1) -> 0 | H15: 김영진 | J15: 0.05 | N15: 김일재 | O15: 법인장 | P15: 흥화라오스 | Q15: 0.05 | U15: 최재혁 | W15: 0.05
B16: Amount | C16: =SUM('LKA 01:LKA XX'!R2) -> 0 | H16: 김재광 | J16: 0.05 | N16: 박성호 | O16: 대표 | P16: LK Group | Q16: 0.05 | U16: 최지호 | W16: 0.05
H17: 김종한 | J17: 0.05 | N17: 백지원 | O17: 센터장 | P17: 라오스 EPS센터 | Q17: 0.05 | U17: 최현석 | W17: 0.05
B18: 총 할인 금액 | C18: =K67+R46+X20+X30+X44+X60 -> 0 | H18: 김종훈/김희영 | J18: 0.2 | N18: 송대영 | O18: 실장 | P18: DSA(K-LAO) | Q18: 0.05
H19: 김지훈 | J19: 0.05 | N19: 김민우 | O19: 법인장 | P19: DGB 라오 리싱 | Q19: 0.05
H20: 김창수 | J20: 0.05 | L20: 지방배송 | N20: 오유근/김연희 | O20: 법인장 | P20: 코웨포-라오 인터내셔널 | Q20: 0.05 | U20: 할인 총합 | X20: =SUM(X9:X19) -> 0
B21: 현지 발생 비용 | H21: 김필립/이은영 | J21: 0.05 | N21: 유병문 | O21: 법인장 | P21: 현진라오 | Q21: 0.05
B22: 날짜 | C22: 내 용 | D22: 킵 | H22: 박정민 | J22: 0.05 | N22: 최병한 | O22: 부사장 | P22: 삼안 | Q22: 0.05 | U22: 아파트 고객 할인
H23: 박종복 | J23: 0.05 | N23: 이범주 | O23: 단장, 전무 | P23: 삼안 | Q23: 0.05 | U23: 이름 | W23: 할인율 | X23: 할인금액 | Y23: 비 고
H24: 박진경 | I24: 본죽 | J24: 0.05 | N24: 이성한 | O24: 상무 | P24: 한국종합기술 | Q24: 0.05 | U24: 이동현 | V24: 101호 고객 | W24: 0.05
H25: 박창성 | J25: 0.05 | N25: 주인현 | O25: 법인장 | P25: KB 코라오 리싱 | Q25: 0.05 | U25: 정민주 | V25: 206호 고객 | W25: 0.05
H26: 백규현 | I26: 샤론스쿨 | J26: 0.05 | N26: 이재원 | O26: 대표 | P26: 그린굿스 | Q26: 0.05 | U26: 박상욱 | V26: 106호 고객 | W26: 0.05
H27: 백대식 | J27: 0.05 | N27: 이재현 | O27: 법인장 | P27: Paul Golden Lao(좋은차닷컴) | Q27: 0.05 | U27: 박상용 | V27: 301호 고객 | W27: 0.05
D28: =SUM(D23:D27) -> 0 | E28: =D28/C3 -> 0 | H28: 백상호 | J28: 0.05 | N28: 이제원 | O28: 법인장 | P28: 웰컴 리싱 라오 | Q28: 0.05 | U28: 진정우 | V28: 105호 고객 | W28: 0.1 | Y28: 기부
H29: 백운송 | J29: 0.05 | N29: 박준규/간현진/ 정지운(오지은)/이종원 | P29: KOTRA | Q29: 0.05
B30: 총 합산 액 | C30: =C16-E28 -> 0 | H30: 백총명 | J30: 0.05 | N30: 이창열 | O30: 부장 | P30: 라오스증권거래소 | Q30: 0.05 | U30: 할인 총합 | X30: =SUM(X24:X29) -> 0
H31: 변종승 | I31: 기쁜교회 | J31: 0.05 | N31: 이현열 | O31: 지점장 | P31: 에어부산 | Q31: 0.05
H32: 손사랑 | J32: 0.05 | L32: 지방배송 | N32: 임정민 | O32: 지점장 | P32: 제주항공 | Q32: 0.05 | U32: 기업 할인
H33: 신라함/신대웅 | J33: 0.05 | N33: 정석진 | O33: 지사장 | P33: LK Group | Q33: 0.05 | U33: 이름 | V33: 제품 | W33: 할인율 | X33: 할인금액 | Y33: 비 고
H34: 윤영숙/우상봉 | J34: 0.05 | N34: 최완식/고대종 | O34: 단장 | P34: 솔루텍시스템 라오 | Q34: 0.05 | U34: Love STK | V34: 다단계제품 | W34: 0.05
H35: 원순연 | J35: 0.05 | L35: 지방배송 | N35: 한태원 | O35: CEO | P35: 엘에스엠 | Q35: 0.05 | U35: Nice to meat you | W35: 0.05
H36: 곽낭아/이경희 | J36: 0.05 | L36: 지방배송 | N36: 황헌기 | O36: 대표 | P36: 정원상사 | Q36: 0.05 | U36: Peter Kim/Viengchay | V36: 성경책 | W36: 0.05
H37: 이관택/정유은 | J37: 0.05 | N37: 강남규 | O37: 부장 | P37: emart | Q37: 0.05 | U37: 김현민/라오스 국가대표 야구 감독 | W37: 0.05 | Y37: 대량 5%, 기부품 10% (사진 첨부 필)
H38: 이규상 | J38: 0.05 | N38: 정길영 | O38: 행장 | P38: 부영라오은행 | Q38: 0.05 | U38: 이우용 | V38: 유투버 | W38: 0.05 | Y38: 지방배송
H39: 이명숙/임기환 | J39: 0.05 | L39: (오혜창) | N39: 박대성 | O39: 차장 | P39: 부영라오 골프장 | Q39: 0.05 | U39: 배상국/정창옥 | W39: 0.05 | Y39: 대량 10%
H40: 이병목/장혜진 | J40: 0.05 | N40: 이성한 | O40: 상무 | P40: 한국종합기술 | Q40: 0.05 | U40: 참앤들/Lamthong Trading Co.,Ltd/ 권세욱/Wisit Limphothong | V40: 화장품 | W40: 0.05 | Y40: By KOTRA
H41: 이상미 | J41: 0.05 | N41: 김승용 | O41: 대표이사 | P41: 코코넛샤일로 | Q41: 0.05 | U41: Dani/Sky | V41: 커피머신 | W41: 0.05
...

Sheet 시내, 지방배송
A1: No. | B1: Name | C1: Name | D1: Tel | E1: Local company | F1: Destination Address | G1: Paid by
A2: 1 | B2: 구상채 / Oly | C2: Ku Sang Chae / Oly | D2: 020-5431-3355 020-5486-5440 | E2: HAL | F2: ສາຂາ ບ້ານ ປ່າອອ້ຍ, ຫວ້ຍຊາຍ, ບໍ່ແກ້ວ
E3: ANS
A4: 2 | B4: 김석현 | C4: KIM, Sukhyun | D4: 020-5566-8605 | E4: HAL | F4: Savannaket (ສາຂາ ຕະຫຼາດ ໃຫຍ່)
E5: ANS
A6: 3 | B6: 김영훈/010 2490 9081 | C6: KIM YoungHoon | D6: 020 9637 1027 | E6: HAL | F6: ສາຂາ ຫນອງຂຽວ, ເມືອງງອຍ
E7: ANS
A8: 4 | B8: 김정호 | C8: Mr. KIM Jung Ho | D8: '020-9697-1366 | E8: HAL | F8: Namngam village, paek district, xiengkhuang provice
E9: ANS
A10: 5 | B10: 김창수 | C10: Kim chang soo | D10: 020-5202-6723 | E10: HAL | F10: ແຟຣນຊີບມໍ
E11: ANS
A12: 6 | B12: 나유리 | C12: Ms. NA Yoo Ri | D12: 020-5538-6544 | E12: HAL | F12: LPB province
E13: ANS
A14: 7 | B14: 남미화 | C14: NAM, Mi Hwa | D14: 020 9593 7554 | E14: HAL | F14: ສາຂາ ບ້ານຊຽງມ່ວນ (ຕະຫລາດມືດ), ເມືອງຫລວງພະບາງ, ຫລວງພະບາງ
E15: ANS
A16: 8 | B16: 남윤천 | C16: NAM Yun Cheon | D16: 020 5550 8172 | E16: HAL | F16: ບ້ານມີໄຊ, Paksan, Bolikhamxai
E17: ANS
A18: 9 | B18: 문종곤 | C18: Mr. MOON Joong Gon | D18: 020 9956 0707 | E18: HAL | F18: Pakse city
E19: ANS
A20: 10 | B20: 백원상 | C20: Mr. BAIK woon song | D20: 020-5605-1991 | E20: HAL | F20: ປາຍທາງ xieng mouak village LPB district, LPB province
E21: ANS
A22: 11 | B22: 손사랑 | C22: Mr. SON Sa Rang | D22: 020-5959-1790 | E22: HAL | F22: Luangprabang city
E23: ANS
A24: 12 | B24: 쑤빈 | C24: Soubin | D24: 020-7777-1940 020-528-83018 | E24: HAL | F24: ກາສີ, ຕົວເມືອງກາສີ
E25: ANS
A26: 13 | B26: 우형철 | C26: Mr. WOO Hyung Chu | D26: 020-9505-3052 | E26: HAL | F26: PAKSE km8
E27: ANS
A28: 14 | B28: 윤성식 | C28: Mr. YOON Sung Sik | D28: 020-9604-3012 | E28: HAL | F28: Ban Keun Napheng
E29: ANS
A30: 15 | B30: 곽낭아/이경희 | C30: LEE kyung hee/ຈຳປາລີ | D30: 020-9550-5260 020-9784-4110 | E30: HAL | F30: Oudomxay Muangxay ໜອງແມງດາ
E31: ANS | F31: ສາຂາ ບ້ານບໍ່ ເມືອງໄຊ ແຂວງອຸດົມໄຊ
E32: ບໍລິສັດ ບັນດິດຂົນສົ່ງ (ຊົມພູ) ນະຄອນຫລວງ - ອຸດົມໄຊ 030-5471650, 020-9998-8884, 5547-6377 | F32: ບ້ານບໍ່ ເມືອງໄຊ ແຂວງອຸດົມໄຊ
A33: 16 | B33: 이복희 | C33: LEE Bok Hee | D33: 020-5547-0797 | E33: HAL | F33: ສາຂາ ສຸນັນທາ, Savannaket
E34: ANS
A35: 17 | B35: 이상호 | C35: LEE sang ho | D35: 020-9552-2978 | E35: HAL | F35: ອັດຕາປື ສາມັກຄີໄຊ 1
E36: ANS
A37: 18 | B37: 이우용 | C37: Seevisai Manephong | D37: 020-5847-7710 | E37: HAL | F37: ສາຂາ ຫນອງຂຽວ, ເມືອງງອຍ, ຫລວງພະບາງ
E38: ANS | F38: ສາຂາ ປ່ອງຄຳ ເມືອງຫຼວງພະບາງ ແຂວງຫຼວງພະບາງ
A39: 19 | B39: 이존희 | C39: LEE Jonhee | D39: 020-5625-9292 | E39: HAL | F39: ອັດຕາປື ສາມັກຄີໄຊ 1
E40: ANS
...

Sheet 물품 입고 내역
B1: 2026년 xx항차 항공 물품 입고 내역 (Cargo list)
B2: 배송자 | D2: LK그룹, LK무역 (LK Trading) | F2: 주소 | G2: 인천광역시 중구 항동 7가 104-7 드림물류센터 4층 1번도크 집하장 라오스 LK무역 수출 물량 | N2: 전화번호 | O2: +82) 32 -886 -9603
B3: 수령자 | D3: LK Group(LAKO Co., Ltd) | F3: 주소 | G3: 비엔티엔시, 씨싿따낙구, 싸판텅 느아 09, 11번 골목, LK 빌딩 | N3: 전화번호 | O3: +856) 20-9112-6780
B4: 접수 마감일 | D4: 2026-xx-xx | F4: 출항일 | G4: 2026-xx-xx | K4: 출발지 | L4: 한국 | N4: 도착지 | O4: 라오스
B5: No. | C5: 송장 번호 | D5: 발신인 | E5: 수신인 | F5: 전화번호 | G5: 내용물 | H5: 포장형태 | I5: 수량 | J5: 중량(KGS) | K5: L | L5: w | M5: H | N5: 영수 번호 | O5: 구획 | P5: 비고 | Q5: 접수일
A6: =N6&"_"&COUNTIF($N$6:N6,N6) -> _0 | B6: A001 | O6: 102
A7: =N7&"_"&COUNTIF($N$6:N7,N7) -> _0 | B7: A002 | O7: 102
A8: =N8&"_"&COUNTIF($N$6:N8,N8) -> _0 | B8: A003 | O8: 102
A9: =N9&"_"&COUNTIF($N$6:N9,N9) -> _0 | B9: A004 | O9: 102
A10: =N10&"_"&COUNTIF($N$6:N10,N10) -> _0 | B10: A005 | O10: 102
A11: =N11&"_"&COUNTIF($N$6:N11,N11) -> _0 | B11: A006 | O11: 102
A12: =N12&"_"&COUNTIF($N$6:N12,N12) -> _0 | B12: A007 | O12: 102
A13: =N13&"_"&COUNTIF($N$6:N13,N13) -> _0 | B13: A008 | O13: 102
A14: =N14&"_"&COUNTIF($N$6:N14,N14) -> _0 | B14: A009 | O14: 102
A15: =N15&"_"&COUNTIF($N$6:N15,N15) -> _0 | B15: A010 | O15: 102
A16: =N16&"_"&COUNTIF($N$6:N16,N16) -> _0 | B16: A011 | O16: 102
A17: =N17&"_"&COUNTIF($N$6:N17,N17) -> _0 | B17: A012 | O17: 102
... A105: =N105&"_"&COUNTIF($N$6:N105,N105) -> _0 | B105: A100 | O105: 102
B106: 총 물량 | H106: 박스 | I106: =SUM(I6:I105) -> 0
B107: 합포장 물량 | H107: 박스
B108: 합포장 개수 | H108: 박스
B109: 최종 실제 | H109: 박스 | I109: =I106-I107+I108 -> 0

Sheet 고객 리스트
A1: Kor-Lao Air xxth 고객 리스트 (ລາຍການລູກຄ້າຂອງທາງອາກາດ)
A2: 아래 고객님 본인 성함을 찾아 서명해 주시면 직원이 확인 후 출고 진행 도와드립니다.
A3: No. Bill | B3: 이 름 (ຊື່ ແລະ ນາມສະກຸນ) | C3: Area Categorized | D3: Item No. | E3: 서 명(ລາຍເຊັນ) | G3: 1 | H3: 2 | I3: 3 | J3: 4 | K3: 5 | L3: 6 | M3: 7 | N3: 8 | O3: 9 | P3: 10 | Q3: 11 | R3: 12 | S3: 13 | T3: 14 | U3: 15 | V3: 16 | W3: 17 | X3: 18 | Y3: 19 | Z3: 20 | AA3: 21 | AB3: 22 | AC3: 23 | AD3: 24 | AE3: 25 | AF3: 26 | AG3: 27 | AH3: 28 | AI3: 29 | AJ3: 30 | AK3: 31 | AL3: 32 | AM3: 33 | AN3: 34 | AO3: 35 | AP3: 36 | AQ3: 37 | AR3: 38 | AS3: 39 | AT3: 40 | AU3: 41 | AV3: 42 | AW3: 43 | AX3: 44 | AY3: 45 | AZ3: 46 | BA3: 47 | BB3: 48 | BC3: 49 | BD3: 50 | BE3: 51 | BF3: 52 | BG3: 53 | BH3: 54 | BI3: 55 | BJ3: 56 | BK3: 57 | BL3: 58 | BM3: 59 | BN3: 60 | BO3: 61 | BP3: 62 | BQ3: 63 | BR3: 64 | BS3: 65 | BT3: 66 | BU3: 67 | BV3: 68 | BW3: 69 | BX3: 70 | BY3: 71 | BZ3: 72 | CA3: 73 | CB3: 74 | CC3: 75 | CD3: 76 | CE3: 77 | CF3: 78 | CG3: 79 | CH3: 80 | CI3: 81 | CJ3: 82 | CK3: 83 | CL3: 84 | CM3: 85 | CN3: 86 | CO3: 87 | CP3: 88 | CQ3: 89 | CR3: 90 | CS3: 91 | CT3: 92 | CU3: 93 | CV3: 94 | CW3: 95 | CX3: 96 | CY3: 97 | CZ3: 98 | DA3: 99 | DB3: 100
A4: LKA 01 | B4: =IFERROR(INDEX('물품 입고 내역'!$E$6:$N$105,MATCH($A4,'물품 입고 내역'!$N$6:$N$105,0),1)," ") | C4: 102 | D4: =CONCATENATE(G4," ",H4," ",I4," ",J4," ",K4," ",L4," ",M4," ",N4," ",O4," ",P4," ",Q4," ",R4," ",S4," ",T4," ",U4," ",V4," ",W4," ",X4," ",Y4," ",Z4," ",AA4," ",AB4," ",AC4," ",AD4," ",AE4," ",AF4," ",AG4," ",AH4," ",AI4," ",AJ4," ",AK4," ",AL4," ",AM4," ",AN4," ",AO4," ",AP4," ",AQ4," ",AR4," ",AS4," ",AT4," ",AU4," ",AV4," ",AW4," ",AX4," ",AY4," ",AZ4," ",BA4," ",BB4," ",BC4," ",BD4," ",BE4," ",BF4," ",BG4," ",BH4," ",BI4," ",BJ4," ",BK4," ",BL4," ",BM4," ",BN4," ",BO4," ",BP4," ",BQ4," ",BR4," ",BS4," ",BT4," ",BU4," ",BV4," ",BW4," ",BX4," ",BY4," ",BZ4," ",CA4," ",CB4," ",CC4," ",CD4," ",CE4," ",CF4," ",CG4," ",CH4," ",CI4," ",CJ4," ",CK4," ",CL4," ",CM4," ",CN4," ",CO4," ",CP4," ",CQ4," ",CR4," ",CS4," ",CT4," ",CU4," ",CV4," ",CW4," ",CX4," ",CY4," ",CZ4," ",DA4," ",DB4) | F4: =COUNTA(G4:DB4)-COUNTBLANK(G4:DB4) -> 0 | G4: =IFERROR(VLOOKUP($A4&"_"&G$3,'물품 입고 내역'!$A$5:$O$629,2,0),"") | H4: =IFERROR(VLOOKUP($A4&"_"&H$3,'물품 입고 내역'!$A$5:$O$629,2,0),"") | I4: =IFERROR(VLOOKUP($A4&"_"&I$3,'물품 입고 내역'!$A$5:$O$629,2,0),"") | J4: =IFERROR(VLOOKUP($A4&"_"&J$3,'물품 입고 내역'!$A$5:$O$629,2,0),"") | K4: =IFERROR(VLOOKUP($A4&"_"&K$3,'물품 입고 내역'!$A$5:$O$629,2,0),"") | L4: =IFERROR(VLOOKUP($A4&"_"&L$3,'물품 입고 내역'!$A$5:$O$629,2,0),"") | M4: =IFERROR(VLOOKUP($A4&"_"&M$3,'물품 입고 내역'!$A$5:$O$629,2,0),"") | N4: =IFERROR(VLOOKUP($A4&"_"&N$3,'물품 입고 내역'!$A$5:$O$629,2,0),"") | ... DB4: =IFERROR(VLOOKUP($A4&"_"&DB$3,'물품 입고 내역'!$A$5:$O$629,2,0),"")
A5: LKA 02 | B5: =IFERROR(INDEX('물품 입고 내역'!$E$6:$N$105,MATCH($A5,'물품 입고 내역'!$N$6:$N$105,0),1)," ") | C5: 102 | D5: =CONCATENATE(G5," ",H5," ",I5," ",J5," ",K5," ",L5," ",M5," ",N5," ",O5," ",P5," ",Q5," ",R5," ",S5," ",T5," ",U5," ",V5," ",W5," ",X5," ",Y5," ",Z5," ",AA5," ",AB5," ",AC5," ",AD5," ",AE5," ",AF5," ",AG5," ",AH5," ",AI5," ",AJ5," ",AK5," ",AL5," ",AM5," ",AN5," ",AO5," ",AP5," ",AQ5," ",AR5," ",AS5," ",AT5," ",AU5," ",AV5," ",AW5," ",AX5," ",AY5," ",AZ5," ",BA5," ",BB5," ",BC5," ",BD5," ",BE5," ",BF5," ",BG5," ",BH5," ",BI5," ",BJ5," ",BK5," ",BL5," ",BM5," ",BN5," ",BO5," ",BP5," ",BQ5," ",BR5," ",BS5," ",BT5," ",BU5," ",BV5," ",BW5," ",BX5," ",BY5," ",BZ5," ",CA5," ",CB5," ",CC5," ",CD5," ",CE5," ",CF5," ",CG5," ",CH5," ",CI5," ",CJ5," ",CK5," ",CL5," ",CM5," ",CN5," ",CO5," ",CP5," ",CQ5," ",CR5," ",CS5," ",CT5," ",CU5," ",CV5," ",CW5," ",CX5," ",CY5," ",CZ5," ",DA5," ",DB5) | F5: =COUNTA(G5:DB5)-COUNTBLANK(G5:DB5) -> 0 | G5: =IFERROR(VLOOKUP($A5&"_"&G$3,'물품 입고 내역'!$A$5:$O$629,2,0),"") | H5: =IFERROR(VLOOKUP($A5&"_"&H$3,'물품 입고 내역'!$A$5:$O$629,2,0),"") | I5: =IFERROR(VLOOKUP($A5&"_"&I$3,'물품 입고 내역'!$A$5:$O$629,2,0),"") | J5: =IFERROR(VLOOKUP($A5&"_"&J$3,'물품 입고 내역'!$A$5:$O$629,2,0),"") | K5: =IFERROR(VLOOKUP($A5&"_"&K$3,'물품 입고 내역'!$A$5:$O$629,2,0),"") | L5: =IFERROR(VLOOKUP($A5&"_"&L$3,'물품 입고 내역'!$A$5:$O$629,2,0),"") | M5: =IFERROR(VLOOKUP($A5&"_"&M$3,'물품 입고 내역'!$A$5:$O$629,2,0),"") | N5: =IFERROR(VLOOKUP($A5&"_"&N$3,'물품 입고 내역'!$A$5:$O$629,2,0),"") | ... DB5: =IFERROR(VLOOKUP($A5&"_"&DB$3,'물품 입고 내역'!$A$5:$O$629,2,0),"")
A6: LKA 03 | B6: =IFERROR(INDEX('물품 입고 내역'!$E$6:$N$105,MATCH($A6,'물품 입고 내역'!$N$6:$N$105,0),1)," ") | C6: 102 | D6: =CONCATENATE(G6," ",H6," ",I6," ",J6," ",K6," ",L6," ",M6," ",N6," ",O6," ",P6," ",Q6," ",R6," ",S6," ",T6," ",U6," ",V6," ",W6," ",X6," ",Y6," ",Z6," ",AA6," ",AB6," ",AC6," ",AD6," ",AE6," ",AF6," ",AG6," ",AH6," ",AI6," ",AJ6," ",AK6," ",AL6," ",AM6," ",AN6," ",AO6," ",AP6," ",AQ6," ",AR6," ",AS6," ",AT6," ",AU6," ",AV6," ",AW6," ",AX6," ",AY6," ",AZ6," ",BA6," ",BB6," ",BC6," ",BD6," ",BE6," ",BF6," ",BG6," ",BH6," ",BI6," ",BJ6," ",BK6," ",BL6," ",BM6," ",BN6," ",BO6," ",BP6," ",BQ6," ",BR6," ",BS6," ",BT6," ",BU6," ",BV6," ",BW6," ",BX6," ",BY6," ",BZ6," ",CA6," ",CB6," ",CC6," ",CD6," ",CE6," ",CF6," ",CG6," ",CH6," ",CI6," ",CJ6," ",CK6," ",CL6," ",CM6," ",CN6," ",CO6," ",CP6," ",CQ6," ",CR6," ",CS6," ",CT6," ",CU6," ",CV6," ",CW6," ",CX6," ",CY6," ",CZ6," ",DA6," ",DB6) | F6: =COUNTA(G6:DB6)-COUNTBLANK(G6:DB6) -> 0 | G6: =IFERROR(VLOOKUP($A6&"_"&G$3,'물품 입고 내역'!$A$5:$O$629,2,0),"") | H6: =IFERROR(VLOOKUP($A6&"_"&H$3,'물품 입고 내역'!$A$5:$O$629,2,0),"") | I6: =IFERROR(VLOOKUP($A6&"_"&I$3,'물품 입고 내역'!$A$5:$O$629,2,0),"") | J6: =IFERROR(VLOOKUP($A6&"_"&J$3,'물품 입고 내역'!$A$5:$O$629,2,0),"") | K6: =IFERROR(VLOOKUP($A6&"_"&K$3,'물품 입고 내역'!$A$5:$O$629,2,0),"") | L6: =IFERROR(VLOOKUP($A6&"_"&L$3,'물품 입고 내역'!$A$5:$O$629,2,0),"") | M6: =IFERROR(VLOOKUP($A6&"_"&M$3,'물품 입고 내역'!$A$5:$O$629,2,0),"") | N6: =IFERROR(VLOOKUP($A6&"_"&N$3,'물품 입고 내역'!$A$5:$O$629,2,0),"") | ... DB6: =IFERROR(VLOOKUP($A6&"_"&DB$3,'물품 입고 내역'!$A$5:$O$629,2,0),"")
A7: LKA 04 | B7: =IFERROR(INDEX('물품 입고 내역'!$E$6:$N$105,MATCH($A7,'물품 입고 내역'!$N$6:$N$105,0),1)," ") | C7: 102 | D7: =CONCATENATE(G7," ",H7," ",I7," ",J7," ",K7," ",L7," ",M7," ",N7," ",O7," ",P7," ",Q7," ",R7," ",S7," ",T7," ",U7," ",V7," ",W7," ",X7," ",Y7," ",Z7," ",AA7," ",AB7," ",AC7," ",AD7," ",AE7," ",AF7," ",AG7," ",AH7," ",AI7," ",AJ7," ",AK7," ",AL7," ",AM7," ",AN7," ",AO7," ",AP7," ",AQ7," ",AR7," ",AS7," ",AT7," ",AU7," ",AV7," ",AW7," ",AX7," ",AY7," ",AZ7," ",BA7," ",BB7," ",BC7," ",BD7," ",BE7," ",BF7," ",BG7," ",BH7," ",BI7," ",BJ7," ",BK7," ",BL7," ",BM7," ",BN7," ",BO7," ",BP7," ",BQ7," ",BR7," ",BS7," ",BT7," ",BU7," ",BV7," ",BW7," ",BX7," ",BY7," ",BZ7," ",CA7," ",CB7," ",CC7," ",CD7," ",CE7," ",CF7," ",CG7," ",CH7," ",CI7," ",CJ7," ",CK7," ",CL7," ",CM7," ",CN7," ",CO7," ",CP7," ",CQ7," ",CR7," ",CS7," ",CT7," ",CU7," ",CV7," ",CW7," ",CX7," ",CY7," ",CZ7," ",DA7," ",DB7) | F7: =COUNTA(G7:DB7)-COUNTBLANK(G7:DB7) -> 0 | G7: =IFERROR(VLOOKUP($A7&"_"&G$3,'물품 입고 내역'!$A$5:$O$629,2,0),"") | H7: =IFERROR(VLOOKUP($A7&"_"&H$3,'물품 입고 내역'!$A$5:$O$629,2,0),"") | I7: =IFERROR(VLOOKUP($A7&"_"&I$3,'물품 입고 내역'!$A$5:$O$629,2,0),"") | J7: =IFERROR(VLOOKUP($A7&"_"&J$3,'물품 입고 내역'!$A$5:$O$629,2,0),"") | K7: =IFERROR(VLOOKUP($A7&"_"&K$3,'물품 입고 내역'!$A$5:$O$629,2,0),"") | L7: =IFERROR(VLOOKUP($A7&"_"&L$3,'물품 입고 내역'!$A$5:$O$629,2,0),"") | M7: =IFERROR(VLOOKUP($A7&"_"&M$3,'물품 입고 내역'!$A$5:$O$629,2,0),"") | N7: =IFERROR(VLOOKUP($A7&"_"&N$3,'물품 입고 내역'!$A$5:$O$629,2,0),"") | ... DB7: =IFERROR(VLOOKUP($A7&"_"&DB$3,'물품 입고 내역'!$A$5:$O$629,2,0),"")
A8: LKA 05 | B8: =IFERROR(INDEX('물품 입고 내역'!$E$6:$N$105,MATCH($A8,'물품 입고 내역'!$N$6:$N$105,0),1)," ") | C8: 102 | D8: =CONCATENATE(G8," ",H8," ",I8," ",J8," ",K8," ",L8," ",M8," ",N8," ",O8," ",P8," ",Q8," ",R8," ",S8," ",T8," ",U8," ",V8," ",W8," ",X8," ",Y8," ",Z8," ",AA8," ",AB8," ",AC8," ",AD8," ",AE8," ",AF8," ",AG8," ",AH8," ",AI8," ",AJ8," ",AK8," ",AL8," ",AM8," ",AN8," ",AO8," ",AP8," ",AQ8," ",AR8," ",AS8," ",AT8," ",AU8," ",AV8," ",AW8," ",AX8," ",AY8," ",AZ8," ",BA8," ",BB8," ",BC8," ",BD8," ",BE8," ",BF8," ",BG8," ",BH8," ",BI8," ",BJ8," ",BK8," ",BL8," ",BM8," ",BN8," ",BO8," ",BP8," ",BQ8," ",BR8," ",BS8," ",BT8," ",BU8," ",BV8," ",BW8," ",BX8," ",BY8," ",BZ8," ",CA8," ",CB8," ",CC8," ",CD8," ",CE8," ",CF8," ",CG8," ",CH8," ",CI8," ",CJ8," ",CK8," ",CL8," ",CM8," ",CN8," ",CO8," ",CP8," ",CQ8," ",CR8," ",CS8," ",CT8," ",CU8," ",CV8," ",CW8," ",CX8," ",CY8," ",CZ8," ",DA8," ",DB8) | F8: =COUNTA(G8:DB8)-COUNTBLANK(G8:DB8) -> 0 | G8: =IFERROR(VLOOKUP($A8&"_"&G$3,'물품 입고 내역'!$A$5:$O$629,2,0),"") | H8: =IFERROR(VLOOKUP($A8&"_"&H$3,'물품 입고 내역'!$A$5:$O$629,2,0),"") | I8: =IFERROR(VLOOKUP($A8&"_"&I$3,'물품 입고 내역'!$A$5:$O$629,2,0),"") | J8: =IFERROR(VLOOKUP($A8&"_"&J$3,'물품 입고 내역'!$A$5:$O$629,2,0),"") | K8: =IFERROR(VLOOKUP($A8&"_"&K$3,'물품 입고 내역'!$A$5:$O$629,2,0),"") | L8: =IFERROR(VLOOKUP($A8&"_"&L$3,'물품 입고 내역'!$A$5:$O$629,2,0),"") | M8: =IFERROR(VLOOKUP($A8&"_"&M$3,'물품 입고 내역'!$A$5:$O$629,2,0),"") | N8: =IFERROR(VLOOKUP($A8&"_"&N$3,'물품 입고 내역'!$A$5:$O$629,2,0),"") | ... DB8: =IFERROR(VLOOKUP($A8&"_"&DB$3,'물품 입고 내역'!$A$5:$O$629,2,0),"")
A9: LKA 06 | B9: =IFERROR(INDEX('물품 입고 내역'!$E$6:$N$105,MATCH($A9,'물품 입고 내역'!$N$6:$N$105,0),1)," ") | C9: 102 | D9: =CONCATENATE(G9," ",H9," ",I9," ",J9," ",K9," ",L9," ",M9," ",N9," ",O9," ",P9," ",Q9," ",R9," ",S9," ",T9," ",U9," ",V9," ",W9," ",X9," ",Y9," ",Z9," ",AA9," ",AB9," ",AC9," ",AD9," ",AE9," ",AF9," ",AG9," ",AH9," ",AI9," ",AJ9," ",AK9," ",AL9," ",AM9," ",AN9," ",AO9," ",AP9," ",AQ9," ",AR9," ",AS9," ",AT9," ",AU9," ",AV9," ",AW9," ",AX9," ",AY9," ",AZ9," ",BA9," ",BB9," ",BC9," ",BD9," ",BE9," ",BF9," ",BG9," ",BH9," ",BI9," ",BJ9," ",BK9," ",BL9," ",BM9," ",BN9," ",BO9," ",BP9," ",BQ9," ",BR9," ",BS9," ",BT9," ",BU9," ",BV9," ",BW9," ",BX9," ",BY9," ",BZ9," ",CA9," ",CB9," ",CC9," ",CD9," ",CE9," ",CF9," ",CG9," ",CH9," ",CI9," ",CJ9," ",CK9," ",CL9," ",CM9," ",CN9," ",CO9," ",CP9," ",CQ9," ",CR9," ",CS9," ",CT9," ",CU9," ",CV9," ",CW9," ",CX9," ",CY9," ",CZ9," ",DA9," ",DB9) | F9: =COUNTA(G9:DB9)-COUNTBLANK(G9:DB9) -> 0 | G9: =IFERROR(VLOOKUP($A9&"_"&G$3,'물품 입고 내역'!$A$5:$O$629,2,0),"") | H9: =IFERROR(VLOOKUP($A9&"_"&H$3,'물품 입고 내역'!$A$5:$O$629,2,0),"") | I9: =IFERROR(VLOOKUP($A9&"_"&I$3,'물품 입고 내역'!$A$5:$O$629,2,0),"") | J9: =IFERROR(VLOOKUP($A9&"_"&J$3,'물품 입고 내역'!$A$5:$O$629,2,0),"") | K9: =IFERROR(VLOOKUP($A9&"_"&K$3,'물품 입고 내역'!$A$5:$O$629,2,0),"") | L9: =IFERROR(VLOOKUP($A9&"_"&L$3,'물품 입고 내역'!$A$5:$O$629,2,0),"") | M9: =IFERROR(VLOOKUP($A9&"_"&M$3,'물품 입고 내역'!$A$5:$O$629,2,0),"") | N9: =IFERROR(VLOOKUP($A9&"_"&N$3,'물품 입고 내역'!$A$5:$O$629,2,0),"") | ... DB9: =IFERROR(VLOOKUP($A9&"_"&DB$3,'물품 입고 내역'!$A$5:$O$629,2,0),"")
A10: LKA 07 | B10: =IFERROR(INDEX('물품 입고 내역'!$E$6:$N$105,MATCH($A10,'물품 입고 내역'!$N$6:$N$105,0),1)," ") | C10: 102 | D10: =CONCATENATE(G10," ",H10," ",I10," ",J10," ",K10," ",L10," ",M10," ",N10," ",O10," ",P10," ",Q10," ",R10," ",S10," ",T10," ",U10," ",V10," ",W10," ",X10," ",Y10," ",Z10," ",AA10," ",AB10," ",AC10," ",AD10," ",AE10," ",AF10," ",AG10," ",AH10," ",AI10," ",AJ10," ",AK10," ",AL10," ",AM10," ",AN10," ",AO10," ",AP10," ",AQ10," ",AR10," ",AS10," ",AT10," ",AU10," ",AV10," ",AW10," ",AX10," ",AY10," ",AZ10," ",BA10," ",BB10," ",BC10," ",BD10," ",BE10," ",BF10," ",BG10," ",BH10," ",BI10," ",BJ10," ",BK10," ",BL10," ",BM10," ",BN10," ",BO10," ",BP10," ",BQ10," ",BR10," ",BS10," ",BT10," ",BU10," ",BV10," ",BW10," ",BX10," ",BY10," ",BZ10," ",CA10," ",CB10," ",CC10," ",CD10," ",CE10," ",CF10," ",CG10," ",CH10," ",CI10," ",CJ10," ",CK10," ",CL10," ",CM10," ",CN10," ",CO10," ",CP10," ",CQ10," ",CR10," ",CS10," ",CT10," ",CU10," ",CV10," ",CW10," ",CX10," ",CY10," ",CZ10," ",DA10," ",DB10) | F10: =COUNTA(G10:DB10)-COUNTBLANK(G10:DB10) -> 0 | G10: =IFERROR(VLOOKUP($A10&"_"&G$3,'물품 입고 내역'!$A$5:$O$629,2,0),"") | H10: =IFERROR(VLOOKUP($A10&"_"&H$3,'물품 입고 내역'!$A$5:$O$629,2,0),"") | I10: =IFERROR(VLOOKUP($A10&"_"&I$3,'물품 입고 내역'!$A$5:$O$629,2,0),"") | J10: =IFERROR(VLOOKUP($A10&"_"&J$3,'물품 입고 내역'!$A$5:$O$629,2,0),"") | K10: =IFERROR(VLOOKUP($A10&"_"&K$3,'물품 입고 내역'!$A$5:$O$629,2,0),"") | L10: =IFERROR(VLOOKUP($A10&"_"&L$3,'물품 입고 내역'!$A$5:$O$629,2,0),"") | M10: =IFERROR(VLOOKUP($A10&"_"&M$3,'물품 입고 내역'!$A$5:$O$629,2,0),"") | N10: =IFERROR(VLOOKUP($A10&"_"&N$3,'물품 입고 내역'!$A$5:$O$629,2,0),"") | ... DB10: =IFERROR(VLOOKUP($A10&"_"&DB$3,'물품 입고 내역'!$A$5:$O$629,2,0),"")
A11: LKA 08 | B11: =IFERROR(INDEX('물품 입고 내역'!$E$6:$N$105,MATCH($A11,'물품 입고 내역'!$N$6:$N$105,0),1)," ") | C11: 102 | D11: =CONCATENATE(G11," ",H11," ",I11," ",J11," ",K11," ",L11," ",M11," ",N11," ",O11," ",P11," ",Q11," ",R11," ",S11," ",T11," ",U11," ",V11," ",W11," ",X11," ",Y11," ",Z11," ",AA11," ",AB11," ",AC11," ",AD11," ",AE11," ",AF11," ",AG11," ",AH11," ",AI11," ",AJ11," ",AK11," ",AL11," ",AM11," ",AN11," ",AO11," ",AP11," ",AQ11," ",AR11," ",AS11," ",AT11," ",AU11," ",AV11," ",AW11," ",AX11," ",AY11," ",AZ11," ",BA11," ",BB11," ",BC11," ",BD11," ",BE11," ",BF11," ",BG11," ",BH11," ",BI11," ",BJ11," ",BK11," ",BL11," ",BM11," ",BN11," ",BO11," ",BP11," ",BQ11," ",BR11," ",BS11," ",BT11," ",BU11," ",BV11," ",BW11," ",BX11," ",BY11," ",BZ11," ",CA11," ",CB11," ",CC11," ",CD11," ",CE11," ",CF11," ",CG11," ",CH11," ",CI11," ",CJ11," ",CK11," ",CL11," ",CM11," ",CN11," ",CO11," ",CP11," ",CQ11," ",CR11," ",CS11," ",CT11," ",CU11," ",CV11," ",CW11," ",CX11," ",CY11," ",CZ11," ",DA11," ",DB11) | F11: =COUNTA(G11:DB11)-COUNTBLANK(G11:DB11) -> 0 | G11: =IFERROR(VLOOKUP($A11&"_"&G$3,'물품 입고 내역'!$A$5:$O$629,2,0),"") | H11: =IFERROR(VLOOKUP($A11&"_"&H$3,'물품 입고 내역'!$A$5:$O$629,2,0),"") | I11: =IFERROR(VLOOKUP($A11&"_"&I$3,'물품 입고 내역'!$A$5:$O$629,2,0),"") | J11: =IFERROR(VLOOKUP($A11&"_"&J$3,'물품 입고 내역'!$A$5:$O$629,2,0),"") | K11: =IFERROR(VLOOKUP($A11&"_"&K$3,'물품 입고 내역'!$A$5:$O$629,2,0),"") | L11: =IFERROR(VLOOKUP($A11&"_"&L$3,'물품 입고 내역'!$A$5:$O$629,2,0),"") | M11: =IFERROR(VLOOKUP($A11&"_"&M$3,'물품 입고 내역'!$A$5:$O$629,2,0),"") | N11: =IFERROR(VLOOKUP($A11&"_"&N$3,'물품 입고 내역'!$A$5:$O$629,2,0),"") | ... DB11: =IFERROR(VLOOKUP($A11&"_"&DB$3,'물품 입고 내역'!$A$5:$O$629,2,0),"")
A12: LKA 09 | B12: =IFERROR(INDEX('물품 입고 내역'!$E$6:$N$105,MATCH($A12,'물품 입고 내역'!$N$6:$N$105,0),1)," ") | C12: 102 | D12: =CONCATENATE(G12," ",H12," ",I12," ",J12," ",K12," ",L12," ",M12," ",N12," ",O12," ",P12," ",Q12," ",R12," ",S12," ",T12," ",U12," ",V12," ",W12," ",X12," ",Y12," ",Z12," ",AA12," ",AB12," ",AC12," ",AD12," ",AE12," ",AF12," ",AG12," ",AH12," ",AI12," ",AJ12," ",AK12," ",AL12," ",AM12," ",AN12," ",AO12," ",AP12," ",AQ12," ",AR12," ",AS12," ",AT12," ",AU12," ",AV12," ",AW12," ",AX12," ",AY12," ",AZ12," ",BA12," ",BB12," ",BC12," ",BD12," ",BE12," ",BF12," ",BG12," ",BH12," ",BI12," ",BJ12," ",BK12," ",BL12," ",BM12," ",BN12," ",BO12," ",BP12," ",BQ12," ",BR12," ",BS12," ",BT12," ",BU12," ",BV12," ",BW12," ",BX12," ",BY12," ",BZ12," ",CA12," ",CB12," ",CC12," ",CD12," ",CE12," ",CF12," ",CG12," ",CH12," ",CI12," ",CJ12," ",CK12," ",CL12," ",CM12," ",CN12," ",CO12," ",CP12," ",CQ12," ",CR12," ",CS12," ",CT12," ",CU12," ",CV12," ",CW12," ",CX12," ",CY12," ",CZ12," ",DA12," ",DB12) | F12: =COUNTA(G12:DB12)-COUNTBLANK(G12:DB12) -> 0 | G12: =IFERROR(VLOOKUP($A12&"_"&G$3,'물품 입고 내역'!$A$5:$O$629,2,0),"") | H12: =IFERROR(VLOOKUP($A12&"_"&H$3,'물품 입고 내역'!$A$5:$O$629,2,0),"") | I12: =IFERROR(VLOOKUP($A12&"_"&I$3,'물품 입고 내역'!$A$5:$O$629,2,0),"") | J12: =IFERROR(VLOOKUP($A12&"_"&J$3,'물품 입고 내역'!$A$5:$O$629,2,0),"") | K12: =IFERROR(VLOOKUP($A12&"_"&K$3,'물품 입고 내역'!$A$5:$O$629,2,0),"") | L12: =IFERROR(VLOOKUP($A12&"_"&L$3,'물품 입고 내역'!$A$5:$O$629,2,0),"") | M12: =IFERROR(VLOOKUP($A12&"_"&M$3,'물품 입고 내역'!$A$5:$O$629,2,0),"") | N12: =IFERROR(VLOOKUP($A12&"_"&N$3,'물품 입고 내역'!$A$5:$O$629,2,0),"") | ... DB12: =IFERROR(VLOOKUP($A12&"_"&DB$3,'물품 입고 내역'!$A$5:$O$629,2,0),"")
A13: LKA 10 | B13: =IFERROR(INDEX('물품 입고 내역'!$E$6:$N$105,MATCH($A13,'물품 입고 내역'!$N$6:$N$105,0),1)," ") | C13: 102 | D13: =CONCATENATE(G13," ",H13," ",I13," ",J13," ",K13," ",L13," ",M13," ",N13," ",O13," ",P13," ",Q13," ",R13," ",S13," ",T13," ",U13," ",V13," ",W13," ",X13," ",Y13," ",Z13," ",AA13," ",AB13," ",AC13," ",AD13," ",AE13," ",AF13," ",AG13," ",AH13," ",AI13," ",AJ13," ",AK13," ",AL13," ",AM13," ",AN13," ",AO13," ",AP13," ",AQ13," ",AR13," ",AS13," ",AT13," ",AU13," ",AV13," ",AW13," ",AX13," ",AY13," ",AZ13," ",BA13," ",BB13," ",BC13," ",BD13," ",BE13," ",BF13," ",BG13," ",BH13," ",BI13," ",BJ13," ",BK13," ",BL13," ",BM13," ",BN13," ",BO13," ",BP13," ",BQ13," ",BR13," ",BS13," ",BT13," ",BU13," ",BV13," ",BW13," ",BX13," ",BY13," ",BZ13," ",CA13," ",CB13," ",CC13," ",CD13," ",CE13," ",CF13," ",CG13," ",CH13," ",CI13," ",CJ13," ",CK13," ",CL13," ",CM13," ",CN13," ",CO13," ",CP13," ",CQ13," ",CR13," ",CS13," ",CT13," ",CU13," ",CV13," ",CW13," ",CX13," ",CY13," ",CZ13," ",DA13," ",DB13) | F13: =COUNTA(G13:DB13)-COUNTBLANK(G13:DB13) -> 0 | G13: =IFERROR(VLOOKUP($A13&"_"&G$3,'물품 입고 내역'!$A$5:$O$629,2,0),"") | H13: =IFERROR(VLOOKUP($A13&"_"&H$3,'물품 입고 내역'!$A$5:$O$629,2,0),"") | I13: =IFERROR(VLOOKUP($A13&"_"&I$3,'물품 입고 내역'!$A$5:$O$629,2,0),"") | J13: =IFERROR(VLOOKUP($A13&"_"&J$3,'물품 입고 내역'!$A$5:$O$629,2,0),"") | K13: =IFERROR(VLOOKUP($A13&"_"&K$3,'물품 입고 내역'!$A$5:$O$629,2,0),"") | L13: =IFERROR(VLOOKUP($A13&"_"&L$3,'물품 입고 내역'!$A$5:$O$629,2,0),"") | M13: =IFERROR(VLOOKUP($A13&"_"&M$3,'물품 입고 내역'!$A$5:$O$629,2,0),"") | N13: =IFERROR(VLOOKUP($A13&"_"&N$3,'물품 입고 내역'!$A$5:$O$629,2,0),"") | ... DB13: =IFERROR(VLOOKUP($A13&"_"&DB$3,'물품 입고 내역'!$A$5:$O$629,2,0),"")
A14: LKA 11 | B14: =IFERROR(INDEX('물품 입고 내역'!$E$6:$N$105,MATCH($A14,'물품 입고 내역'!$N$6:$N$105,0),1)," ") | C14: 102 | D14: =CONCATENATE(G14," ",H14," ",I14," ",J14," ",K14," ",L14," ",M14," ",N14," ",O14," ",P14," ",Q14," ",R14," ",S14," ",T14," ",U14," ",V14," ",W14," ",X14," ",Y14," ",Z14," ",AA14," ",AB14," ",AC14," ",AD14," ",AE14," ",AF14," ",AG14," ",AH14," ",AI14," ",AJ14," ",AK14," ",AL14," ",AM14," ",AN14," ",AO14," ",AP14," ",AQ14," ",AR14," ",AS14," ",AT14," ",AU14," ",AV14," ",AW14," ",AX14," ",AY14," ",AZ14," ",BA14," ",BB14," ",BC14," ",BD14," ",BE14," ",BF14," ",BG14," ",BH14," ",BI14," ",BJ14," ",BK14," ",BL14," ",BM14," ",BN14," ",BO14," ",BP14," ",BQ14," ",BR14," ",BS14," ",BT14," ",BU14," ",BV14," ",BW14," ",BX14," ",BY14," ",BZ14," ",CA14," ",CB14," ",CC14," ",CD14," ",CE14," ",CF14," ",CG14," ",CH14," ",CI14," ",CJ14," ",CK14," ",CL14," ",CM14," ",CN14," ",CO14," ",CP14," ",CQ14," ",CR14," ",CS14," ",CT14," ",CU14," ",CV14," ",CW14," ",CX14," ",CY14," ",CZ14," ",DA14," ",DB14) | F14: =COUNTA(G14:DB14)-COUNTBLANK(G14:DB14) -> 0 | G14: =IFERROR(VLOOKUP($A14&"_"&G$3,'물품 입고 내역'!$A$5:$O$629,2,0),"") | H14: =IFERROR(VLOOKUP($A14&"_"&H$3,'물품 입고 내역'!$A$5:$O$629,2,0),"") | I14: =IFERROR(VLOOKUP($A14&"_"&I$3,'물품 입고 내역'!$A$5:$O$629,2,0),"") | J14: =IFERROR(VLOOKUP($A14&"_"&J$3,'물품 입고 내역'!$A$5:$O$629,2,0),"") | K14: =IFERROR(VLOOKUP($A14&"_"&K$3,'물품 입고 내역'!$A$5:$O$629,2,0),"") | L14: =IFERROR(VLOOKUP($A14&"_"&L$3,'물품 입고 내역'!$A$5:$O$629,2,0),"") | M14: =IFERROR(VLOOKUP($A14&"_"&M$3,'물품 입고 내역'!$A$5:$O$629,2,0),"") | N14: =IFERROR(VLOOKUP($A14&"_"&N$3,'물품 입고 내역'!$A$5:$O$629,2,0),"") | ... DB14: =IFERROR(VLOOKUP($A14&"_"&DB$3,'물품 입고 내역'!$A$5:$O$629,2,0),"")
A15: LKA 12 | B15: =IFERROR(INDEX('물품 입고 내역'!$E$6:$N$105,MATCH($A15,'물품 입고 내역'!$N$6:$N$105,0),1)," ") | C15: 102 | D15: =CONCATENATE(G15," ",H15," ",I15," ",J15," ",K15," ",L15," ",M15," ",N15," ",O15," ",P15," ",Q15," ",R15," ",S15," ",T15," ",U15," ",V15," ",W15," ",X15," ",Y15," ",Z15," ",AA15," ",AB15," ",AC15," ",AD15," ",AE15," ",AF15," ",AG15," ",AH15," ",AI15," ",AJ15," ",AK15," ",AL15," ",AM15," ",AN15," ",AO15," ",AP15," ",AQ15," ",AR15," ",AS15," ",AT15," ",AU15," ",AV15," ",AW15," ",AX15," ",AY15," ",AZ15," ",BA15," ",BB15," ",BC15," ",BD15," ",BE15," ",BF15," ",BG15," ",BH15," ",BI15," ",BJ15," ",BK15," ",BL15," ",BM15," ",BN15," ",BO15," ",BP15," ",BQ15," ",BR15," ",BS15," ",BT15," ",BU15," ",BV15," ",BW15," ",BX15," ",BY15," ",BZ15," ",CA15," ",CB15," ",CC15," ",CD15," ",CE15," ",CF15," ",CG15," ",CH15," ",CI15," ",CJ15," ",CK15," ",CL15," ",CM15," ",CN15," ",CO15," ",CP15," ",CQ15," ",CR15," ",CS15," ",CT15," ",CU15," ",CV15," ",CW15," ",CX15," ",CY15," ",CZ15," ",DA15," ",DB15) | F15: =COUNTA(G15:DB15)-COUNTBLANK(G15:DB15) -> 0 | G15: =IFERROR(VLOOKUP($A15&"_"&G$3,'물품 입고 내역'!$A$5:$O$629,2,0),"") | H15: =IFERROR(VLOOKUP($A15&"_"&H$3,'물품 입고 내역'!$A$5:$O$629,2,0),"") | I15: =IFERROR(VLOOKUP($A15&"_"&I$3,'물품 입고 내역'!$A$5:$O$629,2,0),"") | J15: =IFERROR(VLOOKUP($A15&"_"&J$3,'물품 입고 내역'!$A$5:$O$629,2,0),"") | K15: =IFERROR(VLOOKUP($A15&"_"&K$3,'물품 입고 내역'!$A$5:$O$629,2,0),"") | L15: =IFERROR(VLOOKUP($A15&"_"&L$3,'물품 입고 내역'!$A$5:$O$629,2,0),"") | M15: =IFERROR(VLOOKUP($A15&"_"&M$3,'물품 입고 내역'!$A$5:$O$629,2,0),"") | N15: =IFERROR(VLOOKUP($A15&"_"&N$3,'물품 입고 내역'!$A$5:$O$629,2,0),"") | ... DB15: =IFERROR(VLOOKUP($A15&"_"&DB$3,'물품 입고 내역'!$A$5:$O$629,2,0),"")
... A83: LKA xx | B83: =IFERROR(INDEX('물품 입고 내역'!$E$6:$N$105,MATCH($A83,'물품 입고 내역'!$N$6:$N$105,0),1)," ") | C83: 102 | D83: =CONCATENATE(G83," ",H83," ",I83," ",J83," ",K83," ",L83," ",M83," ",N83," ",O83," ",P83," ",Q83," ",R83," ",S83," ",T83," ",U83," ",V83," ",W83," ",X83," ",Y83," ",Z83," ",AA83," ",AB83," ",AC83," ",AD83," ",AE83," ",AF83," ",AG83," ",AH83," ",AI83," ",AJ83," ",AK83," ",AL83," ",AM83," ",AN83," ",AO83," ",AP83," ",AQ83," ",AR83," ",AS83," ",AT83," ",AU83," ",AV83," ",AW83," ",AX83," ",AY83," ",AZ83," ",BA83," ",BB83," ",BC83," ",BD83," ",BE83," ",BF83," ",BG83," ",BH83," ",BI83," ",BJ83," ",BK83," ",BL83," ",BM83," ",BN83," ",BO83," ",BP83," ",BQ83," ",BR83," ",BS83," ",BT83," ",BU83," ",BV83," ",BW83," ",BX83," ",BY83," ",BZ83," ",CA83," ",CB83," ",CC83," ",CD83," ",CE83," ",CF83," ",CG83," ",CH83," ",CI83," ",CJ83," ",CK83," ",CL83," ",CM83," ",CN83," ",CO83," ",CP83," ",CQ83," ",CR83," ",CS83," ",CT83," ",CU83," ",CV83," ",CW83," ",CX83," ",CY83," ",CZ83," ",DA83," ",DB83) | F83: =COUNTA(G83:DB83)-COUNTBLANK(G83:DB83) -> 0 | G83: =IFERROR(VLOOKUP($A83&"_"&G$3,'물품 입고 내역'!$A$5:$O$629,2,0),"") | H83: =IFERROR(VLOOKUP($A83&"_"&H$3,'물품 입고 내역'!$A$5:$O$629,2,0),"") | I83: =IFERROR(VLOOKUP($A83&"_"&I$3,'물품 입고 내역'!$A$5:$O$629,2,0),"") | J83: =IFERROR(VLOOKUP($A83&"_"&J$3,'물품 입고 내역'!$A$5:$O$629,2,0),"") | K83: =IFERROR(VLOOKUP($A83&"_"&K$3,'물품 입고 내역'!$A$5:$O$629,2,0),"") | L83: =IFERROR(VLOOKUP($A83&"_"&L$3,'물품 입고 내역'!$A$5:$O$629,2,0),"") | M83: =IFERROR(VLOOKUP($A83&"_"&M$3,'물품 입고 내역'!$A$5:$O$629,2,0),"") | N83: =IFERROR(VLOOKUP($A83&"_"&N$3,'물품 입고 내역'!$A$5:$O$629,2,0),"") | ... DB83: =IFERROR(VLOOKUP($A83&"_"&DB$3,'물품 입고 내역'!$A$5:$O$629,2,0),"")
F84: =SUM(SUM(F4:F83)) -> 0

Sheet 수취인 불명 내역
A1: 영수 번호 | B1: 송장 번호 | C1: Remark
A2: LK81 | B2: 5593-8870-9956 | C2: 김인규??
A3: LK82 | B3: 10-2664-5564-6053, 382-7242-2753
A4: LK83 | B4: 5903-7235-0543, 5903-7199-0220
A5: LK84 | B5: 66597-0117-4099 | C5: 이우용??
A6: LK85 | B6: 6856-8748-0750
A7: LK86 | B7: 66017-0128-0372
A8: LK87 | B8: 65689-0106-6533
A9: LK88 | B9: 5796-5801-8672 | C9: 송인호 고객물류로 추정됨 / 박주유 님이 한국에서 보내신 물건으로 추정
A10: LK89 | B10: 5909-8013-8342 | C10: 폼마린??
A11: LK90 | B11: 65129-0112-6372
A12: LK91 | B12: 64134-0322-0901, 64134-0322-0902 | C12: 박주유
A13: LK92 | B13: 6105072440050, 4107032440085, 3132212443441
A14: LK93 | B14: 10-2672-2107-9721, 10-2672-2107-9964, 10-2672-2107-5613, 10-2672-2107-8553, 10-2672-2107-5731 | C14: 박환영??
B15: 2601-402-015153
A16: LK94 | B16: 2484-9497-0570
A17: LK95 | B17: 3647-7561-7276

Sheet LKA 01
C1: Kor-Lao Air xxth 거래 명세서 | L1: 구획(Zone) | M1: 102 | R1: =D16 -> 0 | T1: 화폐 | U1: 기준 환율 | V1: 추가 환율 | W1: 적용 환율
A2: 회사명 | B2: 엘케이(LK)무역 | D2: 도착일 | E2: 2026-XX-XX | I2: 고객명/회사명 // 영수 번호 | L2: =IFERROR(INDEX('고객 리스트'!$A$4:$D$83,MATCH(N2,'고객 리스트'!$A$4:$A$83,0),2)," ") | N2: =MID(CELL("filename",A1),FIND("]",CELL("filename",A1))+1,255) -> LKA 01 | R2: =N21 -> 0 | T2: USD-KIP | U2: ='Row data'!C3 -> 23000 | V2: 1000 | W2: =U2+V2 -> 24000
A3: 회사 주소 | B3: 비엔티엔시, 씨싿따낙구, 싸판텅 느아 09, 11번 골목, 엘케이(LK) 빌딩, 1층 LK Trading | T3: USD-THB | U3: ='Row data'!C4 -> 33 | V3: 1 | W3: =U3+V3 -> 34
A4: 전화번호 | B4: 020-9112-6780 | I4: 고객 연락처/회사 연락처 | L4: =IFERROR(VLOOKUP($N$2&"_"&$A$6,'물품 입고 내역'!$A$5:$N$105,6,0)," ") | T4: USD-WON | U4: ='Row data'!C5 -> 1515 | V4: 30 | W4: =U4+V4 -> 1545
A5: No. | B5: 종류 | C5: 단가 | D5: 수량 | E5: 실제중량(Kg) | F5: 실제중량 합산(kg) | G5: 규격 (cm) | J5: 용적 중량(kg) | K5: 용적중량 합산(Kg) | L5: 실제중량 운임 | M5: 용적중량 운임 | N5: 청구중량 운임
A6: 1 | B6: =IFERROR(VLOOKUP($N$2&"_"&$A6,'물품 입고 내역'!$A$5:$N$105,2,0)," ") | C6: =IF(" "=D6," ",IF(0<D6,14)) | D6: =IFERROR(VLOOKUP($N$2&"_"&$A6,'물품 입고 내역'!$A$5:$N$105,9,0)," ") | E6: =IFERROR(INDEX('물품 입고 내역'!$B$5:$M$105,MATCH($B6,'물품 입고 내역'!$B$5:$B$105,0),9)," ") | F6: =IFERROR(D6*E6," ") | G6: =IFERROR(INDEX('물품 입고 내역'!$B$5:$M$105,MATCH($B6,'물품 입고 내역'!$B$5:$B$105,0),10)," ") | H6: =IFERROR(INDEX('물품 입고 내역'!$B$5:$M$105,MATCH($B6,'물품 입고 내역'!$B$5:$B$105,0),11)," ") | I6: =IFERROR(INDEX('물품 입고 내역'!$B$5:$M$105,MATCH($B6,'물품 입고 내역'!$B$5:$B$105,0),12)," ") | J6: =IFERROR((G6*H6*I6)*0.00022," ") | K6: =IFERROR(J6*D6," ") | L6: =IFERROR((IF(0=F6*C6,0,IF(14>=C6*F6,14,C6*F6)))," ") | M6: =IFERROR((IF(0=K6*C6,0,IF(14>=K6*C6,14,K6*C6)))," ") | N6: =MAX(L6:M6) -> 0
A7: 2 | B7: =IFERROR(VLOOKUP($N$2&"_"&$A7,'물품 입고 내역'!$A$5:$N$105,2,0)," ") | C7: =IF(" "=D7," ",IF(0<D7,14)) | D7: =IFERROR(VLOOKUP($N$2&"_"&$A7,'물품 입고 내역'!$A$5:$N$105,9,0)," ") | E7: =IFERROR(INDEX('물품 입고 내역'!$B$5:$M$105,MATCH($B7,'물품 입고 내역'!$B$5:$B$105,0),9)," ") | F7: =IFERROR(D7*E7," ") | G7: =IFERROR(INDEX('물품 입고 내역'!$B$5:$M$105,MATCH($B7,'물품 입고 내역'!$B$5:$B$105,0),10)," ") | H7: =IFERROR(INDEX('물품 입고 내역'!$B$5:$M$105,MATCH($B7,'물품 입고 내역'!$B$5:$B$105,0),11)," ") | I7: =IFERROR(INDEX('물품 입고 내역'!$B$5:$M$105,MATCH($B7,'물품 입고 내역'!$B$5:$B$105,0),12)," ") | J7: =IFERROR((G7*H7*I7)*0.00022," ") | K7: =IFERROR(J7*D7," ") | L7: =IFERROR((IF(0=F7*C7,0,IF(14>=C7*F7,14,C7*F7)))," ") | M7: =IFERROR((IF(0=K7*C7,0,IF(14>=K7*C7,14,K7*C7)))," ") | N7: =MAX(L7:M7) -> 0
A8: 3 | B8: =IFERROR(VLOOKUP($N$2&"_"&$A8,'물품 입고 내역'!$A$5:$N$105,2,0)," ") | C8: =IF(" "=D8," ",IF(0<D8,14)) | D8: =IFERROR(VLOOKUP($N$2&"_"&$A8,'물품 입고 내역'!$A$5:$N$105,9,0)," ") | E8: =IFERROR(INDEX('물품 입고 내역'!$B$5:$M$105,MATCH($B8,'물품 입고 내역'!$B$5:$B$105,0),9)," ") | F8: =IFERROR(D8*E8," ") | G8: =IFERROR(INDEX('물품 입고 내역'!$B$5:$M$105,MATCH($B8,'물품 입고 내역'!$B$5:$B$105,0),10)," ") | H8: =IFERROR(INDEX('물품 입고 내역'!$B$5:$M$105,MATCH($B8,'물품 입고 내역'!$B$5:$B$105,0),11)," ") | I8: =IFERROR(INDEX('물품 입고 내역'!$B$5:$M$105,MATCH($B8,'물품 입고 내역'!$B$5:$B$105,0),12)," ") | J8: =IFERROR((G8*H8*I8)*0.00022," ") | K8: =IFERROR(J8*D8," ") | L8: =IFERROR((IF(0=F8*C8,0,IF(14>=C8*F8,14,C8*F8)))," ") | M8: =IFERROR((IF(0=K8*C8,0,IF(14>=K8*C8,14,K8*C8)))," ") | N8: =MAX(L8:M8) -> 0
A9: 4 | B9: =IFERROR(VLOOKUP($N$2&"_"&$A9,'물품 입고 내역'!$A$5:$N$105,2,0)," ") | C9: =IF(" "=D9," ",IF(0<D9,14)) | D9: =IFERROR(VLOOKUP($N$2&"_"&$A9,'물품 입고 내역'!$A$5:$N$105,9,0)," ") | E9: =IFERROR(INDEX('물품 입고 내역'!$B$5:$M$105,MATCH($B9,'물품 입고 내역'!$B$5:$B$105,0),9)," ") | F9: =IFERROR(D9*E9," ") | G9: =IFERROR(INDEX('물품 입고 내역'!$B$5:$M$105,MATCH($B9,'물품 입고 내역'!$B$5:$B$105,0),10)," ") | H9: =IFERROR(INDEX('물품 입고 내역'!$B$5:$M$105,MATCH($B9,'물품 입고 내역'!$B$5:$B$105,0),11)," ") | I9: =IFERROR(INDEX('물품 입고 내역'!$B$5:$M$105,MATCH($B9,'물품 입고 내역'!$B$5:$B$105,0),12)," ") | J9: =IFERROR((G9*H9*I9)*0.00022," ") | K9: =IFERROR(J9*D9," ") | L9: =IFERROR((IF(0=F9*C9,0,IF(14>=C9*F9,14,C9*F9)))," ") | M9: =IFERROR((IF(0=K9*C9,0,IF(14>=K9*C9,14,K9*C9)))," ") | N9: =MAX(L9:M9) -> 0
A10: 5 | B10: =IFERROR(VLOOKUP($N$2&"_"&$A10,'물품 입고 내역'!$A$5:$N$105,2,0)," ") | C10: =IF(" "=D10," ",IF(0<D10,14)) | D10: =IFERROR(VLOOKUP($N$2&"_"&$A10,'물품 입고 내역'!$A$5:$N$105,9,0)," ") | E10: =IFERROR(INDEX('물품 입고 내역'!$B$5:$M$105,MATCH($B10,'물품 입고 내역'!$B$5:$B$105,0),9)," ") | F10: =IFERROR(D10*E10," ") | G10: =IFERROR(INDEX('물품 입고 내역'!$B$5:$M$105,MATCH($B10,'물품 입고 내역'!$B$5:$B$105,0),10)," ") | H10: =IFERROR(INDEX('물품 입고 내역'!$B$5:$M$105,MATCH($B10,'물품 입고 내역'!$B$5:$B$105,0),11)," ") | I10: =IFERROR(INDEX('물품 입고 내역'!$B$5:$M$105,MATCH($B10,'물품 입고 내역'!$B$5:$B$105,0),12)," ") | J10: =IFERROR((G10*H10*I10)*0.00022," ") | K10: =IFERROR(J10*D10," ") | L10: =IFERROR((IF(0=F10*C10,0,IF(14>=C10*F10,14,C10*F10)))," ") | M10: =IFERROR((IF(0=K10*C10,0,IF(14>=K10*C10,14,K10*C10)))," ") | N10: =MAX(L10:M10) -> 0
A11: 6 | B11: =IFERROR(VLOOKUP($N$2&"_"&$A11,'물품 입고 내역'!$A$5:$N$105,2,0)," ") | C11: =IF(" "=D11," ",IF(0<D11,14)) | D11: =IFERROR(VLOOKUP($N$2&"_"&$A11,'물품 입고 내역'!$A$5:$N$105,9,0)," ") | E11: =IFERROR(INDEX('물품 입고 내역'!$B$5:$M$105,MATCH($B11,'물품 입고 내역'!$B$5:$B$105,0),9)," ") | F11: =IFERROR(D11*E11," ") | G11: =IFERROR(INDEX('물품 입고 내역'!$B$5:$M$105,MATCH($B11,'물품 입고 내역'!$B$5:$B$105,0),10)," ") | H11: =IFERROR(INDEX('물품 입고 내역'!$B$5:$M$105,MATCH($B11,'물품 입고 내역'!$B$5:$B$105,0),11)," ") | I11: =IFERROR(INDEX('물품 입고 내역'!$B$5:$M$105,MATCH($B11,'물품 입고 내역'!$B$5:$B$105,0),12)," ") | J11: =IFERROR((G11*H11*I11)*0.00022," ") | K11: =IFERROR(J11*D11," ") | L11: =IFERROR((IF(0=F11*C11,0,IF(14>=C11*F11,14,C11*F11)))," ") | M11: =IFERROR((IF(0=K11*C11,0,IF(14>=K11*C11,14,K11*C11)))," ") | N11: =MAX(L11:M11) -> 0
A12: 7 | B12: =IFERROR(VLOOKUP($N$2&"_"&$A12,'물품 입고 내역'!$A$5:$N$105,2,0)," ") | C12: =IF(" "=D12," ",IF(0<D12,14)) | D12: =IFERROR(VLOOKUP($N$2&"_"&$A12,'물품 입고 내역'!$A$5:$N$105,9,0)," ") | E12: =IFERROR(INDEX('물품 입고 내역'!$B$5:$M$105,MATCH($B12,'물품 입고 내역'!$B$5:$B$105,0),9)," ") | F12: =IFERROR(D12*E12," ") | G12: =IFERROR(INDEX('물품 입고 내역'!$B$5:$M$105,MATCH($B12,'물품 입고 내역'!$B$5:$B$105,0),10)," ") | H12: =IFERROR(INDEX('물품 입고 내역'!$B$5:$M$105,MATCH($B12,'물품 입고 내역'!$B$5:$B$105,0),11)," ") | I12: =IFERROR(INDEX('물품 입고 내역'!$B$5:$M$105,MATCH($B12,'물품 입고 내역'!$B$5:$B$105,0),12)," ") | J12: =IFERROR((G12*H12*I12)*0.00022," ") | K12: =IFERROR(J12*D12," ") | L12: =IFERROR((IF(0=F12*C12,0,IF(14>=C12*F12,14,C12*F12)))," ") | M12: =IFERROR((IF(0=K12*C12,0,IF(14>=K12*C12,14,K12*C12)))," ") | N12: =MAX(L12:M12) -> 0
A13: 8 | B13: =IFERROR(VLOOKUP($N$2&"_"&$A13,'물품 입고 내역'!$A$5:$N$105,2,0)," ") | C13: =IF(" "=D13," ",IF(0<D13,14)) | D13: =IFERROR(VLOOKUP($N$2&"_"&$A13,'물품 입고 내역'!$A$5:$N$105,9,0)," ") | E13: =IFERROR(INDEX('물품 입고 내역'!$B$5:$M$105,MATCH($B13,'물품 입고 내역'!$B$5:$B$105,0),9)," ") | F13: =IFERROR(D13*E13," ") | G13: =IFERROR(INDEX('물품 입고 내역'!$B$5:$M$105,MATCH($B13,'물품 입고 내역'!$B$5:$B$105,0),10)," ") | H13: =IFERROR(INDEX('물품 입고 내역'!$B$5:$M$105,MATCH($B13,'물품 입고 내역'!$B$5:$B$105,0),11)," ") | I13: =IFERROR(INDEX('물품 입고 내역'!$B$5:$M$105,MATCH($B13,'물품 입고 내역'!$B$5:$B$105,0),12)," ") | J13: =IFERROR((G13*H13*I13)*0.00022," ") | K13: =IFERROR(J13*D13," ") | L13: =IFERROR((IF(0=F13*C13,0,IF(14>=C13*F13,14,C13*F13)))," ") | M13: =IFERROR((IF(0=K13*C13,0,IF(14>=K13*C13,14,K13*C13)))," ") | N13: =MAX(L13:M13) -> 0
A14: 9 | B14: =IFERROR(VLOOKUP($N$2&"_"&$A14,'물품 입고 내역'!$A$5:$N$105,2,0)," ") | C14: =IF(" "=D14," ",IF(0<D14,14)) | D14: =IFERROR(VLOOKUP($N$2&"_"&$A14,'물품 입고 내역'!$A$5:$N$105,9,0)," ") | E14: =IFERROR(INDEX('물품 입고 내역'!$B$5:$M$105,MATCH($B14,'물품 입고 내역'!$B$5:$B$105,0),9)," ") | F14: =IFERROR(D14*E14," ") | G14: =IFERROR(INDEX('물품 입고 내역'!$B$5:$M$105,MATCH($B14,'물품 입고 내역'!$B$5:$B$105,0),10)," ") | H14: =IFERROR(INDEX('물품 입고 내역'!$B$5:$M$105,MATCH($B14,'물품 입고 내역'!$B$5:$B$105,0),11)," ") | I14: =IFERROR(INDEX('물품 입고 내역'!$B$5:$M$105,MATCH($B14,'물품 입고 내역'!$B$5:$B$105,0),12)," ") | J14: =IFERROR((G14*H14*I14)*0.00022," ") | K14: =IFERROR(J14*D14," ") | L14: =IFERROR((IF(0=F14*C14,0,IF(14>=C14*F14,14,C14*F14)))," ") | M14: =IFERROR((IF(0=K14*C14,0,IF(14>=K14*C14,14,K14*C14)))," ") | N14: =MAX(L14:M14) -> 0
A15: 10 | B15: =IFERROR(VLOOKUP($N$2&"_"&$A15,'물품 입고 내역'!$A$5:$N$105,2,0)," ") | C15: =IF(" "=D15," ",IF(0<D15,14)) | D15: =IFERROR(VLOOKUP($N$2&"_"&$A15,'물품 입고 내역'!$A$5:$N$105,9,0)," ") | E15: =IFERROR(INDEX('물품 입고 내역'!$B$5:$M$105,MATCH($B15,'물품 입고 내역'!$B$5:$B$105,0),9)," ") | F15: =IFERROR(D15*E15," ") | G15: =IFERROR(INDEX('물품 입고 내역'!$B$5:$M$105,MATCH($B15,'물품 입고 내역'!$B$5:$B$105,0),10)," ") | H15: =IFERROR(INDEX('물품 입고 내역'!$B$5:$M$105,MATCH($B15,'물품 입고 내역'!$B$5:$B$105,0),11)," ") | I15: =IFERROR(INDEX('물품 입고 내역'!$B$5:$M$105,MATCH($B15,'물품 입고 내역'!$B$5:$B$105,0),12)," ") | J15: =IFERROR((G15*H15*I15)*0.00022," ") | K15: =IFERROR(J15*D15," ") | L15: =IFERROR((IF(0=F15*C15,0,IF(14>=C15*F15,14,C15*F15)))," ") | M15: =IFERROR((IF(0=K15*C15,0,IF(14>=K15*C15,14,K15*C15)))," ") | N15: =MAX(L15:M15) -> 0
A16: 합 계 | D16: =SUM(D6:D15) -> 0 | F16: =SUM(F6:F15) -> 0 | K16: =SUM(K6:K15) -> 0
A17: Remark/비 고 | F17: Inland delivery/시내.지방 배송 | L17: 운임 총합 | N17: =SUM(N6:N16) -> 0
A18: =IFERROR(VLOOKUP($N$2&"_"&$A$6,'물품 입고 내역'!$A$5:$O$522,4,0)," ") | L18: 할인 | M18: =IFERROR(MID($A$18,FIND(" "&$L$18&" ",$A$18)+4,3)," ") | N18: =IFERROR(N17*M18,0) -> 0
L19: 특별할인 | M19: =IFERROR(MID($A$18,FIND(" "&$L$19&" ",$A$18)+6,3)," ") | N19: =IFERROR(N17*M19,0) -> 0
L20: 세금 계산서(VAT) | M20: =IFERROR(IF(FIND("세금 계산서",$A$18),10%," ")," ") | N20: =IFERROR((N17-N18-N19)*M20,0) -> 0
L21: 최종 청구 금액 | M21: USD | N21: =(N17-N18-N19+N20) -> 0
M22: KIP | N22: =ROUNDUP((N21*$W$2),-3) -> 0
M23: THB | N23: =ROUNDUP((N21*$W$3),-1) -> 0
M24: WON | N24: =ROUNDUP((N21*$W$4),-2) -> 0
A26: * 모든 비용은 회사의 내규 및 각 물품의 중량/크기 실측을 기준으로 청구되며 최소 운임은 $14/kg 입니다.
A27: * 입.출고지를 떠나시기 전 꼭! 고객님 본인 물품 및 개수 확인 부탁 드립니다. 물품이 출고된 이후 LK그룹은 물품의 파손/분실에 대한 어떠한 책임도 없습니다.
A28: * 물품 도착 및 출고 후 특별한 사유 없이 장기 미수취 물품의 경우 보관료등 기타 추가 비용이 발생 할 수 있습니다.
A29: * 물품 출고 후 1주 후부터 보관료(최소 3불/CBM/day)가 발생하며, 특별한 사유 없이 2달 이상 보관 물품들은 임의로 폐기/처분 될 수 있습니다.
A30: 엘케이 (LK)무역 | H30: * 이용해 주셔서 감사합니다. | K30: 고객사 서명

Sheet LKA XX
C1: Kor-Lao Air xxth 거래 명세서 | L1: 구획(Zone) | M1: 102 | R1: =D16 -> 0 | T1: 화폐 | U1: 기준 환율 | V1: 추가 환율 | W1: 적용 환율
A2: 회사명 | B2: 엘케이(LK)무역 | D2: 도착일 | E2: 2026-XX-XX | I2: 고객명/회사명 // 영수 번호 | L2: =IFERROR(INDEX('고객 리스트'!$A$4:$D$83,MATCH(N2,'고객 리스트'!$A$4:$A$83,0),2)," ") | N2: =MID(CELL("filename",A1),FIND("]",CELL("filename",A1))+1,255) -> LKA XX | R2: =N21 -> 0 | T2: USD-KIP | U2: ='Row data'!C3 -> 23000 | V2: 1000 | W2: =U2+V2 -> 24000
A3: 회사 주소 | B3: 비엔티엔시, 씨싿따낙구, 싸판텅 느아 09, 11번 골목, 엘케이(LK) 빌딩, 1층 LK Trading | T3: USD-THB | U3: ='Row data'!C4 -> 33 | V3: 1 | W3: =U3+V3 -> 34
A4: 전화번호 | B4: 020-9112-6780 | I4: 고객 연락처/회사 연락처 | L4: =IFERROR(VLOOKUP($N$2&"_"&$A$6,'물품 입고 내역'!$A$5:$N$105,6,0)," ") | T4: USD-WON | U4: ='Row data'!C5 -> 1515 | V4: 30 | W4: =U4+V4 -> 1545
A5: No. | B5: 종류 | C5: 단가 | D5: 수량 | E5: 실제중량(Kg) | F5: 실제중량 합산(kg) | G5: 규격 (cm) | J5: 용적 중량(kg) | K5: 용적중량 합산(Kg) | L5: 실제중량 운임 | M5: 용적중량 운임 | N5: 청구중량 운임
A6: 1 | B6: =IFERROR(VLOOKUP($N$2&"_"&$A6,'물품 입고 내역'!$A$5:$N$105,2,0)," ") | C6: =IF(" "=D6," ",IF(0<D6,14)) | D6: =IFERROR(VLOOKUP($N$2&"_"&$A6,'물품 입고 내역'!$A$5:$N$105,9,0)," ") | E6: =IFERROR(INDEX('물품 입고 내역'!$B$5:$M$105,MATCH($B6,'물품 입고 내역'!$B$5:$B$105,0),9)," ") | F6: =IFERROR(D6*E6," ") | G6: =IFERROR(INDEX('물품 입고 내역'!$B$5:$M$105,MATCH($B6,'물품 입고 내역'!$B$5:$B$105,0),10)," ") | H6: =IFERROR(INDEX('물품 입고 내역'!$B$5:$M$105,MATCH($B6,'물품 입고 내역'!$B$5:$B$105,0),11)," ") | I6: =IFERROR(INDEX('물품 입고 내역'!$B$5:$M$105,MATCH($B6,'물품 입고 내역'!$B$5:$B$105,0),12)," ") | J6: =IFERROR((G6*H6*I6)*0.00022," ") | K6: =IFERROR(J6*D6," ") | L6: =IFERROR((IF(0=F6*C6,0,IF(14>=C6*F6,14,C6*F6)))," ") | M6: =IFERROR((IF(0=K6*C6,0,IF(14>=K6*C6,14,K6*C6)))," ") | N6: =MAX(L6:M6) -> 0
A7: 2 | B7: =IFERROR(VLOOKUP($N$2&"_"&$A7,'물품 입고 내역'!$A$5:$N$105,2,0)," ") | C7: =IF(" "=D7," ",IF(0<D7,14)) | D7: =IFERROR(VLOOKUP($N$2&"_"&$A7,'물품 입고 내역'!$A$5:$N$105,9,0)," ") | E7: =IFERROR(INDEX('물품 입고 내역'!$B$5:$M$105,MATCH($B7,'물품 입고 내역'!$B$5:$B$105,0),9)," ") | F7: =IFERROR(D7*E7," ") | G7: =IFERROR(INDEX('물품 입고 내역'!$B$5:$M$105,MATCH($B7,'물품 입고 내역'!$B$5:$B$105,0),10)," ") | H7: =IFERROR(INDEX('물품 입고 내역'!$B$5:$M$105,MATCH($B7,'물품 입고 내역'!$B$5:$B$105,0),11)," ") | I7: =IFERROR(INDEX('물품 입고 내역'!$B$5:$M$105,MATCH($B7,'물품 입고 내역'!$B$5:$B$105,0),12)," ") | J7: =IFERROR((G7*H7*I7)*0.00022," ") | K7: =IFERROR(J7*D7," ") | L7: =IFERROR((IF(0=F7*C7,0,IF(14>=C7*F7,14,C7*F7)))," ") | M7: =IFERROR((IF(0=K7*C7,0,IF(14>=K7*C7,14,K7*C7)))," ") | N7: =MAX(L7:M7) -> 0
A8: 3 | B8: =IFERROR(VLOOKUP($N$2&"_"&$A8,'물품 입고 내역'!$A$5:$N$105,2,0)," ") | C8: =IF(" "=D8," ",IF(0<D8,14)) | D8: =IFERROR(VLOOKUP($N$2&"_"&$A8,'물품 입고 내역'!$A$5:$N$105,9,0)," ") | E8: =IFERROR(INDEX('물품 입고 내역'!$B$5:$M$105,MATCH($B8,'물품 입고 내역'!$B$5:$B$105,0),9)," ") | F8: =IFERROR(D8*E8," ") | G8: =IFERROR(INDEX('물품 입고 내역'!$B$5:$M$105,MATCH($B8,'물품 입고 내역'!$B$5:$B$105,0),10)," ") | H8: =IFERROR(INDEX('물품 입고 내역'!$B$5:$M$105,MATCH($B8,'물품 입고 내역'!$B$5:$B$105,0),11)," ") | I8: =IFERROR(INDEX('물품 입고 내역'!$B$5:$M$105,MATCH($B8,'물품 입고 내역'!$B$5:$B$105,0),12)," ") | J8: =IFERROR((G8*H8*I8)*0.00022," ") | K8: =IFERROR(J8*D8," ") | L8: =IFERROR((IF(0=F8*C8,0,IF(14>=C8*F8,14,C8*F8)))," ") | M8: =IFERROR((IF(0=K8*C8,0,IF(14>=K8*C8,14,K8*C8)))," ") | N8: =MAX(L8:M8) -> 0
A9: 4 | B9: =IFERROR(VLOOKUP($N$2&"_"&$A9,'물품 입고 내역'!$A$5:$N$105,2,0)," ") | C9: =IF(" "=D9," ",IF(0<D9,14)) | D9: =IFERROR(VLOOKUP($N$2&"_"&$A9,'물품 입고 내역'!$A$5:$N$105,9,0)," ") | E9: =IFERROR(INDEX('물품 입고 내역'!$B$5:$M$105,MATCH($B9,'물품 입고 내역'!$B$5:$B$105,0),9)," ") | F9: =IFERROR(D9*E9," ") | G9: =IFERROR(INDEX('물품 입고 내역'!$B$5:$M$105,MATCH($B9,'물품 입고 내역'!$B$5:$B$105,0),10)," ") | H9: =IFERROR(INDEX('물품 입고 내역'!$B$5:$M$105,MATCH($B9,'물품 입고 내역'!$B$5:$B$105,0),11)," ") | I9: =IFERROR(INDEX('물품 입고 내역'!$B$5:$M$105,MATCH($B9,'물품 입고 내역'!$B$5:$B$105,0),12)," ") | J9: =IFERROR((G9*H9*I9)*0.00022," ") | K9: =IFERROR(J9*D9," ") | L9: =IFERROR((IF(0=F9*C9,0,IF(14>=C9*F9,14,C9*F9)))," ") | M9: =IFERROR((IF(0=K9*C9,0,IF(14>=K9*C9,14,K9*C9)))," ") | N9: =MAX(L9:M9) -> 0
A10: 5 | B10: =IFERROR(VLOOKUP($N$2&"_"&$A10,'물품 입고 내역'!$A$5:$N$105,2,0)," ") | C10: =IF(" "=D10," ",IF(0<D10,14)) | D10: =IFERROR(VLOOKUP($N$2&"_"&$A10,'물품 입고 내역'!$A$5:$N$105,9,0)," ") | E10: =IFERROR(INDEX('물품 입고 내역'!$B$5:$M$105,MATCH($B10,'물품 입고 내역'!$B$5:$B$105,0),9)," ") | F10: =IFERROR(D10*E10," ") | G10: =IFERROR(INDEX('물품 입고 내역'!$B$5:$M$105,MATCH($B10,'물품 입고 내역'!$B$5:$B$105,0),10)," ") | H10: =IFERROR(INDEX('물품 입고 내역'!$B$5:$M$105,MATCH($B10,'물품 입고 내역'!$B$5:$B$105,0),11)," ") | I10: =IFERROR(INDEX('물품 입고 내역'!$B$5:$M$105,MATCH($B10,'물품 입고 내역'!$B$5:$B$105,0),12)," ") | J10: =IFERROR((G10*H10*I10)*0.00022," ") | K10: =IFERROR(J10*D10," ") | L10: =IFERROR((IF(0=F10*C10,0,IF(14>=C10*F10,14,C10*F10)))," ") | M10: =IFERROR((IF(0=K10*C10,0,IF(14>=K10*C10,14,K10*C10)))," ") | N10: =MAX(L10:M10) -> 0
A11: 6 | B11: =IFERROR(VLOOKUP($N$2&"_"&$A11,'물품 입고 내역'!$A$5:$N$105,2,0)," ") | C11: =IF(" "=D11," ",IF(0<D11,14)) | D11: =IFERROR(VLOOKUP($N$2&"_"&$A11,'물품 입고 내역'!$A$5:$N$105,9,0)," ") | E11: =IFERROR(INDEX('물품 입고 내역'!$B$5:$M$105,MATCH($B11,'물품 입고 내역'!$B$5:$B$105,0),9)," ") | F11: =IFERROR(D11*E11," ") | G11: =IFERROR(INDEX('물품 입고 내역'!$B$5:$M$105,MATCH($B11,'물품 입고 내역'!$B$5:$B$105,0),10)," ") | H11: =IFERROR(INDEX('물품 입고 내역'!$B$5:$M$105,MATCH($B11,'물품 입고 내역'!$B$5:$B$105,0),11)," ") | I11: =IFERROR(INDEX('물품 입고 내역'!$B$5:$M$105,MATCH($B11,'물품 입고 내역'!$B$5:$B$105,0),12)," ") | J11: =IFERROR((G11*H11*I11)*0.00022," ") | K11: =IFERROR(J11*D11," ") | L11: =IFERROR((IF(0=F11*C11,0,IF(14>=C11*F11,14,C11*F11)))," ") | M11: =IFERROR((IF(0=K11*C11,0,IF(14>=K11*C11,14,K11*C11)))," ") | N11: =MAX(L11:M11) -> 0
A12: 7 | B12: =IFERROR(VLOOKUP($N$2&"_"&$A12,'물품 입고 내역'!$A$5:$N$105,2,0)," ") | C12: =IF(" "=D12," ",IF(0<D12,14)) | D12: =IFERROR(VLOOKUP($N$2&"_"&$A12,'물품 입고 내역'!$A$5:$N$105,9,0)," ") | E12: =IFERROR(INDEX('물품 입고 내역'!$B$5:$M$105,MATCH($B12,'물품 입고 내역'!$B$5:$B$105,0),9)," ") | F12: =IFERROR(D12*E12," ") | G12: =IFERROR(INDEX('물품 입고 내역'!$B$5:$M$105,MATCH($B12,'물품 입고 내역'!$B$5:$B$105,0),10)," ") | H12: =IFERROR(INDEX('물품 입고 내역'!$B$5:$M$105,MATCH($B12,'물품 입고 내역'!$B$5:$B$105,0),11)," ") | I12: =IFERROR(INDEX('물품 입고 내역'!$B$5:$M$105,MATCH($B12,'물품 입고 내역'!$B$5:$B$105,0),12)," ") | J12: =IFERROR((G12*H12*I12)*0.00022," ") | K12: =IFERROR(J12*D12," ") | L12: =IFERROR((IF(0=F12*C12,0,IF(14>=C12*F12,14,C12*F12)))," ") | M12: =IFERROR((IF(0=K12*C12,0,IF(14>=K12*C12,14,K12*C12)))," ") | N12: =MAX(L12:M12) -> 0
A13: 8 | B13: =IFERROR(VLOOKUP($N$2&"_"&$A13,'물품 입고 내역'!$A$5:$N$105,2,0)," ") | C13: =IF(" "=D13," ",IF(0<D13,14)) | D13: =IFERROR(VLOOKUP($N$2&"_"&$A13,'물품 입고 내역'!$A$5:$N$105,9,0)," ") | E13: =IFERROR(INDEX('물품 입고 내역'!$B$5:$M$105,MATCH($B13,'물품 입고 내역'!$B$5:$B$105,0),9)," ") | F13: =IFERROR(D13*E13," ") | G13: =IFERROR(INDEX('물품 입고 내역'!$B$5:$M$105,MATCH($B13,'물품 입고 내역'!$B$5:$B$105,0),10)," ") | H13: =IFERROR(INDEX('물품 입고 내역'!$B$5:$M$105,MATCH($B13,'물품 입고 내역'!$B$5:$B$105,0),11)," ") | I13: =IFERROR(INDEX('물품 입고 내역'!$B$5:$M$105,MATCH($B13,'물품 입고 내역'!$B$5:$B$105,0),12)," ") | J13: =IFERROR((G13*H13*I13)*0.00022," ") | K13: =IFERROR(J13*D13," ") | L13: =IFERROR((IF(0=F13*C13,0,IF(14>=C13*F13,14,C13*F13)))," ") | M13: =IFERROR((IF(0=K13*C13,0,IF(14>=K13*C13,14,K13*C13)))," ") | N13: =MAX(L13:M13) -> 0
A14: 9 | B14: =IFERROR(VLOOKUP($N$2&"_"&$A14,'물품 입고 내역'!$A$5:$N$105,2,0)," ") | C14: =IF(" "=D14," ",IF(0<D14,14)) | D14: =IFERROR(VLOOKUP($N$2&"_"&$A14,'물품 입고 내역'!$A$5:$N$105,9,0)," ") | E14: =IFERROR(INDEX('물품 입고 내역'!$B$5:$M$105,MATCH($B14,'물품 입고 내역'!$B$5:$B$105,0),9)," ") | F14: =IFERROR(D14*E14," ") | G14: =IFERROR(INDEX('물품 입고 내역'!$B$5:$M$105,MATCH($B14,'물품 입고 내역'!$B$5:$B$105,0),10)," ") | H14: =IFERROR(INDEX('물품 입고 내역'!$B$5:$M$105,MATCH($B14,'물품 입고 내역'!$B$5:$B$105,0),11)," ") | I14: =IFERROR(INDEX('물품 입고 내역'!$B$5:$M$105,MATCH($B14,'물품 입고 내역'!$B$5:$B$105,0),12)," ") | J14: =IFERROR((G14*H14*I14)*0.00022," ") | K14: =IFERROR(J14*D14," ") | L14: =IFERROR((IF(0=F14*C14,0,IF(14>=C14*F14,14,C14*F14)))," ") | M14: =IFERROR((IF(0=K14*C14,0,IF(14>=K14*C14,14,K14*C14)))," ") | N14: =MAX(L14:M14) -> 0
A15: 10 | B15: =IFERROR(VLOOKUP($N$2&"_"&$A15,'물품 입고 내역'!$A$5:$N$105,2,0)," ") | C15: =IF(" "=D15," ",IF(0<D15,14)) | D15: =IFERROR(VLOOKUP($N$2&"_"&$A15,'물품 입고 내역'!$A$5:$N$105,9,0)," ") | E15: =IFERROR(INDEX('물품 입고 내역'!$B$5:$M$105,MATCH($B15,'물품 입고 내역'!$B$5:$B$105,0),9)," ") | F15: =IFERROR(D15*E15," ") | G15: =IFERROR(INDEX('물품 입고 내역'!$B$5:$M$105,MATCH($B15,'물품 입고 내역'!$B$5:$B$105,0),10)," ") | H15: =IFERROR(INDEX('물품 입고 내역'!$B$5:$M$105,MATCH($B15,'물품 입고 내역'!$B$5:$B$105,0),11)," ") | I15: =IFERROR(INDEX('물품 입고 내역'!$B$5:$M$105,MATCH($B15,'물품 입고 내역'!$B$5:$B$105,0),12)," ") | J15: =IFERROR((G15*H15*I15)*0.00022," ") | K15: =IFERROR(J15*D15," ") | L15: =IFERROR((IF(0=F15*C15,0,IF(14>=C15*F15,14,C15*F15)))," ") | M15: =IFERROR((IF(0=K15*C15,0,IF(14>=K15*C15,14,K15*C15)))," ") | N15: =MAX(L15:M15) -> 0
A16: 합 계 | D16: =SUM(D6:D15) -> 0 | F16: =SUM(F6:F15) -> 0 | K16: =SUM(K6:K15) -> 0
A17: Remark/비 고 | F17: Inland delivery/시내.지방 배송 | L17: 운임 총합 | N17: =SUM(N6:N16) -> 0
A18: =IFERROR(VLOOKUP($N$2&"_"&$A$6,'물품 입고 내역'!$A$5:$O$522,4,0)," ") | L18: 할인 | M18: =IFERROR(MID($A$18,FIND(" "&$L$18&" ",$A$18)+4,3)," ") | N18: =IFERROR(N17*M18,0) -> 0
L19: 특별할인 | M19: =IFERROR(MID($A$18,FIND(" "&$L$19&" ",$A$18)+6,3)," ") | N19: =IFERROR(N17*M19,0) -> 0
L20: 세금 계산서(VAT) | M20: =IFERROR(IF(FIND("세금 계산서",$A$18),10%," ")," ") | N20: =IFERROR((N17-N18-N19)*M20,0) -> 0
L21: 최종 청구 금액 | M21: USD | N21: =(N17-N18-N19+N20) -> 0
M22: KIP | N22: =ROUNDUP((N21*$W$2),-3) -> 0
M23: THB | N23: =ROUNDUP((N21*$W$3),-1) -> 0
M24: WON | N24: =ROUNDUP((N21*$W$4),-2) -> 0
A26: * 모든 비용은 회사의 내규 및 각 물품의 중량/크기 실측을 기준으로 청구되며 최소 운임은 $14/kg 입니다.
A27: * 입.출고지를 떠나시기 전 꼭! 고객님 본인 물품 및 개수 확인 부탁 드립니다. 물품이 출고된 이후 LK그룹은 물품의 파손/분실에 대한 어떠한 책임도 없습니다.
A28: * 물품 도착 및 출고 후 특별한 사유 없이 장기 미수취 물품의 경우 보관료등 기타 추가 비용이 발생 할 수 있습니다.
A29: * 물품 출고 후 1주 후부터 보관료(최소 3불/CBM/day)가 발생하며, 특별한 사유 없이 2달 이상 보관 물품들은 임의로 폐기/처분 될 수 있습니다.
A30: 엘케이 (LK)무역 | H30: * 이용해 주셔서 감사합니다. | K30: 고객사 서명
