Workbook

Sheet Row data
B1: LK내부 환율 | H1: 할인 적용 목록
B2: 화폐 | C2: 기준 환율 | D2: 추가 환율 | E2: 적용 환율
B3: USD-KIP | C3: 23000 | D3: 1000 | E3: =C3+D3 -> 24000 | H3: 라선협 할인 | N3: 지상사협의회 회원사 할인 | U3: 법인장 지인 할인
B4: USD-THB | C4: 34 | D4: 1 | E4: =C4+D4 -> 35 | H4: 해상 | J4: 항공 | N4: 해상 | P4: 항공 | U4: 해상 | W4: 항공
B5: USD-WON | C5: 1545 | D5: 30 | E5: =C5+D5 -> 1575 | H5: 일반 | I5: 기부 | J5: 일반 | K5: 기부 | N5: 일반 | O5: 기부 | P5: 일반 | Q5: 기부 | U5: 일반 | V5: 기부 | W5: 일반 | X5: 기부
H6: 0.2 | I6: 0.3 | J6: 0.05 | K6: 0.1 | N6: 0.2 | O6: 0.3 | P6: 0.05 | Q6: 0.1 | U6: 5~10% | V6: 0.2 | W6: 0.05 | X6: 0.1
B8: 한국 세금 계산서 발급시 계좌번호 | H8: 이름 | J8: 할인율 | K8: 할인금액 | L8: 비 고 | N8: 이름 | P8: 회사 | Q8: 할인율 | R8: 할인금액 | S8: 비 고 | U8: 이름 | W8: 할인율 | X8: 할인금액 | Y8: 비 고
B9: 경남은행 2070133424601 박성호(엘케이무역) | H9: 강병준 | J9: 0.2 | N9: 노인철 | O9: 법인장 | P9: PNPC | Q9: 0.2 | U9: 김인섭 | V9: 요정 투어 (김요셉 형) | W9: 0.1
H10: 강성애 | J10: 0.2 | N10: 고영태 | O10: 부이사장 | P10: 라오스증권거래소 | Q10: 0.2 | U10: 민윤미 | W10: 0.05 | Y10: 대량 특별 할인
B11: 일반 입금 | H11: 김민기 | J11: 0.2 | N11: 고중하 | O11: 대표 | P11: 젤라콘 | Q11: 0.2 | U11: 서정진(서이사님) | W11: 0.1
B12: 경남은행 571-22-0330221 박성호 | H12: 김재양/김반석 | I12: EZRA | J12: 0.2 | N12: 한조운 | O12: 법인장 | P12: iM Leasing | Q12: 0.2 | U12: 이형준 | V12: 골재 판매 | W12: 0.1
H13: 김세진 | J13: 0.2 | N13: 김지운 | O13: 법인장 | P13: BNK 캐피탈 라오스 | Q13: 0.2 | U13: 임홍식 | W13: 0.1
B14: 한국-라오스 해상 xx항차 | H14: 김양현 | J14: 0.2 | N14: 고현식 | O14: 법인장 | P14: BNK 소액대출 MFI | Q14: 0.2 | U14: 정석진 | W14: 0.5
B15: Total | C15: =SUM('LKS 01:LKS XX'!R1) -> 0 | H15: 김영진 | J15: 0.2 | N15: 김일재 | O15: 법인장 | P15: 흥화라오스 | Q15: 0.2 | U15: 최성식 | V15: 큐빅 바이크 | W15: 0.1
B16: Amount | C16: =SUM('LKS 01:LKS XX'!R2) -> 0 | H16: 김재광 | J16: 0.2 | N16: 박성호 | O16: 대표 | P16: LK Group | Q16: 0.2 | U16: 최승현 | V16: 김요셉 지인 | W16: 0.05
H17: 김종한 | J17: 0.2 | N17: 김성원 | O17: 센터장 | P17: 라오스 EPS센터 | Q17: 0.2 | U17: 최재혁 | W17: 0.1
B18: 총 할인 금액 | C18: =K67+R46+X23+X54+X34+X70 -> 0 | H18: 김종훈/김희영 | J18: 0.2 | N18: 송대영 | O18: 실장 | P18: DSA(K-LAO) | Q18: 0.2 | U18: 최지호 | W18: 0.1
H19: 김지훈 | J19: 0.2 | N19: 김민우 | O19: 법인장 | P19: DGB 라오 리싱 | Q19: 0.2 | U19: 최현석 | W19: 0.1
H20: 김창수 | J20: 0.2 | L20: 지방배송 | N20: 오유근/김연희 | O20: 법인장 | P20: 코웨포-라오 인터내셔널 | Q20: 0.2 | U20: 정한진 사장님 | V20: 건설 | W20: 0.1
B21: 현지 발생 비용 | H21: 김필립/이은영 | J21: 0.2 | N21: 유병문 | O21: 법인장 | P21: 현진라오 | Q21: 0.2 | U21: 지석현 | W21: 0.1 | Y21: 대량
B22: 날짜 | C22: 내 용 | D22: 킵 | H22: 박정민 | J22: 0.2 | N22: 최병한 | O22: 부사장 | P22: 삼안 | Q22: 0.2
H23: 박종복 | J23: 0.2 | N23: 이범주 | O23: 단장, 전무 | P23: 삼안 | Q23: 0.2 | U23: 할인 총합 | X23: =SUM(X9:X22) -> 0
H24: 박진경 | I24: 본죽/삼부팩 | J24: 0.2 | N24: 이성한 | O24: 상무 | P24: 한국종합기술 | Q24: 0.2
H25: 박창성 | J25: 0.2 | N25: 주인현/한상욱(김유진) | O25: 법인장 | P25: KB 코라오 리싱 | Q25: 0.2
H26: 백규현/백인철 | I26: 샤론스쿨 | J26: 0.2 | N26: 이재원 | O26: 대표 | P26: 그린굿스 | Q26: 0.2 | U26: 아파트 고객 할인
H27: 백대식 | J27: 0.2 | N27: 이재현 | O27: 법인장 | P27: Paul Golden Lao(좋은차닷컴) | Q27: 0.2 | U27: 이름 | W27: 할인율 | X27: 할인금액 | Y27: 비 고
H28: 백상호 | J28: 0.2 | N28: 이제원 | O28: 법인장 | P28: 웰컴 리싱 라오 | Q28: 0.2 | U28: 이동현 | V28: 101호 고객 | W28: 0.1
D29: =SUM(D23:D28) -> 0 | E29: =D29/C3 -> 0 | H29: 백운송 | J29: 0.2 | N29: 박준규/간현진/ 정지운(오지은)/이종원 | P29: KOTRA | Q29: 0.2 | U29: 정민주 | V29: 206호 고객 | W29: 0.1
H30: 백총명 | J30: 0.2 | N30: 이창열 | O30: 부장 | P30: 라오스증권거래소 | Q30: 0.2 | U30: 박상욱 | V30: 106호 고객 | W30: 0.1
H31: 변종승 | I31: 기쁜교회 | J31: 0.2 | N31: 이현열 | O31: 지점장 | P31: 에어부산 | Q31: 0.2 | U31: 박상용 | V31: 301호 고객 | W31: 0.1
B32: 총 합산 액 | C32: =C16-E29 -> 0 | H32: 손사랑 | J32: 0.2 | L32: 지방배송 | N32: 임정민 | O32: 지점장 | P32: 제주항공 | Q32: 0.2 | U32: 진정우 | V32: 105호 고객 | W32: 0.3 | Y32: 기부
H33: 신라함/신대웅 | J33: 0.2 | N33: 정석진 | O33: 지사장 | P33: LK Group | Q33: 0.2
H34: 윤영숙/우상봉 | J34: 0.2 | N34: 최완식/고대종 | O34: 단장 | P34: 솔루텍시스템 라오 | Q34: 0.2 | U34: 할인 총합 | X34: =SUM(X28:X33) -> 0
H35: 원순연 | J35: 0.2 | L35: 지방배송 | N35: 한태원 | O35: CEO | P35: 엘에스엠 | Q35: 0.2
H36: 곽낭아/이경희 | J36: 0.2 | L36: 지방배송 | N36: 황헌기 | O36: 대표 | P36: 정원상사 | Q36: 0.2
H37: 이관택/정유은 | J37: 0.2 | L37: 지방배송 | N37: 강남규 | O37: 부장 | P37: emart | Q37: 0.2 | U37: 기업 할인
H38: 이규상 | J38: 0.2 | N38: 정길영 | O38: 행장 | P38: 부영라오은행 | Q38: 0.2 | U38: 이름 | V38: 제품 | W38: 할인율 | X38: 할인금액 | Y38: 비 고
H39: 이명숙/임기환 | J39: 0.2 | L39: (오혜창) | N39: 박대성 | O39: 차장 | P39: 부영라오 골프장 | Q39: 0.2 | U39: Love STK | V39: 다단계제품 | W39: 0.1
H40: 이병목/장혜진 | J40: 0.2 | N40: 이성한 | O40: 상무 | P40: 한국종합기술 | Q40: 0.2 | U40: Nice to meat you | W40: 0.1
H41: 이상미 | J41: 0.2 | N41: 김승용 | O41: 대표이사 | P41: 코코넛샤일로 | Q41: 0.2 | U41: Peter Kim/Viengchay | V41: 성경책 | W41: 0.2
...

Sheet 시내, 지방배송
A1: No. | B1: Name | C1: Name | D1: Tel | E1: Local company | F1: Destination Address | G1: Paid by
A2: 1 | B2: 구상채 / Oly | C2: Ku Sang Chae / Oly | D2: 020-5431-3355 020-5486-5440 | E2: HAL | F2: ສາຂາ ບ້ານ ປ່າອອ້ຍ, ຫວ້ຍຊາຍ, ບໍ່ແກ້ວ
E3: ANS
A4: 2 | B4: 김석현 | C4: KIM, Sukhyun | D4: 020-5566-8605 | E4: HAL | F4: Savannaket (ສາຂາ ຕະຫຼາດ ໃຫຍ່)
E5: ANS
A6: 3 | B6: 김영훈/010 2490 9081 | C6: KIM YoungHoon | D6: 020 9637 1027 | E6: HAL | F6: ສາຂາ ຫນອງຂຽວ, ເມືອງງອຍ
E7: ANS
A8: 4 | B8: 김정호 | C8: Mr. KIM Jung Ho | D8: '020-9697-1366 | E8: HAL | F8: Namngam village, paek district, xiengkhuang provice
E9: ANS
A10: 5 | B10: 김창수 | C10: Kim chang soo | D10: 020-5202-6723 | E10: HAL | F10: ແຟຣນຊີບມໍ
E11: ANS
A12: 6 | B12: 나유리 | C12: Ms. NA Yoo Ri | D12: 020-5538-6544 | E12: HAL | F12: LPB province
E13: ANS
A14: 7 | B14: 남미화 | C14: NAM, Mi Hwa | D14: 020 9593 7554 | E14: HAL | F14: ສາຂາ ບ້ານຊຽງມ່ວນ (ຕະຫລາດມືດ), ເມືອງຫລວງພະບາງ, ຫລວງພະບາງ
E15: ANS
A16: 8 | B16: 남윤천 | C16: NAM Yun Cheon | D16: 020 5550 8172 | E16: HAL | F16: ບ້ານມີໄຊ, Paksan, Bolikhamxai
E17: ANS
A18: 9 | B18: 문종곤 | C18: Mr. MOON Joong Gon | D18: 020 9956 0707 | E18: HAL | F18: Pakse city
E19: ANS
A20: 10 | B20: 백원상 | C20: Mr. BAIK woon song | D20: 020-5605-1991 | E20: HAL | F20: ປາຍທາງ xieng mouak village LPB district, LPB province
E21: ANS
A22: 11 | B22: 손사랑 | C22: Mr. SON Sa Rang | D22: 020-5959-1790 | E22: HAL | F22: Luangprabang city
E23: ANS
A24: 12 | B24: 쑤빈 | C24: Soubin | D24: 020-7777-1940 020-528-83018 | E24: HAL | F24: ກາສີ, ຕົວເມືອງກາສີ
E25: ANS
A26: 13 | B26: 우형철 | C26: Mr. WOO Hyung Chu | D26: 020-9505-3052 | E26: HAL | F26: PAKSE km8
E27: ANS
A28: 14 | B28: 윤성식 | C28: Mr. YOON Sung Sik | D28: 020-9604-3012 | E28: HAL | F28: Ban Keun Napheng
E29: ANS
A30: 15 | B30: 곽낭아/이경희 | C30: LEE kyung hee/ຈຳປາລີ | D30: 020-9550-5260 020-9784-4110 | E30: HAL | F30: Oudomxay Muangxay ໜອງແມງດາ
E31: ANS | F31: ສາຂາ ບ້ານບໍ່ ເມືອງໄຊ ແຂວງອຸດົມໄຊ
E32: ບໍລິສັດ ບັນດິດຂົນສົ່ງ (ຊົມພູ) ນະຄອນຫລວງ - ອຸດົມໄຊ 030-5471650, 020-9998-8884, 5547-6377 | F32: ບ້ານບໍ່ ເມືອງໄຊ ແຂວງອຸດົມໄຊ
A33: 16 | B33: 이복희 | C33: LEE Bok Hee | D33: 020-5547-0797 | E33: HAL | F33: ສາຂາ ສຸນັນທາ, Savannaket
E34: ANS
A35: 17 | B35: 이상호 | C35: LEE sang ho | D35: 020-9552-2978 | E35: HAL | F35: ອັດຕາປື ສາມັກຄີໄຊ 1
E36: ANS
A37: 18 | B37: 이우용 | C37: Seevisai Manephong | D37: 020-5847-7710 | E37: HAL | F37: ສາຂາ ຫນອງຂຽວ, ເມືອງງອຍ, ຫລວງພະບາງ
E38: ANS | F38: ສາຂາ ປ່ອງຄຳ ເມືອງຫຼວງພະບາງ ແຂວງຫຼວງພະບາງ
A39: 19 | B39: 이존희 | C39: LEE Jonhee | D39: 020-5625-9292 | E39: HAL | F39: ອັດຕາປື ສາມັກຄີໄຊ 1
E40: ANS
...

Sheet 물품 입고 내역
B1: 2026년 xx항차 해상 물품 입고 내역 (Cargo list)
B2: 배송자 | D2: LK그룹, LK무역 (LK Trading) | F2: 주소 | G2: 인천광역시 중구 항동 7가 104-7 드림물류센터 4층 1번도크 집하장 라오스 LK무역 수출 물량 | N2: 전화번호 | O2: +82) 32 -886 -9603
B3: 수령자 | D3: LK Group(LAKO Co., Ltd) | F3: 주소 | G3: 비엔티엔시, 씨싿따낙구, 싸판텅 느아 09, 11번 골목, LK 빌딩 | N3: 전화번호 | O3: +856) 20-9112-6780
B4: 접수 마감일 | D4: 2026-xx-xx | F4: 출항일 | G4: 2026-xx-xx | K4: 출발지 | L4: 한국 | N4: 도착지 | O4: 라오스
B5: No. | C5: 송장 번호 | D5: 발신인 | E5: 수신인 | F5: 전화번호 | G5: 내용물 | H5: 포장형태 | I5: 수량 | J5: 중량(KGS) | K5: L | L5: w | M5: H | N5: 영수 번호 | O5: 구획 | P5: 비고 | Q5: 접수일
A6: =N6&"_"&COUNTIF($N$6:N6,N6) -> _0 | B6: S001 | O6: =IFERROR(INDEX('고객 리스트'!$A$4:$D$150,MATCH(N6,'고객 리스트'!$A$4:$A$150,0),3)," ")
A7: =N7&"_"&COUNTIF($N$6:N7,N7) -> _0 | B7: S002 | O7: =IFERROR(INDEX('고객 리스트'!$A$4:$D$150,MATCH(N7,'고객 리스트'!$A$4:$A$150,0),3)," ")
A8: =N8&"_"&COUNTIF($N$6:N8,N8) -> _0 | B8: S003 | O8: =IFERROR(INDEX('고객 리스트'!$A$4:$D$150,MATCH(N8,'고객 리스트'!$A$4:$A$150,0),3)," ")
A9: =N9&"_"&COUNTIF($N$6:N9,N9) -> _0 | B9: S004 | O9: =IFERROR(INDEX('고객 리스트'!$A$4:$D$150,MATCH(N9,'고객 리스트'!$A$4:$A$150,0),3)," ")
A10: =N10&"_"&COUNTIF($N$6:N10,N10) -> _0 | B10: S005 | O10: =IFERROR(INDEX('고객 리스트'!$A$4:$D$150,MATCH(N10,'고객 리스트'!$A$4:$A$150,0),3)," ")
A11: =N11&"_"&COUNTIF($N$6:N11,N11) -> _0 | B11: S006 | O11: =IFERROR(INDEX('고객 리스트'!$A$4:$D$150,MATCH(N11,'고객 리스트'!$A$4:$A$150,0),3)," ")
A12: =N12&"_"&COUNTIF($N$6:N12,N12) -> _0 | B12: S007 | O12: =IFERROR(INDEX('고객 리스트'!$A$4:$D$150,MATCH(N12,'고객 리스트'!$A$4:$A$150,0),3)," ")
A13: =N13&"_"&COUNTIF($N$6:N13,N13) -> _0 | B13: S008 | O13: =IFERROR(INDEX('고객 리스트'!$A$4:$D$150,MATCH(N13,'고객 리스트'!$A$4:$A$150,0),3)," ")
A14: =N14&"_"&COUNTIF($N$6:N14,N14) -> _0 | B14: S009 | O14: =IFERROR(INDEX('고객 리스트'!$A$4:$D$150,MATCH(N14,'고객 리스트'!$A$4:$A$150,0),3)," ")
A15: =N15&"_"&COUNTIF($N$6:N15,N15) -> _0 | B15: S010 | O15: =IFERROR(INDEX('고객 리스트'!$A$4:$D$150,MATCH(N15,'고객 리스트'!$A$4:$A$150,0),3)," ")
A16: =N16&"_"&COUNTIF($N$6:N16,N16) -> _0 | B16: S011 | O16: =IFERROR(INDEX('고객 리스트'!$A$4:$D$150,MATCH(N16,'고객 리스트'!$A$4:$A$150,0),3)," ")
A17: =N17&"_"&COUNTIF($N$6:N17,N17) -> _0 | B17: S012 | O17: =IFERROR(INDEX('고객 리스트'!$A$4:$D$150,MATCH(N17,'고객 리스트'!$A$4:$A$150,0),3)," ")
... A1005: =N1005&"_"&COUNTIF($N$6:N1005,N1005) -> _0 | B1005: S1000 | O1005: =IFERROR(INDEX('고객 리스트'!$A$4:$D$150,MATCH(N1005,'고객 리스트'!$A$4:$A$150,0),3)," ")
B1006: 총 물량 | H1006: 박스 | I1006: =SUM(I6:I1005) -> 0
B1007: 합포장 물량 | H1007: 박스
B1008: 합포장 개수 | H1008: 박스
B1009: 최종 실제 | H1009: 박스 | I1009: =I1006-I1007+I1008 -> 0

Sheet 하역 Zone
A1: No | B1: Zone | C1: 1 | D1: No | E1: Zone | F1: 1 | G1: No | H1: Zone | I1: 1 | J1: No | K1: Zone | L1: 1 | M1: No | N1: Zone
A2: ='물품 입고 내역'!$B6 -> S001 | B2: =IFERROR(VLOOKUP(A2,'물품 입고 내역'!$B$5:$O$1005,14,0)," ") | D2: ='물품 입고 내역'!$B56 -> S051 | E2: =IFERROR(VLOOKUP(D2,'물품 입고 내역'!$B$5:$O$1005,14,0)," ") | G2: ='물품 입고 내역'!$B106 -> S101 | H2: =IFERROR(VLOOKUP(G2,'물품 입고 내역'!$B$5:$O$1005,14,0)," ") | J2: ='물품 입고 내역'!$B156 -> S151 | K2: =IFERROR(VLOOKUP(J2,'물품 입고 내역'!$B$5:$O$1005,14,0)," ") | M2: ='물품 입고 내역'!$B206 -> S201 | N2: =IFERROR(VLOOKUP(M2,'물품 입고 내역'!$B$5:$O$1005,14,0)," ")
A3: ='물품 입고 내역'!$B7 -> S002 | B3: =IFERROR(VLOOKUP(A3,'물품 입고 내역'!$B$5:$O$1005,14,0)," ") | D3: ='물품 입고 내역'!$B57 -> S052 | E3: =IFERROR(VLOOKUP(D3,'물품 입고 내역'!$B$5:$O$1005,14,0)," ") | G3: ='물품 입고 내역'!$B107 -> S102 | H3: =IFERROR(VLOOKUP(G3,'물품 입고 내역'!$B$5:$O$1005,14,0)," ") | J3: ='물품 입고 내역'!$B157 -> S152 | K3: =IFERROR(VLOOKUP(J3,'물품 입고 내역'!$B$5:$O$1005,14,0)," ") | M3: ='물품 입고 내역'!$B207 -> S202 | N3: =IFERROR(VLOOKUP(M3,'물품 입고 내역'!$B$5:$O$1005,14,0)," ")
A4: ='물품 입고 내역'!$B8 -> S003 | B4: =IFERROR(VLOOKUP(A4,'물품 입고 내역'!$B$5:$O$1005,14,0)," ") | D4: ='물품 입고 내역'!$B58 -> S053 | E4: =IFERROR(VLOOKUP(D4,'물품 입고 내역'!$B$5:$O$1005,14,0)," ") | G4: ='물품 입고 내역'!$B108 -> S103 | H4: =IFERROR(VLOOKUP(G4,'물품 입고 내역'!$B$5:$O$1005,14,0)," ") | J4: ='물품 입고 내역'!$B158 -> S153 | K4: =IFERROR(VLOOKUP(J4,'물품 입고 내역'!$B$5:$O$1005,14,0)," ") | M4: ='물품 입고 내역'!$B208 -> S203 | N4: =IFERROR(VLOOKUP(M4,'물품 입고 내역'!$B$5:$O$1005,14,0)," ")
A5: ='물품 입고 내역'!$B9 -> S004 | B5: =IFERROR(VLOOKUP(A5,'물품 입고 내역'!$B$5:$O$1005,14,0)," ") | D5: ='물품 입고 내역'!$B59 -> S054 | E5: =IFERROR(VLOOKUP(D5,'물품 입고 내역'!$B$5:$O$1005,14,0)," ") | G5: ='물품 입고 내역'!$B109 -> S104 | H5: =IFERROR(VLOOKUP(G5,'물품 입고 내역'!$B$5:$O$1005,14,0)," ") | J5: ='물품 입고 내역'!$B159 -> S154 | K5: =IFERROR(VLOOKUP(J5,'물품 입고 내역'!$B$5:$O$1005,14,0)," ") | M5: ='물품 입고 내역'!$B209 -> S204 | N5: =IFERROR(VLOOKUP(M5,'물품 입고 내역'!$B$5:$O$1005,14,0)," ")
A6: ='물품 입고 내역'!$B10 -> S005 | B6: =IFERROR(VLOOKUP(A6,'물품 입고 내역'!$B$5:$O$1005,14,0)," ") | D6: ='물품 입고 내역'!$B60 -> S055 | E6: =IFERROR(VLOOKUP(D6,'물품 입고 내역'!$B$5:$O$1005,14,0)," ") | G6: ='물품 입고 내역'!$B110 -> S105 | H6: =IFERROR(VLOOKUP(G6,'물품 입고 내역'!$B$5:$O$1005,14,0)," ") | J6: ='물품 입고 내역'!$B160 -> S155 | K6: =IFERROR(VLOOKUP(J6,'물품 입고 내역'!$B$5:$O$1005,14,0)," ") | M6: ='물품 입고 내역'!$B210 -> S205 | N6: =IFERROR(VLOOKUP(M6,'물품 입고 내역'!$B$5:$O$1005,14,0)," ")
A7: ='물품 입고 내역'!$B11 -> S006 | B7: =IFERROR(VLOOKUP(A7,'물품 입고 내역'!$B$5:$O$1005,14,0)," ") | D7: ='물품 입고 내역'!$B61 -> S056 | E7: =IFERROR(VLOOKUP(D7,'물품 입고 내역'!$B$5:$O$1005,14,0)," ") | G7: ='물품 입고 내역'!$B111 -> S106 | H7: =IFERROR(VLOOKUP(G7,'물품 입고 내역'!$B$5:$O$1005,14,0)," ") | J7: ='물품 입고 내역'!$B161 -> S156 | K7: =IFERROR(VLOOKUP(J7,'물품 입고 내역'!$B$5:$O$1005,14,0)," ") | M7: ='물품 입고 내역'!$B211 -> S206 | N7: =IFERROR(VLOOKUP(M7,'물품 입고 내역'!$B$5:$O$1005,14,0)," ")
A8: ='물품 입고 내역'!$B12 -> S007 | B8: =IFERROR(VLOOKUP(A8,'물품 입고 내역'!$B$5:$O$1005,14,0)," ") | D8: ='물품 입고 내역'!$B62 -> S057 | E8: =IFERROR(VLOOKUP(D8,'물품 입고 내역'!$B$5:$O$1005,14,0)," ") | G8: ='물품 입고 내역'!$B112 -> S107 | H8: =IFERROR(VLOOKUP(G8,'물품 입고 내역'!$B$5:$O$1005,14,0)," ") | J8: ='물품 입고 내역'!$B162 -> S157 | K8: =IFERROR(VLOOKUP(J8,'물품 입고 내역'!$B$5:$O$1005,14,0)," ") | M8: ='물품 입고 내역'!$B212 -> S207 | N8: =IFERROR(VLOOKUP(M8,'물품 입고 내역'!$B$5:$O$1005,14,0)," ")
A9: ='물품 입고 내역'!$B13 -> S008 | B9: =IFERROR(VLOOKUP(A9,'물품 입고 내역'!$B$5:$O$1005,14,0)," ") | D9: ='물품 입고 내역'!$B63 -> S058 | E9: =IFERROR(VLOOKUP(D9,'물품 입고 내역'!$B$5:$O$1005,14,0)," ") | G9: ='물품 입고 내역'!$B113 -> S108 | H9: =IFERROR(VLOOKUP(G9,'물품 입고 내역'!$B$5:$O$1005,14,0)," ") | J9: ='물품 입고 내역'!$B163 -> S158 | K9: =IFERROR(VLOOKUP(J9,'물품 입고 내역'!$B$5:$O$1005,14,0)," ") | M9: ='물품 입고 내역'!$B213 -> S208 | N9: =IFERROR(VLOOKUP(M9,'물품 입고 내역'!$B$5:$O$1005,14,0)," ")
A10: ='물품 입고 내역'!$B14 -> S009 | B10: =IFERROR(VLOOKUP(A10,'물품 입고 내역'!$B$5:$O$1005,14,0)," ") | D10: ='물품 입고 내역'!$B64 -> S059 | E10: =IFERROR(VLOOKUP(D10,'물품 입고 내역'!$B$5:$O$1005,14,0)," ") | G10: ='물품 입고 내역'!$B114 -> S109 | H10: =IFERROR(VLOOKUP(G10,'물품 입고 내역'!$B$5:$O$1005,14,0)," ") | J10: ='물품 입고 내역'!$B164 -> S159 | K10: =IFERROR(VLOOKUP(J10,'물품 입고 내역'!$B$5:$O$1005,14,0)," ") | M10: ='물품 입고 내역'!$B214 -> S209 | N10: =IFERROR(VLOOKUP(M10,'물품 입고 내역'!$B$5:$O$1005,14,0)," ")
A11: ='물품 입고 내역'!$B15 -> S010 | B11: =IFERROR(VLOOKUP(A11,'물품 입고 내역'!$B$5:$O$1005,14,0)," ") | D11: ='물품 입고 내역'!$B65 -> S060 | E11: =IFERROR(VLOOKUP(D11,'물품 입고 내역'!$B$5:$O$1005,14,0)," ") | G11: ='물품 입고 내역'!$B115 -> S110 | H11: =IFERROR(VLOOKUP(G11,'물품 입고 내역'!$B$5:$O$1005,14,0)," ") | J11: ='물품 입고 내역'!$B165 -> S160 | K11: =IFERROR(VLOOKUP(J11,'물품 입고 내역'!$B$5:$O$1005,14,0)," ") | M11: ='물품 입고 내역'!$B215 -> S210 | N11: =IFERROR(VLOOKUP(M11,'물품 입고 내역'!$B$5:$O$1005,14,0)," ")
A12: ='물품 입고 내역'!$B16 -> S011 | B12: =IFERROR(VLOOKUP(A12,'물품 입고 내역'!$B$5:$O$1005,14,0)," ") | D12: ='물품 입고 내역'!$B66 -> S061 | E12: =IFERROR(VLOOKUP(D12,'물품 입고 내역'!$B$5:$O$1005,14,0)," ") | G12: ='물품 입고 내역'!$B116 -> S111 | H12: =IFERROR(VLOOKUP(G12,'물품 입고 내역'!$B$5:$O$1005,14,0)," ") | J12: ='물품 입고 내역'!$B166 -> S161 | K12: =IFERROR(VLOOKUP(J12,'물품 입고 내역'!$B$5:$O$1005,14,0)," ") | M12: ='물품 입고 내역'!$B216 -> S211 | N12: =IFERROR(VLOOKUP(M12,'물품 입고 내역'!$B$5:$O$1005,14,0)," ")
A13: ='물품 입고 내역'!$B17 -> S012 | B13: =IFERROR(VLOOKUP(A13,'물품 입고 내역'!$B$5:$O$1005,14,0)," ") | D13: ='물품 입고 내역'!$B67 -> S062 | E13: =IFERROR(VLOOKUP(D13,'물품 입고 내역'!$B$5:$O$1005,14,0)," ") | G13: ='물품 입고 내역'!$B117 -> S112 | H13: =IFERROR(VLOOKUP(G13,'물품 입고 내역'!$B$5:$O$1005,14,0)," ") | J13: ='물품 입고 내역'!$B167 -> S162 | K13: =IFERROR(VLOOKUP(J13,'물품 입고 내역'!$B$5:$O$1005,14,0)," ") | M13: ='물품 입고 내역'!$B217 -> S212 | N13: =IFERROR(VLOOKUP(M13,'물품 입고 내역'!$B$5:$O$1005,14,0)," ")
... A51: ='물품 입고 내역'!$B55 -> S050 | B51: =IFERROR(VLOOKUP(A51,'물품 입고 내역'!$B$5:$O$1005,14,0)," ") | D51: ='물품 입고 내역'!$B105 -> S100 | E51: =IFERROR(VLOOKUP(D51,'물품 입고 내역'!$B$5:$O$1005,14,0)," ") | G51: ='물품 입고 내역'!$B155 -> S150 | H51: =IFERROR(VLOOKUP(G51,'물품 입고 내역'!$B$5:$O$1005,14,0)," ") | J51: ='물품 입고 내역'!$B205 -> S200 | K51: =IFERROR(VLOOKUP(J51,'물품 입고 내역'!$B$5:$O$1005,14,0)," ") | M51: ='물품 입고 내역'!$B255 -> S250 | N51: =IFERROR(VLOOKUP(M51,'물품 입고 내역'!$B$5:$O$1005,14,0)," ")
A52: No | B52: Zone | C52: 1 | D52: No | E52: Zone | F52: 1 | G52: No | H52: Zone | I52: 1 | J52: No | K52: Zone | L52: 1 | M52: No | N52: Zone
A53: ='물품 입고 내역'!$B256 -> S251 | B53: =IFERROR(VLOOKUP(A53,'물품 입고 내역'!$B$5:$O$1005,14,0)," ") | D53: ='물품 입고 내역'!$B306 -> S301 | E53: =IFERROR(VLOOKUP(D53,'물품 입고 내역'!$B$5:$O$1005,14,0)," ") | G53: ='물품 입고 내역'!$B356 -> S351 | H53: =IFERROR(VLOOKUP(G53,'물품 입고 내역'!$B$5:$O$1005,14,0)," ") | J53: ='물품 입고 내역'!$B406 -> S401 | K53: =IFERROR(VLOOKUP(J53,'물품 입고 내역'!$B$5:$O$1005,14,0)," ") | M53: ='물품 입고 내역'!$B456 -> S451 | N53: =IFERROR(VLOOKUP(M53,'물품 입고 내역'!$B$5:$O$1005,14,0)," ")
A54: ='물품 입고 내역'!$B257 -> S252 | B54: =IFERROR(VLOOKUP(A54,'물품 입고 내역'!$B$5:$O$1005,14,0)," ") | D54: ='물품 입고 내역'!$B307 -> S302 | E54: =IFERROR(VLOOKUP(D54,'물품 입고 내역'!$B$5:$O$1005,14,0)," ") | G54: ='물품 입고 내역'!$B357 -> S352 | H54: =IFERROR(VLOOKUP(G54,'물품 입고 내역'!$B$5:$O$1005,14,0)," ") | J54: ='물품 입고 내역'!$B407 -> S402 | K54: =IFERROR(VLOOKUP(J54,'물품 입고 내역'!$B$5:$O$1005,14,0)," ") | M54: ='물품 입고 내역'!$B457 -> S452 | N54: =IFERROR(VLOOKUP(M54,'물품 입고 내역'!$B$5:$O$1005,14,0)," ")
A55: ='물품 입고 내역'!$B258 -> S253 | B55: =IFERROR(VLOOKUP(A55,'물품 입고 내역'!$B$5:$O$1005,14,0)," ") | D55: ='물품 입고 내역'!$B308 -> S303 | E55: =IFERROR(VLOOKUP(D55,'물품 입고 내역'!$B$5:$O$1005,14,0)," ") | G55: ='물품 입고 내역'!$B358 -> S353 | H55: =IFERROR(VLOOKUP(G55,'물품 입고 내역'!$B$5:$O$1005,14,0)," ") | J55: ='물품 입고 내역'!$B408 -> S403 | K55: =IFERROR(VLOOKUP(J55,'물품 입고 내역'!$B$5:$O$1005,14,0)," ") | M55: ='물품 입고 내역'!$B458 -> S453 | N55: =IFERROR(VLOOKUP(M55,'물품 입고 내역'!$B$5:$O$1005,14,0)," ")
A56: ='물품 입고 내역'!$B259 -> S254 | B56: =IFERROR(VLOOKUP(A56,'물품 입고 내역'!$B$5:$O$1005,14,0)," ") | D56: ='물품 입고 내역'!$B309 -> S304 | E56: =IFERROR(VLOOKUP(D56,'물품 입고 내역'!$B$5:$O$1005,14,0)," ") | G56: ='물품 입고 내역'!$B359 -> S354 | H56: =IFERROR(VLOOKUP(G56,'물품 입고 내역'!$B$5:$O$1005,14,0)," ") | J56: ='물품 입고 내역'!$B409 -> S404 | K56: =IFERROR(VLOOKUP(J56,'물품 입고 내역'!$B$5:$O$1005,14,0)," ") | M56: ='물품 입고 내역'!$B459 -> S454 | N56: =IFERROR(VLOOKUP(M56,'물품 입고 내역'!$B$5:$O$1005,14,0)," ")
A57: ='물품 입고 내역'!$B260 -> S255 | B57: =IFERROR(VLOOKUP(A57,'물품 입고 내역'!$B$5:$O$1005,14,0)," ") | D57: ='물품 입고 내역'!$B310 -> S305 | E57: =IFERROR(VLOOKUP(D57,'물품 입고 내역'!$B$5:$O$1005,14,0)," ") | G57: ='물품 입고 내역'!$B360 -> S355 | H57: =IFERROR(VLOOKUP(G57,'물품 입고 내역'!$B$5:$O$1005,14,0)," ") | J57: ='물품 입고 내역'!$B410 -> S405 | K57: =IFERROR(VLOOKUP(J57,'물품 입고 내역'!$B$5:$O$1005,14,0)," ") | M57: ='물품 입고 내역'!$B460 -> S455 | N57: =IFERROR(VLOOKUP(M57,'물품 입고 내역'!$B$5:$O$1005,14,0)," ")
A58: ='물품 입고 내역'!$B261 -> S256 | B58: =IFERROR(VLOOKUP(A58,'물품 입고 내역'!$B$5:$O$1005,14,0)," ") | D58: ='물품 입고 내역'!$B311 -> S306 | E58: =IFERROR(VLOOKUP(D58,'물품 입고 내역'!$B$5:$O$1005,14,0)," ") | G58: ='물품 입고 내역'!$B361 -> S356 | H58: =IFERROR(VLOOKUP(G58,'물품 입고 내역'!$B$5:$O$1005,14,0)," ") | J58: ='물품 입고 내역'!$B411 -> S406 | K58: =IFERROR(VLOOKUP(J58,'물품 입고 내역'!$B$5:$O$1005,14,0)," ") | M58: ='물품 입고 내역'!$B461 -> S456 | N58: =IFERROR(VLOOKUP(M58,'물품 입고 내역'!$B$5:$O$1005,14,0)," ")
A59: ='물품 입고 내역'!$B262 -> S257 | B59: =IFERROR(VLOOKUP(A59,'물품 입고 내역'!$B$5:$O$1005,14,0)," ") | D59: ='물품 입고 내역'!$B312 -> S307 | E59: =IFERROR(VLOOKUP(D59,'물품 입고 내역'!$B$5:$O$1005,14,0)," ") | G59: ='물품 입고 내역'!$B362 -> S357 | H59: =IFERROR(VLOOKUP(G59,'물품 입고 내역'!$B$5:$O$1005,14,0)," ") | J59: ='물품 입고 내역'!$B412 -> S407 | K59: =IFERROR(VLOOKUP(J59,'물품 입고 내역'!$B$5:$O$1005,14,0)," ") | M59: ='물품 입고 내역'!$B462 -> S457 | N59: =IFERROR(VLOOKUP(M59,'물품 입고 내역'!$B$5:$O$1005,14,0)," ")
A60: ='물품 입고 내역'!$B263 -> S258 | B60: =IFERROR(VLOOKUP(A60,'물품 입고 내역'!$B$5:$O$1005,14,0)," ") | D60: ='물품 입고 내역'!$B313 -> S308 | E60: =IFERROR(VLOOKUP(D60,'물품 입고 내역'!$B$5:$O$1005,14,0)," ") | G60: ='물품 입고 내역'!$B363 -> S358 | H60: =IFERROR(VLOOKUP(G60,'물품 입고 내역'!$B$5:$O$1005,14,0)," ") | J60: ='물품 입고 내역'!$B413 -> S408 | K60: =IFERROR(VLOOKUP(J60,'물품 입고 내역'!$B$5:$O$1005,14,0)," ") | M60: ='물품 입고 내역'!$B463 -> S458 | N60: =IFERROR(VLOOKUP(M60,'물품 입고 내역'!$B$5:$O$1005,14,0)," ")
A61: ='물품 입고 내역'!$B264 -> S259 | B61: =IFERROR(VLOOKUP(A61,'물품 입고 내역'!$B$5:$O$1005,14,0)," ") | D61: ='물품 입고 내역'!$B314 -> S309 | E61: =IFERROR(VLOOKUP(D61,'물품 입고 내역'!$B$5:$O$1005,14,0)," ") | G61: ='물품 입고 내역'!$B364 -> S359 | H61: =IFERROR(VLOOKUP(G61,'물품 입고 내역'!$B$5:$O$1005,14,0)," ") | J61: ='물품 입고 내역'!$B414 -> S409 | K61: =IFERROR(VLOOKUP(J61,'물품 입고 내역'!$B$5:$O$1005,14,0)," ") | M61: ='물품 입고 내역'!$B464 -> S459 | N61: =IFERROR(VLOOKUP(M61,'물품 입고 내역'!$B$5:$O$1005,14,0)," ")
A62: ='물품 입고 내역'!$B265 -> S260 | B62: =IFERROR(VLOOKUP(A62,'물품 입고 내역'!$B$5:$O$1005,14,0)," ") | D62: ='물품 입고 내역'!$B315 -> S310 | E62: =IFERROR(VLOOKUP(D62,'물품 입고 내역'!$B$5:$O$1005,14,0)," ") | G62: ='물품 입고 내역'!$B365 -> S360 | H62: =IFERROR(VLOOKUP(G62,'물품 입고 내역'!$B$5:$O$1005,14,0)," ") | J62: ='물품 입고 내역'!$B415 -> S410 | K62: =IFERROR(VLOOKUP(J62,'물품 입고 내역'!$B$5:$O$1005,14,0)," ") | M62: ='물품 입고 내역'!$B465 -> S460 | N62: =IFERROR(VLOOKUP(M62,'물품 입고 내역'!$B$5:$O$1005,14,0)," ")
A63: ='물품 입고 내역'!$B266 -> S261 | B63: =IFERROR(VLOOKUP(A63,'물품 입고 내역'!$B$5:$O$1005,14,0)," ") | D63: ='물품 입고 내역'!$B316 -> S311 | E63: =IFERROR(VLOOKUP(D63,'물품 입고 내역'!$B$5:$O$1005,14,0)," ") | G63: ='물품 입고 내역'!$B366 -> S361 | H63: =IFERROR(VLOOKUP(G63,'물품 입고 내역'!$B$5:$O$1005,14,0)," ") | J63: ='물품 입고 내역'!$B416 -> S411 | K63: =IFERROR(VLOOKUP(J63,'물품 입고 내역'!$B$5:$O$1005,14,0)," ") | M63: ='물품 입고 내역'!$B466 -> S461 | N63: =IFERROR(VLOOKUP(M63,'물품 입고 내역'!$B$5:$O$1005,14,0)," ")
A64: ='물품 입고 내역'!$B267 -> S262 | B64: =IFERROR(VLOOKUP(A64,'물품 입고 내역'!$B$5:$O$1005,14,0)," ") | D64: ='물품 입고 내역'!$B317 -> S312 | E64: =IFERROR(VLOOKUP(D64,'물품 입고 내역'!$B$5:$O$1005,14,0)," ") | G64: ='물품 입고 내역'!$B367 -> S362 | H64: =IFERROR(VLOOKUP(G64,'물품 입고 내역'!$B$5:$O$1005,14,0)," ") | J64: ='물품 입고 내역'!$B417 -> S412 | K64: =IFERROR(VLOOKUP(J64,'물품 입고 내역'!$B$5:$O$1005,14,0)," ") | M64: ='물품 입고 내역'!$B467 -> S462 | N64: =IFERROR(VLOOKUP(M64,'물품 입고 내역'!$B$5:$O$1005,14,0)," ")
... A102: ='물품 입고 내역'!$B305 -> S300 | B102: =IFERROR(VLOOKUP(A102,'물품 입고 내역'!$B$5:$O$1005,14,0)," ") | D102: ='물품 입고 내역'!$B355 -> S350 | E102: =IFERROR(VLOOKUP(D102,'물품 입고 내역'!$B$5:$O$1005,14,0)," ") | G102: ='물품 입고 내역'!$B405 -> S400 | H102: =IFERROR(VLOOKUP(G102,'물품 입고 내역'!$B$5:$O$1005,14,0)," ") | J102: ='물품 입고 내역'!$B455 -> S450 | K102: =IFERROR(VLOOKUP(J102,'물품 입고 내역'!$B$5:$O$1005,14,0)," ") | M102: ='물품 입고 내역'!$B505 -> S500 | N102: =IFERROR(VLOOKUP(M102,'물품 입고 내역'!$B$5:$O$1005,14,0)," ")
A103: No | B103: Zone | C103: 1 | D103: No | E103: Zone | F103: 1 | G103: No | H103: Zone | I103: 1 | J103: No | K103: Zone | L103: 1 | M103: No | N103: Zone
A104: ='물품 입고 내역'!$B506 -> S501 | B104: =IFERROR(VLOOKUP(A104,'물품 입고 내역'!$B$5:$O$1005,14,0)," ") | D104: ='물품 입고 내역'!$B556 -> S551 | E104: =IFERROR(VLOOKUP(D104,'물품 입고 내역'!$B$5:$O$1005,14,0)," ") | G104: ='물품 입고 내역'!$B606 -> S601 | H104: =IFERROR(VLOOKUP(G104,'물품 입고 내역'!$B$5:$O$1005,14,0)," ") | J104: ='물품 입고 내역'!$B656 -> S651 | K104: =IFERROR(VLOOKUP(J104,'물품 입고 내역'!$B$5:$O$1005,14,0)," ") | M104: ='물품 입고 내역'!$B706 -> S701 | N104: =IFERROR(VLOOKUP(M104,'물품 입고 내역'!$B$5:$O$1005,14,0)," ")
A105: ='물품 입고 내역'!$B507 -> S502 | B105: =IFERROR(VLOOKUP(A105,'물품 입고 내역'!$B$5:$O$1005,14,0)," ") | D105: ='물품 입고 내역'!$B557 -> S552 | E105: =IFERROR(VLOOKUP(D105,'물품 입고 내역'!$B$5:$O$1005,14,0)," ") | G105: ='물품 입고 내역'!$B607 -> S602 | H105: =IFERROR(VLOOKUP(G105,'물품 입고 내역'!$B$5:$O$1005,14,0)," ") | J105: ='물품 입고 내역'!$B657 -> S652 | K105: =IFERROR(VLOOKUP(J105,'물품 입고 내역'!$B$5:$O$1005,14,0)," ") | M105: ='물품 입고 내역'!$B707 -> S702 | N105: =IFERROR(VLOOKUP(M105,'물품 입고 내역'!$B$5:$O$1005,14,0)," ")
A106: ='물품 입고 내역'!$B508 -> S503 | B106: =IFERROR(VLOOKUP(A106,'물품 입고 내역'!$B$5:$O$1005,14,0)," ") | D106: ='물품 입고 내역'!$B558 -> S553 | E106: =IFERROR(VLOOKUP(D106,'물품 입고 내역'!$B$5:$O$1005,14,0)," ") | G106: ='물품 입고 내역'!$B608 -> S603 | H106: =IFERROR(VLOOKUP(G106,'물품 입고 내역'!$B$5:$O$1005,14,0)," ") | J106: ='물품 입고 내역'!$B658 -> S653 | K106: =IFERROR(VLOOKUP(J106,'물품 입고 내역'!$B$5:$O$1005,14,0)," ") | M106: ='물품 입고 내역'!$B708 -> S703 | N106: =IFERROR(VLOOKUP(M106,'물품 입고 내역'!$B$5:$O$1005,14,0)," ")
A107: ='물품 입고 내역'!$B509 -> S504 | B107: =IFERROR(VLOOKUP(A107,'물품 입고 내역'!$B$5:$O$1005,14,0)," ") | D107: ='물품 입고 내역'!$B559 -> S554 | E107: =IFERROR(VLOOKUP(D107,'물품 입고 내역'!$B$5:$O$1005,14,0)," ") | G107: ='물품 입고 내역'!$B609 -> S604 | H107: =IFERROR(VLOOKUP(G107,'물품 입고 내역'!$B$5:$O$1005,14,0)," ") | J107: ='물품 입고 내역'!$B659 -> S654 | K107: =IFERROR(VLOOKUP(J107,'물품 입고 내역'!$B$5:$O$1005,14,0)," ") | M107: ='물품 입고 내역'!$B709 -> S704 | N107: =IFERROR(VLOOKUP(M107,'물품 입고 내역'!$B$5:$O$1005,14,0)," ")
A108: ='물품 입고 내역'!$B510 -> S505 | B108: =IFERROR(VLOOKUP(A108,'물품 입고 내역'!$B$5:$O$1005,14,0)," ") | D108: ='물품 입고 내역'!$B560 -> S555 | E108: =IFERROR(VLOOKUP(D108,'물품 입고 내역'!$B$5:$O$1005,14,0)," ") | G108: ='물품 입고 내역'!$B610 -> S605 | H108: =IFERROR(VLOOKUP(G108,'물품 입고 내역'!$B$5:$O$1005,14,0)," ") | J108: ='물품 입고 내역'!$B660 -> S655 | K108: =IFERROR(VLOOKUP(J108,'물품 입고 내역'!$B$5:$O$1005,14,0)," ") | M108: ='물품 입고 내역'!$B710 -> S705 | N108: =IFERROR(VLOOKUP(M108,'물품 입고 내역'!$B$5:$O$1005,14,0)," ")
A109: ='물품 입고 내역'!$B511 -> S506 | B109: =IFERROR(VLOOKUP(A109,'물품 입고 내역'!$B$5:$O$1005,14,0)," ") | D109: ='물품 입고 내역'!$B561 -> S556 | E109: =IFERROR(VLOOKUP(D109,'물품 입고 내역'!$B$5:$O$1005,14,0)," ") | G109: ='물품 입고 내역'!$B611 -> S606 | H109: =IFERROR(VLOOKUP(G109,'물품 입고 내역'!$B$5:$O$1005,14,0)," ") | J109: ='물품 입고 내역'!$B661 -> S656 | K109: =IFERROR(VLOOKUP(J109,'물품 입고 내역'!$B$5:$O$1005,14,0)," ") | M109: ='물품 입고 내역'!$B711 -> S706 | N109: =IFERROR(VLOOKUP(M109,'물품 입고 내역'!$B$5:$O$1005,14,0)," ")
A110: ='물품 입고 내역'!$B512 -> S507 | B110: =IFERROR(VLOOKUP(A110,'물품 입고 내역'!$B$5:$O$1005,14,0)," ") | D110: ='물품 입고 내역'!$B562 -> S557 | E110: =IFERROR(VLOOKUP(D110,'물품 입고 내역'!$B$5:$O$1005,14,0)," ") | G110: ='물품 입고 내역'!$B612 -> S607 | H110: =IFERROR(VLOOKUP(G110,'물품 입고 내역'!$B$5:$O$1005,14,0)," ") | J110: ='물품 입고 내역'!$B662 -> S657 | K110: =IFERROR(VLOOKUP(J110,'물품 입고 내역'!$B$5:$O$1005,14,0)," ") | M110: ='물품 입고 내역'!$B712 -> S707 | N110: =IFERROR(VLOOKUP(M110,'물품 입고 내역'!$B$5:$O$1005,14,0)," ")
A111: ='물품 입고 내역'!$B513 -> S508 | B111: =IFERROR(VLOOKUP(A111,'물품 입고 내역'!$B$5:$O$1005,14,0)," ") | D111: ='물품 입고 내역'!$B563 -> S558 | E111: =IFERROR(VLOOKUP(D111,'물품 입고 내역'!$B$5:$O$1005,14,0)," ") | G111: ='물품 입고 내역'!$B613 -> S608 | H111: =IFERROR(VLOOKUP(G111,'물품 입고 내역'!$B$5:$O$1005,14,0)," ") | J111: ='물품 입고 내역'!$B663 -> S658 | K111: =IFERROR(VLOOKUP(J111,'물품 입고 내역'!$B$5:$O$1005,14,0)," ") | M111: ='물품 입고 내역'!$B713 -> S708 | N111: =IFERROR(VLOOKUP(M111,'물품 입고 내역'!$B$5:$O$1005,14,0)," ")
A112: ='물품 입고 내역'!$B514 -> S509 | B112: =IFERROR(VLOOKUP(A112,'물품 입고 내역'!$B$5:$O$1005,14,0)," ") | D112: ='물품 입고 내역'!$B564 -> S559 | E112: =IFERROR(VLOOKUP(D112,'물품 입고 내역'!$B$5:$O$1005,14,0)," ") | G112: ='물품 입고 내역'!$B614 -> S609 | H112: =IFERROR(VLOOKUP(G112,'물품 입고 내역'!$B$5:$O$1005,14,0)," ") | J112: ='물품 입고 내역'!$B664 -> S659 | K112: =IFERROR(VLOOKUP(J112,'물품 입고 내역'!$B$5:$O$1005,14,0)," ") | M112: ='물품 입고 내역'!$B714 -> S709 | N112: =IFERROR(VLOOKUP(M112,'물품 입고 내역'!$B$5:$O$1005,14,0)," ")
A113: ='물품 입고 내역'!$B515 -> S510 | B113: =IFERROR(VLOOKUP(A113,'물품 입고 내역'!$B$5:$O$1005,14,0)," ") | D113: ='물품 입고 내역'!$B565 -> S560 | E113: =IFERROR(VLOOKUP(D113,'물품 입고 내역'!$B$5:$O$1005,14,0)," ") | G113: ='물품 입고 내역'!$B615 -> S610 | H113: =IFERROR(VLOOKUP(G113,'물품 입고 내역'!$B$5:$O$1005,14,0)," ") | J113: ='물품 입고 내역'!$B665 -> S660 | K113: =IFERROR(VLOOKUP(J113,'물품 입고 내역'!$B$5:$O$1005,14,0)," ") | M113: ='물품 입고 내역'!$B715 -> S710 | N113: =IFERROR(VLOOKUP(M113,'물품 입고 내역'!$B$5:$O$1005,14,0)," ")
A114: ='물품 입고 내역'!$B516 -> S511 | B114: =IFERROR(VLOOKUP(A114,'물품 입고 내역'!$B$5:$O$1005,14,0)," ") | D114: ='물품 입고 내역'!$B566 -> S561 | E114: =IFERROR(VLOOKUP(D114,'물품 입고 내역'!$B$5:$O$1005,14,0)," ") | G114: ='물품 입고 내역'!$B616 -> S611 | H114: =IFERROR(VLOOKUP(G114,'물품 입고 내역'!$B$5:$O$1005,14,0)," ") | J114: ='물품 입고 내역'!$B666 -> S661 | K114: =IFERROR(VLOOKUP(J114,'물품 입고 내역'!$B$5:$O$1005,14,0)," ") | M114: ='물품 입고 내역'!$B716 -> S711 | N114: =IFERROR(VLOOKUP(M114,'물품 입고 내역'!$B$5:$O$1005,14,0)," ")
...

Sheet 고객 리스트
A1: Kor-Lao Sea xx항차 고객 리스트 (ລາຍການລູກຄ້າຂອງທາງເຮືອ)
A2: 아래 고객님 본인 성함을 찾아 서명해 주시면 직원이 확인 후 출고 진행 도와드립니다.
A3: No. Bill | B3: 이 름 (ຊື່ ແລະ ນາມສະກຸນ) | C3: Area Categorized | D3: Item No. | E3: 서 명(ລາຍເຊັນ) | G3: 1 | H3: 2 | I3: 3 | J3: 4 | K3: 5 | L3: 6 | M3: 7 | N3: 8 | O3: 9 | P3: 10 | Q3: 11 | R3: 12 | S3: 13 | T3: 14 | U3: 15 | V3: 16 | W3: 17 | X3: 18 | Y3: 19 | Z3: 20 | AA3: 21 | AB3: 22 | AC3: 23 | AD3: 24 | AE3: 25 | AF3: 26 | AG3: 27 | AH3: 28 | AI3: 29 | AJ3: 30 | AK3: 31 | AL3: 32 | AM3: 33 | AN3: 34 | AO3: 35 | AP3: 36 | AQ3: 37 | AR3: 38 | AS3: 39 | AT3: 40 | AU3: 41 | AV3: 42 | AW3: 43 | AX3: 44 | AY3: 45 | AZ3: 46 | BA3: 47 | BB3: 48 | BC3: 49 | BD3: 50 | BE3: 51 | BF3: 52 | BG3: 53 | BH3: 54 | BI3: 55 | BJ3: 56 | BK3: 57 | BL3: 58 | BM3: 59 | BN3: 60 | BO3: 61 | BP3: 62 | BQ3: 63 | BR3: 64 | BS3: 65 | BT3: 66 | BU3: 67 | BV3: 68 | BW3: 69 | BX3: 70 | BY3: 71 | BZ3: 72 | CA3: 73 | CB3: 74 | CC3: 75 | CD3: 76 | CE3: 77 | CF3: 78 | CG3: 79 | CH3: 80 | CI3: 81 | CJ3: 82 | CK3: 83 | CL3: 84 | CM3: 85 | CN3: 86 | CO3: 87 | CP3: 88 | CQ3: 89 | CR3: 90 | CS3: 91 | CT3: 92 | CU3: 93 | CV3: 94 | CW3: 95 | CX3: 96 | CY3: 97 | CZ3: 98 | DA3: 99 | DB3: 100 | DC3: 101 | DD3: 102 | DE3: 103 | DF3: 104 | DG3: 105 | DH3: 106 | DI3: 107 | DJ3: 108 | DK3: 109 | DL3: 110
A4: LKS 01 | B4: =IFERROR(INDEX('물품 입고 내역'!$E$6:$O$1005,MATCH($A4,'물품 입고 내역'!$N$6:$N$1005,0),1)," ") | C4: =IFERROR(VLOOKUP(F4,$C$117:$D$120,2,TRUE)," ") | D4: =CONCATENATE(G4," ",H4," ",I4," ",J4," ",K4," ",L4," ",M4," ",N4," ",O4," ",P4," ",Q4," ",R4," ",S4," ",T4," ",U4," ",V4," ",W4," ",X4," ",Y4," ",Z4," ",AA4," ",AB4," ",AC4," ",AD4," ",AE4," ",AF4," ",AG4," ",AH4," ",AI4," ",AJ4," ",AK4," ",AL4," ",AM4," ",AN4," ",AO4," ",AP4," ",AQ4," ",AR4," ",AS4," ",AT4," ",AU4," ",AV4," ",AW4," ",AX4," ",AY4," ",AZ4," ",BA4," ",BB4," ",BC4," ",BD4," ",BE4," ",BF4," ",BG4," ",BH4," ",BI4," ",BJ4," ",BK4," ",BL4," ",BM4," ",BN4," ",BO4," ",BP4," ",BQ4," ",BR4," ",BS4," ",BT4," ",BU4," ",BV4," ",BW4," ",BX4," ",BY4," ",BZ4," ",CA4," ",CB4," ",CC4," ",CD4," ",CE4," ",CF4," ",CG4," ",CH4," ",CI4," ",CJ4," ",CK4," ",CL4," ",CM4," ",CN4," ",CO4," ",CP4," ",CQ4," ",CR4," ",CS4," ",CT4," ",CU4," ",CV4," ",CW4," ",CX4," ",CY4," ",CZ4," ",DA4," ",DB4," ",DC4," ",DD4," ",DE4," ",DF4," ",DG4," ",DH4," ",DI4," ",DJ4," ",DK4," ",DL4) | F4: =COUNTA(G4:DL4)-COUNTBLANK(G4:DL4) -> 0 | G4: =IFERROR(VLOOKUP($A4&"_"&G$3,'물품 입고 내역'!$A$5:$O$1005,2,0),"") | H4: =IFERROR(VLOOKUP($A4&"_"&H$3,'물품 입고 내역'!$A$5:$O$1005,2,0),"") | I4: =IFERROR(VLOOKUP($A4&"_"&I$3,'물품 입고 내역'!$A$5:$O$1005,2,0),"") | J4: =IFERROR(VLOOKUP($A4&"_"&J$3,'물품 입고 내역'!$A$5:$O$1005,2,0),"") | K4: =IFERROR(VLOOKUP($A4&"_"&K$3,'물품 입고 내역'!$A$5:$O$1005,2,0),"") | L4: =IFERROR(VLOOKUP($A4&"_"&L$3,'물품 입고 내역'!$A$5:$O$1005,2,0),"") | M4: =IFERROR(VLOOKUP($A4&"_"&M$3,'물품 입고 내역'!$A$5:$O$1005,2,0),"") | N4: =IFERROR(VLOOKUP($A4&"_"&N$3,'물품 입고 내역'!$A$5:$O$1005,2,0),"") | ... DL4: =IFERROR(VLOOKUP($A4&"_"&DL$3,'물품 입고 내역'!$A$5:$O$1005,2,0),"")
A5: LKS 02 | B5: =IFERROR(INDEX('물품 입고 내역'!$E$6:$O$1005,MATCH($A5,'물품 입고 내역'!$N$6:$N$1005,0),1)," ") | C5: =IFERROR(VLOOKUP(F5,$C$117:$D$120,2,TRUE)," ") | D5: =CONCATENATE(G5," ",H5," ",I5," ",J5," ",K5," ",L5," ",M5," ",N5," ",O5," ",P5," ",Q5," ",R5," ",S5," ",T5," ",U5," ",V5," ",W5," ",X5," ",Y5," ",Z5," ",AA5," ",AB5," ",AC5," ",AD5," ",AE5," ",AF5," ",AG5," ",AH5," ",AI5," ",AJ5," ",AK5," ",AL5," ",AM5," ",AN5," ",AO5," ",AP5," ",AQ5," ",AR5," ",AS5," ",AT5," ",AU5," ",AV5," ",AW5," ",AX5," ",AY5," ",AZ5," ",BA5," ",BB5," ",BC5," ",BD5," ",BE5," ",BF5," ",BG5," ",BH5," ",BI5," ",BJ5," ",BK5," ",BL5," ",BM5," ",BN5," ",BO5," ",BP5," ",BQ5," ",BR5," ",BS5," ",BT5," ",BU5," ",BV5," ",BW5," ",BX5," ",BY5," ",BZ5," ",CA5," ",CB5," ",CC5," ",CD5," ",CE5," ",CF5," ",CG5," ",CH5," ",CI5," ",CJ5," ",CK5," ",CL5," ",CM5," ",CN5," ",CO5," ",CP5," ",CQ5," ",CR5," ",CS5," ",CT5," ",CU5," ",CV5," ",CW5," ",CX5," ",CY5," ",CZ5," ",DA5," ",DB5," ",DC5," ",DD5," ",DE5," ",DF5," ",DG5," ",DH5," ",DI5," ",DJ5," ",DK5," ",DL5) | F5: =COUNTA(G5:DL5)-COUNTBLANK(G5:DL5) -> 0 | G5: =IFERROR(VLOOKUP($A5&"_"&G$3,'물품 입고 내역'!$A$5:$O$1005,2,0),"") | H5: =IFERROR(VLOOKUP($A5&"_"&H$3,'물품 입고 내역'!$A$5:$O$1005,2,0),"") | I5: =IFERROR(VLOOKUP($A5&"_"&I$3,'물품 입고 내역'!$A$5:$O$1005,2,0),"") | J5: =IFERROR(VLOOKUP($A5&"_"&J$3,'물품 입고 내역'!$A$5:$O$1005,2,0),"") | K5: =IFERROR(VLOOKUP($A5&"_"&K$3,'물품 입고 내역'!$A$5:$O$1005,2,0),"") | L5: =IFERROR(VLOOKUP($A5&"_"&L$3,'물품 입고 내역'!$A$5:$O$1005,2,0),"") | M5: =IFERROR(VLOOKUP($A5&"_"&M$3,'물품 입고 내역'!$A$5:$O$1005,2,0),"") | N5: =IFERROR(VLOOKUP($A5&"_"&N$3,'물품 입고 내역'!$A$5:$O$1005,2,0),"") | ... DL5: =IFERROR(VLOOKUP($A5&"_"&DL$3,'물품 입고 내역'!$A$5:$O$1005,2,0),"")
A6: LKS 03 | B6: =IFERROR(INDEX('물품 입고 내역'!$E$6:$O$1005,MATCH($A6,'물품 입고 내역'!$N$6:$N$1005,0),1)," ") | C6: =IFERROR(VLOOKUP(F6,$C$117:$D$120,2,TRUE)," ") | D6: =CONCATENATE(G6," ",H6," ",I6," ",J6," ",K6," ",L6," ",M6," ",N6," ",O6," ",P6," ",Q6," ",R6," ",S6," ",T6," ",U6," ",V6," ",W6," ",X6," ",Y6," ",Z6," ",AA6," ",AB6," ",AC6," ",AD6," ",AE6," ",AF6," ",AG6," ",AH6," ",AI6," ",AJ6," ",AK6," ",AL6," ",AM6," ",AN6," ",AO6," ",AP6," ",AQ6," ",AR6," ",AS6," ",AT6," ",AU6," ",AV6," ",AW6," ",AX6," ",AY6," ",AZ6," ",BA6," ",BB6," ",BC6," ",BD6," ",BE6," ",BF6," ",BG6," ",BH6," ",BI6," ",BJ6," ",BK6," ",BL6," ",BM6," ",BN6," ",BO6," ",BP6," ",BQ6," ",BR6," ",BS6," ",BT6," ",BU6," ",BV6," ",BW6," ",BX6," ",BY6," ",BZ6," ",CA6," ",CB6," ",CC6," ",CD6," ",CE6," ",CF6," ",CG6," ",CH6," ",CI6," ",CJ6," ",CK6," ",CL6," ",CM6," ",CN6," ",CO6," ",CP6," ",CQ6," ",CR6," ",CS6," ",CT6," ",CU6," ",CV6," ",CW6," ",CX6," ",CY6," ",CZ6," ",DA6," ",DB6," ",DC6," ",DD6," ",DE6," ",DF6," ",DG6," ",DH6," ",DI6," ",DJ6," ",DK6," ",DL6) | F6: =COUNTA(G6:DL6)-COUNTBLANK(G6:DL6) -> 0 | G6: =IFERROR(VLOOKUP($A6&"_"&G$3,'물품 입고 내역'!$A$5:$O$1005,2,0),"") | H6: =IFERROR(VLOOKUP($A6&"_"&H$3,'물품 입고 내역'!$A$5:$O$1005,2,0),"") | I6: =IFERROR(VLOOKUP($A6&"_"&I$3,'물품 입고 내역'!$A$5:$O$1005,2,0),"") | J6: =IFERROR(VLOOKUP($A6&"_"&J$3,'물품 입고 내역'!$A$5:$O$1005,2,0),"") | K6: =IFERROR(VLOOKUP($A6&"_"&K$3,'물품 입고 내역'!$A$5:$O$1005,2,0),"") | L6: =IFERROR(VLOOKUP($A6&"_"&L$3,'물품 입고 내역'!$A$5:$O$1005,2,0),"") | M6: =IFERROR(VLOOKUP($A6&"_"&M$3,'물품 입고 내역'!$A$5:$O$1005,2,0),"") | N6: =IFERROR(VLOOKUP($A6&"_"&N$3,'물품 입고 내역'!$A$5:$O$1005,2,0),"") | ... DL6: =IFERROR(VLOOKUP($A6&"_"&DL$3,'물품 입고 내역'!$A$5:$O$1005,2,0),"")
A7: LKS 04 | B7: =IFERROR(INDEX('물품 입고 내역'!$E$6:$O$1005,MATCH($A7,'물품 입고 내역'!$N$6:$N$1005,0),1)," ") | C7: =IFERROR(VLOOKUP(F7,$C$117:$D$120,2,TRUE)," ") | D7: =CONCATENATE(G7," ",H7," ",I7," ",J7," ",K7," ",L7," ",M7," ",N7," ",O7," ",P7," ",Q7," ",R7," ",S7," ",T7," ",U7," ",V7," ",W7," ",X7," ",Y7," ",Z7," ",AA7," ",AB7," ",AC7," ",AD7," ",AE7," ",AF7," ",AG7," ",AH7," ",AI7," ",AJ7," ",AK7," ",AL7," ",AM7," ",AN7," ",AO7," ",AP7," ",AQ7," ",AR7," ",AS7," ",AT7," ",AU7," ",AV7," ",AW7," ",AX7," ",AY7," ",AZ7," ",BA7," ",BB7," ",BC7," ",BD7," ",BE7," ",BF7," ",BG7," ",BH7," ",BI7," ",BJ7," ",BK7," ",BL7," ",BM7," ",BN7," ",BO7," ",BP7," ",BQ7," ",BR7," ",BS7," ",BT7," ",BU7," ",BV7," ",BW7," ",BX7," ",BY7," ",BZ7," ",CA7," ",CB7," ",CC7," ",CD7," ",CE7," ",CF7," ",CG7," ",CH7," ",CI7," ",CJ7," ",CK7," ",CL7," ",CM7," ",CN7," ",CO7," ",CP7," ",CQ7," ",CR7," ",CS7," ",CT7," ",CU7," ",CV7," ",CW7," ",CX7," ",CY7," ",CZ7," ",DA7," ",DB7," ",DC7," ",DD7," ",DE7," ",DF7," ",DG7," ",DH7," ",DI7," ",DJ7," ",DK7," ",DL7) | F7: =COUNTA(G7:DL7)-COUNTBLANK(G7:DL7) -> 0 | G7: =IFERROR(VLOOKUP($A7&"_"&G$3,'물품 입고 내역'!$A$5:$O$1005,2,0),"") | H7: =IFERROR(VLOOKUP($A7&"_"&H$3,'물품 입고 내역'!$A$5:$O$1005,2,0),"") | I7: =IFERROR(VLOOKUP($A7&"_"&I$3,'물품 입고 내역'!$A$5:$O$1005,2,0),"") | J7: =IFERROR(VLOOKUP($A7&"_"&J$3,'물품 입고 내역'!$A$5:$O$1005,2,0),"") | K7: =IFERROR(VLOOKUP($A7&"_"&K$3,'물품 입고 내역'!$A$5:$O$1005,2,0),"") | L7: =IFERROR(VLOOKUP($A7&"_"&L$3,'물품 입고 내역'!$A$5:$O$1005,2,0),"") | M7: =IFERROR(VLOOKUP($A7&"_"&M$3,'물품 입고 내역'!$A$5:$O$1005,2,0),"") | N7: =IFERROR(VLOOKUP($A7&"_"&N$3,'물품 입고 내역'!$A$5:$O$1005,2,0),"") | ... DL7: =IFERROR(VLOOKUP($A7&"_"&DL$3,'물품 입고 내역'!$A$5:$O$1005,2,0),"")
A8: LKS 05 | B8: =IFERROR(INDEX('물품 입고 내역'!$E$6:$O$1005,MATCH($A8,'물품 입고 내역'!$N$6:$N$1005,0),1)," ") | C8: =IFERROR(VLOOKUP(F8,$C$117:$D$120,2,TRUE)," ") | D8: =CONCATENATE(G8," ",H8," ",I8," ",J8," ",K8," ",L8," ",M8," ",N8," ",O8," ",P8," ",Q8," ",R8," ",S8," ",T8," ",U8," ",V8," ",W8," ",X8," ",Y8," ",Z8," ",AA8," ",AB8," ",AC8," ",AD8," ",AE8," ",AF8," ",AG8," ",AH8," ",AI8," ",AJ8," ",AK8," ",AL8," ",AM8," ",AN8," ",AO8," ",AP8," ",AQ8," ",AR8," ",AS8," ",AT8," ",AU8," ",AV8," ",AW8," ",AX8," ",AY8," ",AZ8," ",BA8," ",BB8," ",BC8," ",BD8," ",BE8," ",BF8," ",BG8," ",BH8," ",BI8," ",BJ8," ",BK8," ",BL8," ",BM8," ",BN8," ",BO8," ",BP8," ",BQ8," ",BR8," ",BS8," ",BT8," ",BU8," ",BV8," ",BW8," ",BX8," ",BY8," ",BZ8," ",CA8," ",CB8," ",CC8," ",CD8," ",CE8," ",CF8," ",CG8," ",CH8," ",CI8," ",CJ8," ",CK8," ",CL8," ",CM8," ",CN8," ",CO8," ",CP8," ",CQ8," ",CR8," ",CS8," ",CT8," ",CU8," ",CV8," ",CW8," ",CX8," ",CY8," ",CZ8," ",DA8," ",DB8," ",DC8," ",DD8," ",DE8," ",DF8," ",DG8," ",DH8," ",DI8," ",DJ8," ",DK8," ",DL8) | F8: =COUNTA(G8:DL8)-COUNTBLANK(G8:DL8) -> 0 | G8: =IFERROR(VLOOKUP($A8&"_"&G$3,'물품 입고 내역'!$A$5:$O$1005,2,0),"") | H8: =IFERROR(VLOOKUP($A8&"_"&H$3,'물품 입고 내역'!$A$5:$O$1005,2,0),"") | I8: =IFERROR(VLOOKUP($A8&"_"&I$3,'물품 입고 내역'!$A$5:$O$1005,2,0),"") | J8: =IFERROR(VLOOKUP($A8&"_"&J$3,'물품 입고 내역'!$A$5:$O$1005,2,0),"") | K8: =IFERROR(VLOOKUP($A8&"_"&K$3,'물품 입고 내역'!$A$5:$O$1005,2,0),"") | L8: =IFERROR(VLOOKUP($A8&"_"&L$3,'물품 입고 내역'!$A$5:$O$1005,2,0),"") | M8: =IFERROR(VLOOKUP($A8&"_"&M$3,'물품 입고 내역'!$A$5:$O$1005,2,0),"") | N8: =IFERROR(VLOOKUP($A8&"_"&N$3,'물품 입고 내역'!$A$5:$O$1005,2,0),"") | ... DL8: =IFERROR(VLOOKUP($A8&"_"&DL$3,'물품 입고 내역'!$A$5:$O$1005,2,0),"")
A9: LKS 06 | B9: =IFERROR(INDEX('물품 입고 내역'!$E$6:$O$1005,MATCH($A9,'물품 입고 내역'!$N$6:$N$1005,0),1)," ") | C9: =IFERROR(VLOOKUP(F9,$C$117:$D$120,2,TRUE)," ") | D9: =CONCATENATE(G9," ",H9," ",I9," ",J9," ",K9," ",L9," ",M9," ",N9," ",O9," ",P9," ",Q9," ",R9," ",S9," ",T9," ",U9," ",V9," ",W9," ",X9," ",Y9," ",Z9," ",AA9," ",AB9," ",AC9," ",AD9," ",AE9," ",AF9," ",AG9," ",AH9," ",AI9," ",AJ9," ",AK9," ",AL9," ",AM9," ",AN9," ",AO9," ",AP9," ",AQ9," ",AR9," ",AS9," ",AT9," ",AU9," ",AV9," ",AW9," ",AX9," ",AY9," ",AZ9," ",BA9," ",BB9," ",BC9," ",BD9," ",BE9," ",BF9," ",BG9," ",BH9," ",BI9," ",BJ9," ",BK9," ",BL9," ",BM9," ",BN9," ",BO9," ",BP9," ",BQ9," ",BR9," ",BS9," ",BT9," ",BU9," ",BV9," ",BW9," ",BX9," ",BY9," ",BZ9," ",CA9," ",CB9," ",CC9," ",CD9," ",CE9," ",CF9," ",CG9," ",CH9," ",CI9," ",CJ9," ",CK9," ",CL9," ",CM9," ",CN9," ",CO9," ",CP9," ",CQ9," ",CR9," ",CS9," ",CT9," ",CU9," ",CV9," ",CW9," ",CX9," ",CY9," ",CZ9," ",DA9," ",DB9," ",DC9," ",DD9," ",DE9," ",DF9," ",DG9," ",DH9," ",DI9," ",DJ9," ",DK9," ",DL9) | F9: =COUNTA(G9:DL9)-COUNTBLANK(G9:DL9) -> 0 | G9: =IFERROR(VLOOKUP($A9&"_"&G$3,'물품 입고 내역'!$A$5:$O$1005,2,0),"") | H9: =IFERROR(VLOOKUP($A9&"_"&H$3,'물품 입고 내역'!$A$5:$O$1005,2,0),"") | I9: =IFERROR(VLOOKUP($A9&"_"&I$3,'물품 입고 내역'!$A$5:$O$1005,2,0),"") | J9: =IFERROR(VLOOKUP($A9&"_"&J$3,'물품 입고 내역'!$A$5:$O$1005,2,0),"") | K9: =IFERROR(VLOOKUP($A9&"_"&K$3,'물품 입고 내역'!$A$5:$O$1005,2,0),"") | L9: =IFERROR(VLOOKUP($A9&"_"&L$3,'물품 입고 내역'!$A$5:$O$1005,2,0),"") | M9: =IFERROR(VLOOKUP($A9&"_"&M$3,'물품 입고 내역'!$A$5:$O$1005,2,0),"") | N9: =IFERROR(VLOOKUP($A9&"_"&N$3,'물품 입고 내역'!$A$5:$O$1005,2,0),"") | ... DL9: =IFERROR(VLOOKUP($A9&"_"&DL$3,'물품 입고 내역'!$A$5:$O$1005,2,0),"")
A10: LKS 07 | B10: =IFERROR(INDEX('물품 입고 내역'!$E$6:$O$1005,MATCH($A10,'물품 입고 내역'!$N$6:$N$1005,0),1)," ") | C10: =IFERROR(VLOOKUP(F10,$C$117:$D$120,2,TRUE)," ") | D10: =CONCATENATE(G10," ",H10," ",I10," ",J10," ",K10," ",L10," ",M10," ",N10," ",O10," ",P10," ",Q10," ",R10," ",S10," ",T10," ",U10," ",V10," ",W10," ",X10," ",Y10," ",Z10," ",AA10," ",AB10," ",AC10," ",AD10," ",AE10," ",AF10," ",AG10," ",AH10," ",AI10," ",AJ10," ",AK10," ",AL10," ",AM10," ",AN10," ",AO10," ",AP10," ",AQ10," ",AR10," ",AS10," ",AT10," ",AU10," ",AV10," ",AW10," ",AX10," ",AY10," ",AZ10," ",BA10," ",BB10," ",BC10," ",BD10," ",BE10," ",BF10," ",BG10," ",BH10," ",BI10," ",BJ10," ",BK10," ",BL10," ",BM10," ",BN10," ",BO10," ",BP10," ",BQ10," ",BR10," ",BS10," ",BT10," ",BU10," ",BV10," ",BW10," ",BX10," ",BY10," ",BZ10," ",CA10," ",CB10," ",CC10," ",CD10," ",CE10," ",CF10," ",CG10," ",CH10," ",CI10," ",CJ10," ",CK10," ",CL10," ",CM10," ",CN10," ",CO10," ",CP10," ",CQ10," ",CR10," ",CS10," ",CT10," ",CU10," ",CV10," ",CW10," ",CX10," ",CY10," ",CZ10," ",DA10," ",DB10," ",DC10," ",DD10," ",DE10," ",DF10," ",DG10," ",DH10," ",DI10," ",DJ10," ",DK10," ",DL10) | F10: =COUNTA(G10:DL10)-COUNTBLANK(G10:DL10) -> 0 | G10: =IFERROR(VLOOKUP($A10&"_"&G$3,'물품 입고 내역'!$A$5:$O$1005,2,0),"") | H10: =IFERROR(VLOOKUP($A10&"_"&H$3,'물품 입고 내역'!$A$5:$O$1005,2,0),"") | I10: =IFERROR(VLOOKUP($A10&"_"&I$3,'물품 입고 내역'!$A$5:$O$1005,2,0),"") | J10: =IFERROR(VLOOKUP($A10&"_"&J$3,'물품 입고 내역'!$A$5:$O$1005,2,0),"") | K10: =IFERROR(VLOOKUP($A10&"_"&K$3,'물품 입고 내역'!$A$5:$O$1005,2,0),"") | L10: =IFERROR(VLOOKUP($A10&"_"&L$3,'물품 입고 내역'!$A$5:$O$1005,2,0),"") | M10: =IFERROR(VLOOKUP($A10&"_"&M$3,'물품 입고 내역'!$A$5:$O$1005,2,0),"") | N10: =IFERROR(VLOOKUP($A10&"_"&N$3,'물품 입고 내역'!$A$5:$O$1005,2,0),"") | ... DL10: =IFERROR(VLOOKUP($A10&"_"&DL$3,'물품 입고 내역'!$A$5:$O$1005,2,0),"")
A11: LKS 08 | B11: =IFERROR(INDEX('물품 입고 내역'!$E$6:$O$1005,MATCH($A11,'물품 입고 내역'!$N$6:$N$1005,0),1)," ") | C11: =IFERROR(VLOOKUP(F11,$C$117:$D$120,2,TRUE)," ") | D11: =CONCATENATE(G11," ",H11," ",I11," ",J11," ",K11," ",L11," ",M11," ",N11," ",O11," ",P11," ",Q11," ",R11," ",S11," ",T11," ",U11," ",V11," ",W11," ",X11," ",Y11," ",Z11," ",AA11," ",AB11," ",AC11," ",AD11," ",AE11," ",AF11," ",AG11," ",AH11," ",AI11," ",AJ11," ",AK11," ",AL11," ",AM11," ",AN11," ",AO11," ",AP11," ",AQ11," ",AR11," ",AS11," ",AT11," ",AU11," ",AV11," ",AW11," ",AX11," ",AY11," ",AZ11," ",BA11," ",BB11," ",BC11," ",BD11," ",BE11," ",BF11," ",BG11," ",BH11," ",BI11," ",BJ11," ",BK11," ",BL11," ",BM11," ",BN11," ",BO11," ",BP11," ",BQ11," ",BR11," ",BS11," ",BT11," ",BU11," ",BV11," ",BW11," ",BX11," ",BY11," ",BZ11," ",CA11," ",CB11," ",CC11," ",CD11," ",CE11," ",CF11," ",CG11," ",CH11," ",CI11," ",CJ11," ",CK11," ",CL11," ",CM11," ",CN11," ",CO11," ",CP11," ",CQ11," ",CR11," ",CS11," ",CT11," ",CU11," ",CV11," ",CW11," ",CX11," ",CY11," ",CZ11," ",DA11," ",DB11," ",DC11," ",DD11," ",DE11," ",DF11," ",DG11," ",DH11," ",DI11," ",DJ11," ",DK11," ",DL11) | F11: =COUNTA(G11:DL11)-COUNTBLANK(G11:DL11) -> 0 | G11: =IFERROR(VLOOKUP($A11&"_"&G$3,'물품 입고 내역'!$A$5:$O$1005,2,0),"") | H11: =IFERROR(VLOOKUP($A11&"_"&H$3,'물품 입고 내역'!$A$5:$O$1005,2,0),"") | I11: =IFERROR(VLOOKUP($A11&"_"&I$3,'물품 입고 내역'!$A$5:$O$1005,2,0),"") | J11: =IFERROR(VLOOKUP($A11&"_"&J$3,'물품 입고 내역'!$A$5:$O$1005,2,0),"") | K11: =IFERROR(VLOOKUP($A11&"_"&K$3,'물품 입고 내역'!$A$5:$O$1005,2,0),"") | L11: =IFERROR(VLOOKUP($A11&"_"&L$3,'물품 입고 내역'!$A$5:$O$1005,2,0),"") | M11: =IFERROR(VLOOKUP($A11&"_"&M$3,'물품 입고 내역'!$A$5:$O$1005,2,0),"") | N11: =IFERROR(VLOOKUP($A11&"_"&N$3,'물품 입고 내역'!$A$5:$O$1005,2,0),"") | ... DL11: =IFERROR(VLOOKUP($A11&"_"&DL$3,'물품 입고 내역'!$A$5:$O$1005,2,0),"")
A12: LKS 09 | B12: =IFERROR(INDEX('물품 입고 내역'!$E$6:$O$1005,MATCH($A12,'물품 입고 내역'!$N$6:$N$1005,0),1)," ") | C12: =IFERROR(VLOOKUP(F12,$C$117:$D$120,2,TRUE)," ") | D12: =CONCATENATE(G12," ",H12," ",I12," ",J12," ",K12," ",L12," ",M12," ",N12," ",O12," ",P12," ",Q12," ",R12," ",S12," ",T12," ",U12," ",V12," ",W12," ",X12," ",Y12," ",Z12," ",AA12," ",AB12," ",AC12," ",AD12," ",AE12," ",AF12," ",AG12," ",AH12," ",AI12," ",AJ12," ",AK12," ",AL12," ",AM12," ",AN12," ",AO12," ",AP12," ",AQ12," ",AR12," ",AS12," ",AT12," ",AU12," ",AV12," ",AW12," ",AX12," ",AY12," ",AZ12," ",BA12," ",BB12," ",BC12," ",BD12," ",BE12," ",BF12," ",BG12," ",BH12," ",BI12," ",BJ12," ",BK12," ",BL12," ",BM12," ",BN12," ",BO12," ",BP12," ",BQ12," ",BR12," ",BS12," ",BT12," ",BU12," ",BV12," ",BW12," ",BX12," ",BY12," ",BZ12," ",CA12," ",CB12," ",CC12," ",CD12," ",CE12," ",CF12," ",CG12," ",CH12," ",CI12," ",CJ12," ",CK12," ",CL12," ",CM12," ",CN12," ",CO12," ",CP12," ",CQ12," ",CR12," ",CS12," ",CT12," ",CU12," ",CV12," ",CW12," ",CX12," ",CY12," ",CZ12," ",DA12," ",DB12," ",DC12," ",DD12," ",DE12," ",DF12," ",DG12," ",DH12," ",DI12," ",DJ12," ",DK12," ",DL12) | F12: =COUNTA(G12:DL12)-COUNTBLANK(G12:DL12) -> 0 | G12: =IFERROR(VLOOKUP($A12&"_"&G$3,'물품 입고 내역'!$A$5:$O$1005,2,0),"") | H12: =IFERROR(VLOOKUP($A12&"_"&H$3,'물품 입고 내역'!$A$5:$O$1005,2,0),"") | I12: =IFERROR(VLOOKUP($A12&"_"&I$3,'물품 입고 내역'!$A$5:$O$1005,2,0),"") | J12: =IFERROR(VLOOKUP($A12&"_"&J$3,'물품 입고 내역'!$A$5:$O$1005,2,0),"") | K12: =IFERROR(VLOOKUP($A12&"_"&K$3,'물품 입고 내역'!$A$5:$O$1005,2,0),"") | L12: =IFERROR(VLOOKUP($A12&"_"&L$3,'물품 입고 내역'!$A$5:$O$1005,2,0),"") | M12: =IFERROR(VLOOKUP($A12&"_"&M$3,'물품 입고 내역'!$A$5:$O$1005,2,0),"") | N12: =IFERROR(VLOOKUP($A12&"_"&N$3,'물품 입고 내역'!$A$5:$O$1005,2,0),"") | ... DL12: =IFERROR(VLOOKUP($A12&"_"&DL$3,'물품 입고 내역'!$A$5:$O$1005,2,0),"")
A13: LKS 10 | B13: =IFERROR(INDEX('물품 입고 내역'!$E$6:$O$1005,MATCH($A13,'물품 입고 내역'!$N$6:$N$1005,0),1)," ") | C13: =IFERROR(VLOOKUP(F13,$C$117:$D$120,2,TRUE)," ") | D13: =CONCATENATE(G13," ",H13," ",I13," ",J13," ",K13," ",L13," ",M13," ",N13," ",O13," ",P13," ",Q13," ",R13," ",S13," ",T13," ",U13," ",V13," ",W13," ",X13," ",Y13," ",Z13," ",AA13," ",AB13," ",AC13," ",AD13," ",AE13," ",AF13," ",AG13," ",AH13," ",AI13," ",AJ13," ",AK13," ",AL13," ",AM13," ",AN13," ",AO13," ",AP13," ",AQ13," ",AR13," ",AS13," ",AT13," ",AU13," ",AV13," ",AW13," ",AX13," ",AY13," ",AZ13," ",BA13," ",BB13," ",BC13," ",BD13," ",BE13," ",BF13," ",BG13," ",BH13," ",BI13," ",BJ13," ",BK13," ",BL13," ",BM13," ",BN13," ",BO13," ",BP13," ",BQ13," ",BR13," ",BS13," ",BT13," ",BU13," ",BV13," ",BW13," ",BX13," ",BY13," ",BZ13," ",CA13," ",CB13," ",CC13," ",CD13," ",CE13," ",CF13," ",CG13," ",CH13," ",CI13," ",CJ13," ",CK13," ",CL13," ",CM13," ",CN13," ",CO13," ",CP13," ",CQ13," ",CR13," ",CS13," ",CT13," ",CU13," ",CV13," ",CW13," ",CX13," ",CY13," ",CZ13," ",DA13," ",DB13," ",DC13," ",DD13," ",DE13," ",DF13," ",DG13," ",DH13," ",DI13," ",DJ13," ",DK13," ",DL13) | F13: =COUNTA(G13:DL13)-COUNTBLANK(G13:DL13) -> 0 | G13: =IFERROR(VLOOKUP($A13&"_"&G$3,'물품 입고 내역'!$A$5:$O$1005,2,0),"") | H13: =IFERROR(VLOOKUP($A13&"_"&H$3,'물품 입고 내역'!$A$5:$O$1005,2,0),"") | I13: =IFERROR(VLOOKUP($A13&"_"&I$3,'물품 입고 내역'!$A$5:$O$1005,2,0),"") | J13: =IFERROR(VLOOKUP($A13&"_"&J$3,'물품 입고 내역'!$A$5:$O$1005,2,0),"") | K13: =IFERROR(VLOOKUP($A13&"_"&K$3,'물품 입고 내역'!$A$5:$O$1005,2,0),"") | L13: =IFERROR(VLOOKUP($A13&"_"&L$3,'물품 입고 내역'!$A$5:$O$1005,2,0),"") | M13: =IFERROR(VLOOKUP($A13&"_"&M$3,'물품 입고 내역'!$A$5:$O$1005,2,0),"") | N13: =IFERROR(VLOOKUP($A13&"_"&N$3,'물품 입고 내역'!$A$5:$O$1005,2,0),"") | ... DL13: =IFERROR(VLOOKUP($A13&"_"&DL$3,'물품 입고 내역'!$A$5:$O$1005,2,0),"")
A14: LKS 11 | B14: =IFERROR(INDEX('물품 입고 내역'!$E$6:$O$1005,MATCH($A14,'물품 입고 내역'!$N$6:$N$1005,0),1)," ") | C14: =IFERROR(VLOOKUP(F14,$C$117:$D$120,2,TRUE)," ") | D14: =CONCATENATE(G14," ",H14," ",I14," ",J14," ",K14," ",L14," ",M14," ",N14," ",O14," ",P14," ",Q14," ",R14," ",S14," ",T14," ",U14," ",V14," ",W14," ",X14," ",Y14," ",Z14," ",AA14," ",AB14," ",AC14," ",AD14," ",AE14," ",AF14," ",AG14," ",AH14," ",AI14," ",AJ14," ",AK14," ",AL14," ",AM14," ",AN14," ",AO14," ",AP14," ",AQ14," ",AR14," ",AS14," ",AT14," ",AU14," ",AV14," ",AW14," ",AX14," ",AY14," ",AZ14," ",BA14," ",BB14," ",BC14," ",BD14," ",BE14," ",BF14," ",BG14," ",BH14," ",BI14," ",BJ14," ",BK14," ",BL14," ",BM14," ",BN14," ",BO14," ",BP14," ",BQ14," ",BR14," ",BS14," ",BT14," ",BU14," ",BV14," ",BW14," ",BX14," ",BY14," ",BZ14," ",CA14," ",CB14," ",CC14," ",CD14," ",CE14," ",CF14," ",CG14," ",CH14," ",CI14," ",CJ14," ",CK14," ",CL14," ",CM14," ",CN14," ",CO14," ",CP14," ",CQ14," ",CR14," ",CS14," ",CT14," ",CU14," ",CV14," ",CW14," ",CX14," ",CY14," ",CZ14," ",DA14," ",DB14," ",DC14," ",DD14," ",DE14," ",DF14," ",DG14," ",DH14," ",DI14," ",DJ14," ",DK14," ",DL14) | F14: =COUNTA(G14:DL14)-COUNTBLANK(G14:DL14) -> 0 | G14: =IFERROR(VLOOKUP($A14&"_"&G$3,'물품 입고 내역'!$A$5:$O$1005,2,0),"") | H14: =IFERROR(VLOOKUP($A14&"_"&H$3,'물품 입고 내역'!$A$5:$O$1005,2,0),"") | I14: =IFERROR(VLOOKUP($A14&"_"&I$3,'물품 입고 내역'!$A$5:$O$1005,2,0),"") | J14: =IFERROR(VLOOKUP($A14&"_"&J$3,'물품 입고 내역'!$A$5:$O$1005,2,0),"") | K14: =IFERROR(VLOOKUP($A14&"_"&K$3,'물품 입고 내역'!$A$5:$O$1005,2,0),"") | L14: =IFERROR(VLOOKUP($A14&"_"&L$3,'물품 입고 내역'!$A$5:$O$1005,2,0),"") | M14: =IFERROR(VLOOKUP($A14&"_"&M$3,'물품 입고 내역'!$A$5:$O$1005,2,0),"") | N14: =IFERROR(VLOOKUP($A14&"_"&N$3,'물품 입고 내역'!$A$5:$O$1005,2,0),"") | ... DL14: =IFERROR(VLOOKUP($A14&"_"&DL$3,'물품 입고 내역'!$A$5:$O$1005,2,0),"")
A15: LKS 12 | B15: =IFERROR(INDEX('물품 입고 내역'!$E$6:$O$1005,MATCH($A15,'물품 입고 내역'!$N$6:$N$1005,0),1)," ") | C15: =IFERROR(VLOOKUP(F15,$C$117:$D$120,2,TRUE)," ") | D15: =CONCATENATE(G15," ",H15," ",I15," ",J15," ",K15," ",L15," ",M15," ",N15," ",O15," ",P15," ",Q15," ",R15," ",S15," ",T15," ",U15," ",V15," ",W15," ",X15," ",Y15," ",Z15," ",AA15," ",AB15," ",AC15," ",AD15," ",AE15," ",AF15," ",AG15," ",AH15," ",AI15," ",AJ15," ",AK15," ",AL15," ",AM15," ",AN15," ",AO15," ",AP15," ",AQ15," ",AR15," ",AS15," ",AT15," ",AU15," ",AV15," ",AW15," ",AX15," ",AY15," ",AZ15," ",BA15," ",BB15," ",BC15," ",BD15," ",BE15," ",BF15," ",BG15," ",BH15," ",BI15," ",BJ15," ",BK15," ",BL15," ",BM15," ",BN15," ",BO15," ",BP15," ",BQ15," ",BR15," ",BS15," ",BT15," ",BU15," ",BV15," ",BW15," ",BX15," ",BY15," ",BZ15," ",CA15," ",CB15," ",CC15," ",CD15," ",CE15," ",CF15," ",CG15," ",CH15," ",CI15," ",CJ15," ",CK15," ",CL15," ",CM15," ",CN15," ",CO15," ",CP15," ",CQ15," ",CR15," ",CS15," ",CT15," ",CU15," ",CV15," ",CW15," ",CX15," ",CY15," ",CZ15," ",DA15," ",DB15," ",DC15," ",DD15," ",DE15," ",DF15," ",DG15," ",DH15," ",DI15," ",DJ15," ",DK15," ",DL15) | F15: =COUNTA(G15:DL15)-COUNTBLANK(G15:DL15) -> 0 | G15: =IFERROR(VLOOKUP($A15&"_"&G$3,'물품 입고 내역'!$A$5:$O$1005,2,0),"") | H15: =IFERROR(VLOOKUP($A15&"_"&H$3,'물품 입고 내역'!$A$5:$O$1005,2,0),"") | I15: =IFERROR(VLOOKUP($A15&"_"&I$3,'물품 입고 내역'!$A$5:$O$1005,2,0),"") | J15: =IFERROR(VLOOKUP($A15&"_"&J$3,'물품 입고 내역'!$A$5:$O$1005,2,0),"") | K15: =IFERROR(VLOOKUP($A15&"_"&K$3,'물품 입고 내역'!$A$5:$O$1005,2,0),"") | L15: =IFERROR(VLOOKUP($A15&"_"&L$3,'물품 입고 내역'!$A$5:$O$1005,2,0),"") | M15: =IFERROR(VLOOKUP($A15&"_"&M$3,'물품 입고 내역'!$A$5:$O$1005,2,0),"") | N15: =IFERROR(VLOOKUP($A15&"_"&N$3,'물품 입고 내역'!$A$5:$O$1005,2,0),"") | ... DL15: =IFERROR(VLOOKUP($A15&"_"&DL$3,'물품 입고 내역'!$A$5:$O$1005,2,0),"")
... A114: LKS xx | B114: =IFERROR(INDEX('물품 입고 내역'!$E$6:$O$1005,MATCH($A114,'물품 입고 내역'!$N$6:$N$1005,0),1)," ") | C114: =IFERROR(VLOOKUP(F114,$C$117:$D$120,2,TRUE)," ") | D114: =CONCATENATE(G114," ",H114," ",I114," ",J114," ",K114," ",L114," ",M114," ",N114," ",O114," ",P114," ",Q114," ",R114," ",S114," ",T114," ",U114," ",V114," ",W114," ",X114," ",Y114," ",Z114," ",AA114," ",AB114," ",AC114," ",AD114," ",AE114," ",AF114," ",AG114," ",AH114," ",AI114," ",AJ114," ",AK114," ",AL114," ",AM114," ",AN114," ",AO114," ",AP114," ",AQ114," ",AR114," ",AS114," ",AT114," ",AU114," ",AV114," ",AW114," ",AX114," ",AY114," ",AZ114," ",BA114," ",BB114," ",BC114," ",BD114," ",BE114," ",BF114," ",BG114," ",BH114," ",BI114," ",BJ114," ",BK114," ",BL114," ",BM114," ",BN114," ",BO114," ",BP114," ",BQ114," ",BR114," ",BS114," ",BT114," ",BU114," ",BV114," ",BW114," ",BX114," ",BY114," ",BZ114," ",CA114," ",CB114," ",CC114," ",CD114," ",CE114," ",CF114," ",CG114," ",CH114," ",CI114," ",CJ114," ",CK114," ",CL114," ",CM114," ",CN114," ",CO114," ",CP114," ",CQ114," ",CR114," ",CS114," ",CT114," ",CU114," ",CV114," ",CW114," ",CX114," ",CY114," ",CZ114," ",DA114," ",DB114," ",DC114," ",DD114," ",DE114," ",DF114," ",DG114," ",DH114," ",DI114," ",DJ114," ",DK114," ",DL114) | F114: =COUNTA(G114:DL114)-COUNTBLANK(G114:DL114) -> 0 | G114: =IFERROR(VLOOKUP($A114&"_"&G$3,'물품 입고 내역'!$A$5:$O$1005,2,0),"") | H114: =IFERROR(VLOOKUP($A114&"_"&H$3,'물품 입고 내역'!$A$5:$O$1005,2,0),"") | I114: =IFERROR(VLOOKUP($A114&"_"&I$3,'물품 입고 내역'!$A$5:$O$1005,2,0),"") | J114: =IFERROR(VLOOKUP($A114&"_"&J$3,'물품 입고 내역'!$A$5:$O$1005,2,0),"") | K114: =IFERROR(VLOOKUP($A114&"_"&K$3,'물품 입고 내역'!$A$5:$O$1005,2,0),"") | L114: =IFERROR(VLOOKUP($A114&"_"&L$3,'물품 입고 내역'!$A$5:$O$1005,2,0),"") | M114: =IFERROR(VLOOKUP($A114&"_"&M$3,'물품 입고 내역'!$A$5:$O$1005,2,0),"") | N114: =IFERROR(VLOOKUP($A114&"_"&N$3,'물품 입고 내역'!$A$5:$O$1005,2,0),"") | ... DL114: =IFERROR(VLOOKUP($A114&"_"&DL$3,'물품 입고 내역'!$A$5:$O$1005,2,0),"")
F115: =SUM(SUM(F4:F114)) -> 0
B116: 물품 개수 | C116: 최소값 | D116: 구획 Zone
B117: 1~4 | C117: 1 | D117: A
B118: 5~9 | C118: 5 | D118: B
B119: 10~19 | C119: 10 | D119: C
B120: 20~ | C120: 20 | D120: F
B121: 분류 고객 | C121: 박성호 대표 | D121: 102
C122: 정석진 | D122: 102
C123: 이동현 | D123: 102
C124: 정민주 | D124: 102
B125: =IF(INDEX($C$117:$D$134,MATCH(B114,$C$117:$C$134,0),2),IF(VLOOKUP(F114,$C$117:$D$134,2,TRUE),0),0) -> #N/A | C125: 박상욱 | D125: 102
B126: =INDEX($C$121:$D$134,MATCH(B114,$C$121:$C$134,0),2) -> #N/A | D126: 102
C127: 임홍식 | D127: 102
C128: 진정우 | D128: 102
C129: 최현석 | D129: 102

Sheet LKS 01
C1: Kor-Lao Sea xxth 거래 명세서 | L1: 구획(Zone) | M1: =IFERROR(INDEX('고객 리스트'!$A$4:$D$150,MATCH(N2,'고객 리스트'!$A$4:$A$150,0),3)," ") | R1: =D16 -> 0 | T1: 화폐 | U1: 기준 환율 | V1: 추가 환율 | W1: 적용 환율
A2: 회사명 | B2: 엘케이(LK)무역 | D2: 도착일 | E2: 2026-XX-XX | I2: 고객명/회사명 // 영수 번호 | L2: =IFERROR(INDEX('고객 리스트'!$A$4:$D$150,MATCH(N2,'고객 리스트'!$A$4:$A$150,0),2)," ") | N2: =MID(CELL("filename",A1),FIND("]",CELL("filename",A1))+1,255) -> LKS 01 | R2: =N21 -> 0 | T2: USD-KIP | U2: ='Row data'!C3 -> 23000 | V2: 1000 | W2: =U2+V2 -> 24000
A3: 회사 주소 | B3: 비엔티엔시, 씨싿따낙구, 싸판텅 느아 09, 11번 골목, 엘케이(LK) 빌딩, 1층 LK Trading | T3: USD-THB | U3: ='Row data'!C4 -> 34 | V3: 1 | W3: =U3+V3 -> 35
A4: 전화번호 | B4: 020-9112-6780 | I4: 고객 연락처/회사 연락처 | L4: =IFERROR(VLOOKUP($N$2&"_"&$A$6,'물품 입고 내역'!$A$5:$O$1005,6,0)," ") | T4: USD-WON | U4: ='Row data'!C5 -> 1545 | V4: 30 | W4: =U4+V4 -> 1575
A5: No. | B5: 종류 | C5: 단가 | D5: 수량 | E5: 실제중량(Kg) | F5: 실제중량 합산(kg) | G5: 규격 (cm) | J5: 용적 중량(kg) | K5: 용적중량 합산(Kg) | L5: 실제중량 운임 | M5: 용적중량 운임 | N5: 청구중량 운임
A6: 1 | B6: =IFERROR(VLOOKUP($N$2&"_"&$A6,'물품 입고 내역'!$A$5:$O$1005,2,0)," ") | C6: =IF(" "=D6," ",IF(0<D6,1.5)) | D6: =IFERROR(VLOOKUP($N$2&"_"&$A6,'물품 입고 내역'!$A$5:$O$1005,9,0)," ") | E6: =IFERROR(INDEX('물품 입고 내역'!$B$5:$M$1005,MATCH($B6,'물품 입고 내역'!$B$5:$B$1005,0),9)," ") | F6: =IFERROR(D6*E6," ") | G6: =IFERROR(INDEX('물품 입고 내역'!$B$5:$M$1005,MATCH($B6,'물품 입고 내역'!$B$5:$B$1005,0),10)," ") | H6: =IFERROR(INDEX('물품 입고 내역'!$B$5:$M$1005,MATCH($B6,'물품 입고 내역'!$B$5:$B$1005,0),11)," ") | I6: =IFERROR(INDEX('물품 입고 내역'!$B$5:$M$1005,MATCH($B6,'물품 입고 내역'!$B$5:$B$1005,0),12)," ") | J6: =IFERROR((G6*H6*I6)*0.00022," ") | K6: =IFERROR(J6*D6," ") | L6: =IFERROR((IF(0=F6*C6,0,IF(1.5>=C6*F6,1.5,C6*F6)))," ") | M6: =IFERROR((IF(0=K6*C6,0,IF(1.5>=K6*C6,1.5,K6*C6)))," ") | N6: =MAX(L6:M6) -> 0
A7: 2 | B7: =IFERROR(VLOOKUP($N$2&"_"&$A7,'물품 입고 내역'!$A$5:$O$1005,2,0)," ") | C7: =IF(" "=D7," ",IF(0<D7,1.5)) | D7: =IFERROR(VLOOKUP($N$2&"_"&$A7,'물품 입고 내역'!$A$5:$O$1005,9,0)," ") | E7: =IFERROR(INDEX('물품 입고 내역'!$B$5:$M$1005,MATCH($B7,'물품 입고 내역'!$B$5:$B$1005,0),9)," ") | F7: =IFERROR(D7*E7," ") | G7: =IFERROR(INDEX('물품 입고 내역'!$B$5:$M$1005,MATCH($B7,'물품 입고 내역'!$B$5:$B$1005,0),10)," ") | H7: =IFERROR(INDEX('물품 입고 내역'!$B$5:$M$1005,MATCH($B7,'물품 입고 내역'!$B$5:$B$1005,0),11)," ") | I7: =IFERROR(INDEX('물품 입고 내역'!$B$5:$M$1005,MATCH($B7,'물품 입고 내역'!$B$5:$B$1005,0),12)," ") | J7: =IFERROR((G7*H7*I7)*0.00022," ") | K7: =IFERROR(J7*D7," ") | L7: =IFERROR((IF(0=F7*C7,0,IF(1.5>=C7*F7,1.5,C7*F7)))," ") | M7: =IFERROR((IF(0=K7*C7,0,IF(1.5>=K7*C7,1.5,K7*C7)))," ") | N7: =MAX(L7:M7) -> 0
A8: 3 | B8: =IFERROR(VLOOKUP($N$2&"_"&$A8,'물품 입고 내역'!$A$5:$O$1005,2,0)," ") | C8: =IF(" "=D8," ",IF(0<D8,1.5)) | D8: =IFERROR(VLOOKUP($N$2&"_"&$A8,'물품 입고 내역'!$A$5:$O$1005,9,0)," ") | E8: =IFERROR(INDEX('물품 입고 내역'!$B$5:$M$1005,MATCH($B8,'물품 입고 내역'!$B$5:$B$1005,0),9)," ") | F8: =IFERROR(D8*E8," ") | G8: =IFERROR(INDEX('물품 입고 내역'!$B$5:$M$1005,MATCH($B8,'물품 입고 내역'!$B$5:$B$1005,0),10)," ") | H8: =IFERROR(INDEX('물품 입고 내역'!$B$5:$M$1005,MATCH($B8,'물품 입고 내역'!$B$5:$B$1005,0),11)," ") | I8: =IFERROR(INDEX('물품 입고 내역'!$B$5:$M$1005,MATCH($B8,'물품 입고 내역'!$B$5:$B$1005,0),12)," ") | J8: =IFERROR((G8*H8*I8)*0.00022," ") | K8: =IFERROR(J8*D8," ") | L8: =IFERROR((IF(0=F8*C8,0,IF(1.5>=C8*F8,1.5,C8*F8)))," ") | M8: =IFERROR((IF(0=K8*C8,0,IF(1.5>=K8*C8,1.5,K8*C8)))," ") | N8: =MAX(L8:M8) -> 0
A9: 4 | B9: =IFERROR(VLOOKUP($N$2&"_"&$A9,'물품 입고 내역'!$A$5:$O$1005,2,0)," ") | C9: =IF(" "=D9," ",IF(0<D9,1.5)) | D9: =IFERROR(VLOOKUP($N$2&"_"&$A9,'물품 입고 내역'!$A$5:$O$1005,9,0)," ") | E9: =IFERROR(INDEX('물품 입고 내역'!$B$5:$M$1005,MATCH($B9,'물품 입고 내역'!$B$5:$B$1005,0),9)," ") | F9: =IFERROR(D9*E9," ") | G9: =IFERROR(INDEX('물품 입고 내역'!$B$5:$M$1005,MATCH($B9,'물품 입고 내역'!$B$5:$B$1005,0),10)," ") | H9: =IFERROR(INDEX('물품 입고 내역'!$B$5:$M$1005,MATCH($B9,'물품 입고 내역'!$B$5:$B$1005,0),11)," ") | I9: =IFERROR(INDEX('물품 입고 내역'!$B$5:$M$1005,MATCH($B9,'물품 입고 내역'!$B$5:$B$1005,0),12)," ") | J9: =IFERROR((G9*H9*I9)*0.00022," ") | K9: =IFERROR(J9*D9," ") | L9: =IFERROR((IF(0=F9*C9,0,IF(1.5>=C9*F9,1.5,C9*F9)))," ") | M9: =IFERROR((IF(0=K9*C9,0,IF(1.5>=K9*C9,1.5,K9*C9)))," ") | N9: =MAX(L9:M9) -> 0
A10: 5 | B10: =IFERROR(VLOOKUP($N$2&"_"&$A10,'물품 입고 내역'!$A$5:$O$1005,2,0)," ") | C10: =IF(" "=D10," ",IF(0<D10,1.5)) | D10: =IFERROR(VLOOKUP($N$2&"_"&$A10,'물품 입고 내역'!$A$5:$O$1005,9,0)," ") | E10: =IFERROR(INDEX('물품 입고 내역'!$B$5:$M$1005,MATCH($B10,'물품 입고 내역'!$B$5:$B$1005,0),9)," ") | F10: =IFERROR(D10*E10," ") | G10: =IFERROR(INDEX('물품 입고 내역'!$B$5:$M$1005,MATCH($B10,'물품 입고 내역'!$B$5:$B$1005,0),10)," ") | H10: =IFERROR(INDEX('물품 입고 내역'!$B$5:$M$1005,MATCH($B10,'물품 입고 내역'!$B$5:$B$1005,0),11)," ") | I10: =IFERROR(INDEX('물품 입고 내역'!$B$5:$M$1005,MATCH($B10,'물품 입고 내역'!$B$5:$B$1005,0),12)," ") | J10: =IFERROR((G10*H10*I10)*0.00022," ") | K10: =IFERROR(J10*D10," ") | L10: =IFERROR((IF(0=F10*C10,0,IF(1.5>=C10*F10,1.5,C10*F10)))," ") | M10: =IFERROR((IF(0=K10*C10,0,IF(1.5>=K10*C10,1.5,K10*C10)))," ") | N10: =MAX(L10:M10) -> 0
A11: 6 | B11: =IFERROR(VLOOKUP($N$2&"_"&$A11,'물품 입고 내역'!$A$5:$O$1005,2,0)," ") | C11: =IF(" "=D11," ",IF(0<D11,1.5)) | D11: =IFERROR(VLOOKUP($N$2&"_"&$A11,'물품 입고 내역'!$A$5:$O$1005,9,0)," ") | E11: =IFERROR(INDEX('물품 입고 내역'!$B$5:$M$1005,MATCH($B11,'물품 입고 내역'!$B$5:$B$1005,0),9)," ") | F11: =IFERROR(D11*E11," ") | G11: =IFERROR(INDEX('물품 입고 내역'!$B$5:$M$1005,MATCH($B11,'물품 입고 내역'!$B$5:$B$1005,0),10)," ") | H11: =IFERROR(INDEX('물품 입고 내역'!$B$5:$M$1005,MATCH($B11,'물품 입고 내역'!$B$5:$B$1005,0),11)," ") | I11: =IFERROR(INDEX('물품 입고 내역'!$B$5:$M$1005,MATCH($B11,'물품 입고 내역'!$B$5:$B$1005,0),12)," ") | J11: =IFERROR((G11*H11*I11)*0.00022," ") | K11: =IFERROR(J11*D11," ") | L11: =IFERROR((IF(0=F11*C11,0,IF(1.5>=C11*F11,1.5,C11*F11)))," ") | M11: =IFERROR((IF(0=K11*C11,0,IF(1.5>=K11*C11,1.5,K11*C11)))," ") | N11: =MAX(L11:M11) -> 0
A12: 7 | B12: =IFERROR(VLOOKUP($N$2&"_"&$A12,'물품 입고 내역'!$A$5:$O$1005,2,0)," ") | C12: =IF(" "=D12," ",IF(0<D12,1.5)) | D12: =IFERROR(VLOOKUP($N$2&"_"&$A12,'물품 입고 내역'!$A$5:$O$1005,9,0)," ") | E12: =IFERROR(INDEX('물품 입고 내역'!$B$5:$M$1005,MATCH($B12,'물품 입고 내역'!$B$5:$B$1005,0),9)," ") | F12: =IFERROR(D12*E12," ") | G12: =IFERROR(INDEX('물품 입고 내역'!$B$5:$M$1005,MATCH($B12,'물품 입고 내역'!$B$5:$B$1005,0),10)," ") | H12: =IFERROR(INDEX('물품 입고 내역'!$B$5:$M$1005,MATCH($B12,'물품 입고 내역'!$B$5:$B$1005,0),11)," ") | I12: =IFERROR(INDEX('물품 입고 내역'!$B$5:$M$1005,MATCH($B12,'물품 입고 내역'!$B$5:$B$1005,0),12)," ") | J12: =IFERROR((G12*H12*I12)*0.00022," ") | K12: =IFERROR(J12*D12," ") | L12: =IFERROR((IF(0=F12*C12,0,IF(1.5>=C12*F12,1.5,C12*F12)))," ") | M12: =IFERROR((IF(0=K12*C12,0,IF(1.5>=K12*C12,1.5,K12*C12)))," ") | N12: =MAX(L12:M12) -> 0
