Workbook

Sheet Row data
B1: LK내부 환율 | H1: 할인 적용 목록
B2: 화폐 | C2: 기준 환율 | D2: 추가 환율 | E2: 적용 환율
B3: USD-KIP | C3: 23000 | D3: 1000 | E3: =C3+D3 -> 24000 | H3: 라선협 할인 | N3: 지상사협의회 회원사 할인 | U3: 대표님 지인 할인
B4: USD-THB | C4: 33 | D4: 1 | E4: =C4+D4 -> 34 | H4: 해상 | J4: 항공 | N4: 해상 | P4: 항공 | U4: 해상 | W4: 항공
B5: USD-WON | C5: 1515 | D5: 30 | E5: =C5+D5 -> 1545 | H5: 일반 | I5: 기부 | J5: 일반 | K5: 기부 | N5: 일반 | O5: 기부 | P5: 일반 | Q5: 기부 | U5: 일반 | V5: 기부 | W5: 일반 | X5: 기부
H6: 0.2 | I6: 0.3 | J6: 0.05 | K6: 0.1 | N6: 0.2 | O6: 0.3 | P6: 0.05 | Q6: 0.1 | U6: 5~10% | V6: 0.2 | W6: 0.05 | X6: 0.1
B8: 한국 세금 계산서 발급시 계좌번호 | H8: 이름 | J8: 할인율 | K8: 할인금액 | L8: 비 고 | N8: 이름 | P8: 회사 | Q8: 할인율 | R8: 할인금액 | S8: 비 고 | U8: 이름 | W8: 할인율 | X8: 할인금액 | Y8: 비 고
B9: 경남은행 2070133424601 박성호(엘케이무역) | H9: 강병준 | J9: 0.05 | N9: 강병수 | O9: 법인장 | P9: PNPC | Q9: 0.05 | U9: 김인섭 | V9: 요정 투어 (김요셉 형) | W9: 0.05
H10: 강성애 | J10: 0.05 | N10: 고영태 | O10: 부이사장 | P10: 라오스증권거래소 | Q10: 0.05 | U10: 서정진(서이사님) | W10: 0.05
B11: 일반 입금 | H11: 김민기 | J11: 0.05 | N11: 고중하 | O11: 대표 | P11: 젤라콘 | Q11: 0.05 | U11: 이형준 | V11: 골재 판매 | W11: 0.05
B12: 경남은행 571-22-0330221 박성호 | H12: 김재양/김반석 | I12: EZRA | J12: 0.05 | N12: 한조운 | O12: 법인장 | P12: DGB 라오 리싱 | Q12: 0.05 | U12: 임홍식 | W12: 0.05
H13: 김세진 | J13: 0.05 | N13: 김지운 | O13: 법인장 | P13: BNK 캐피탈 라오스 | Q13: 0.05 | U13: 정석진 | W13: 0.05
B14: 한국-라오스 항공 xx항차 | H14: 김양현 | J14: 0.05 | N14: 고현식 | O14: 법인장 | P14: BNK 소액대출 MFI | Q14: 0.05 | U14: 진정우 | V14: 105호 고객 | W14: 0.1 | Y14: 기부
B15: Total | C15: =SUM('LKA 01'!R1) -> 1 | H15: 김영진 | J15: 0.05 | N15: 김일재 | O15: 법인장 | P15: 흥화라오스 | Q15: 0.05 | U15: 최성식 | V15: 큐빅 바이크 | W15: 0.05
B16: Amount | C16: =SUM('LKA 01'!R2) -> 147.84 | H16: 김재광 | J16: 0.05 | N16: 박성호 | O16: 대표 | P16: LK Group | Q16: 0.05 | U16: 최재혁 | W16: 0.05
H17: 김종한 | J17: 0.05 | N17: 백지원 | O17: 센터장 | P17: 라오스 EPS센터 | Q17: 0.05 | U17: 최지호 | W17: 0.05
B18: 총 할인 금액 | C18: =K66+R46+X21+X31+X45+X61 -> 0 | H18: 김종훈/김희영 | J18: 0.2 | N18: 송대영 | O18: 실장 | P18: DSA(K-LAO) | Q18: 0.05 | U18: 최현석 | W18: 0.05
H19: 김지훈 | J19: 0.05 | N19: 김민우 | O19: 법인장 | P19: DGB 라오 리싱 | Q19: 0.05
H20: 김창수 | J20: 0.05 | L20: 지방배송 | N20: 오유근/김연희 | O20: 법인장 | P20: 코웨포-라오 인터내셔널 | Q20: 0.05
B21: 현지 발생 비용 | H21: 김필립/이은영 | J21: 0.05 | N21: 유병문 | O21: 법인장 | P21: 현진라오 | Q21: 0.05 | U21: 할인 총합 | X21: =SUM(X9:X20) -> 0
B22: 날짜 | C22: 내 용 | D22: 킵 | H22: 박정민 | J22: 0.05 | N22: 최병한 | O22: 부사장 | P22: 삼안 | Q22: 0.05
H23: 박종복 | J23: 0.05 | N23: 이범주 | O23: 단장, 전무 | P23: 삼안 | Q23: 0.05 | U23: 아파트 고객 할인
H24: 박진경 | I24: 본죽 | J24: 0.05 | N24: 이성한 | O24: 상무 | P24: 한국종합기술 | Q24: 0.05 | U24: 이름 | W24: 할인율 | X24: 할인금액 | Y24: 비 고
H25: 박창성 | J25: 0.05 | N25: 주인현 | O25: 법인장 | P25: KB 코라오 리싱 | Q25: 0.05 | U25: 이동현 | V25: 101호 고객 | W25: 0.05
H26: 백규현 | I26: 샤론스쿨 | J26: 0.05 | N26: 이재원 | O26: 대표 | P26: 그린굿스 | Q26: 0.05 | U26: 정민주 | V26: 206호 고객 | W26: 0.05
H27: 백대식 | J27: 0.05 | N27: 이재현 | O27: 법인장 | P27: Paul Golden Lao(좋은차닷컴) | Q27: 0.05
D28: =SUM(D23:D27) -> 0 | E28: =D28/C3 -> 0 | H28: 백상호 | J28: 0.05 | N28: 이제원 | O28: 법인장 | P28: 웰컴 리싱 라오 | Q28: 0.05
H29: 백운송 | J29: 0.05 | N29: 박준규/간현진/ 박세연/이종원 | P29: KOTRA | Q29: 0.05
B30: 총 합산 액 | C30: =C16-E28 -> 147.84 | H30: 백총명 | J30: 0.05 | N30: 이창열 | O30: 부장 | P30: 라오스증권거래소 | Q30: 0.05
H31: 변종승 | I31: 기쁜교회 | J31: 0.05 | N31: 이현열 | O31: 지점장 | P31: 에어부산 | Q31: 0.05 | U31: 할인 총합 | X31: =SUM(X25:X30) -> 0
H32: 손사랑 | J32: 0.05 | L32: 지방배송 | N32: 임정민 | O32: 지점장 | P32: 제주항공 | Q32: 0.05
H33: 신라함/신대웅 | J33: 0.05 | N33: 정석진 | O33: 지사장 | P33: CJ대한통운 라오스사무소 | Q33: 0.05 | U33: 기업 할인
H34: 우상봉 | J34: 0.05 | N34: 최완식/고대종 | O34: 단장 | P34: 솔루텍시스템 라오 | Q34: 0.05 | U34: 이름 | V34: 제품 | W34: 할인율 | X34: 할인금액 | Y34: 비 고
H35: 원순연 | J35: 0.05 | L35: 지방배송 | N35: 한태원 | O35: CEO | P35: 엘에스엠 | Q35: 0.05 | U35: Love STK | V35: 다단계제품 | W35: 0.05
H36: 곽낭아/이경희 | J36: 0.05 | L36: 지방배송 | N36: 황헌기 | O36: 대표 | P36: 정원상사 | Q36: 0.05 | U36: Nice to meat you | W36: 0.05
H37: 이관택/정유은 | J37: 0.05 | N37: 강남규 | O37: 부장 | P37: emart | Q37: 0.05 | U37: Peter Kim/Viengchay | V37: 성경책 | W37: 0.05
H38: 이규상 | J38: 0.05 | N38: 정길영 | O38: 행장 | P38: 부영라오은행 | Q38: 0.05 | U38: 김현민/라오스 국가대표 야구 감독 | W38: 0.05 | Y38: 대량 5%, 기부품 10% (사진 첨부 필)
H39: 이명숙/임기환 | J39: 0.05 | N39: 박대성 | O39: 차장 | P39: 부영라오 골프장 | Q39: 0.05 | U39: 이우용 | V39: 유투버 | W39: 0.05 | Y39: 지방배송
H40: 이병목/장혜진 | J40: 0.05 | N40: 이성한 | O40: 상무 | P40: 한국종합기술 | Q40: 0.05 | U40: 배상국/정창옥 | W40: 0.05 | Y40: 대량 10%
H41: 이상미 | J41: 0.05 | N41: 김승용 | O41: 대표이사 | P41: 코코넛샤일로 | Q41: 0.05 | U41: 참앤들/Lamthong Trading Co.,Ltd/ 권세욱/Wisit Limphothong | V41: 화장품 | W41: 0.05 | Y41: By KOTRA
...

Sheet 수취인 불명 내역
A1: 영수 번호 | B1: 송장 번호 | C1: Remark
A2: LK81 | B2: 5593-8870-9956 | C2: 김인규??
A3: LK82 | B3: 10-2664-5564-6053, 382-7242-2753
A4: LK83 | B4: 5903-7235-0543, 5903-7199-0220
A5: LK84 | B5: 66597-0117-4099 | C5: 이우용??
A6: LK85 | B6: 6856-8748-0750
A7: LK86 | B7: 66017-0128-0372
A8: LK87 | B8: 65689-0106-6533
A9: LK88 | B9: 5796-5801-8672 | C9: 송인호 고객물류로 추정됨 / 박주유 님이 한국에서 보내신 물건으로 추정
A10: LK89 | B10: 5909-8013-8342 | C10: 폼마린??
A11: LK90 | B11: 65129-0112-6372
A12: LK91 | B12: 64134-0322-0901, 64134-0322-0902 | C12: 박주유
A13: LK92 | B13: 6105072440050, 4107032440085, 3132212443441
A14: LK93 | B14: 10-2672-2107-9721, 10-2672-2107-9964, 10-2672-2107-5613, 10-2672-2107-8553, 10-2672-2107-5731 | C14: 박환영??
B15: 2601-402-015153
A16: LK94 | B16: 2484-9497-0570
A17: LK95 | B17: 3647-7561-7276

Sheet LKA 01
C1: Kor-Lao Air 가견적서 | L1: 구획(Zone) | R1: =D16 -> 1 | T1: 화폐 | U1: 기준 환율 | V1: 추가 환율 | W1: 적용 환율
A2: 회사명 | B2: 엘케이(LK)무역 | D2: 도착일 | E2: 2026-xx-xx | I2: 고객명/회사명 // 영수 번호 | L2: 이름 | R2: =N21 -> 147.84 | T2: USD-KIP | U2: ='Row data'!C3 -> 23000 | V2: 1000 | W2: =U2+V2 -> 24000
A3: 회사 주소 | B3: 비엔티엔시, 씨싿따낙구, 싸판텅 느아 09, 11번 골목, 엘케이(LK) 빌딩, 1층 LK Trading | T3: USD-THB | U3: ='Row data'!C4 -> 33 | V3: 1 | W3: =U3+V3 -> 34
A4: 전화번호 | B4: 020-9112-6780 | I4: 고객 연락처/회사 연락처 | L4: 전화번호 | T4: USD-WON | U4: ='Row data'!C5 -> 1515 | V4: 30 | W4: =U4+V4 -> 1545
A5: No. | B5: 종류 | C5: 단가 | D5: 수량 | E5: 실제중량(Kg) | F5: 실제중량 합산(kg) | G5: 규격 (cm) | J5: 용적 중량(kg) | K5: 용적중량 합산(Kg) | L5: 실제중량 운임 | M5: 용적중량 운임 | N5: 청구중량 운임
A6: 1 | B6: 잡화 | C6: =IF(" "=D6," ",IF(0<D6,14)) -> 14 | D6: 1 | E6: 8.6 | F6: =IFERROR(D6*E6," ") -> 8.6 | G6: 40 | H6: 30 | I6: 40 | J6: =IFERROR((G6*H6*I6)*0.00022," ") -> 10.56 | K6: =IFERROR(J6*D6," ") -> 10.56 | L6: =IFERROR((IF(0=F6*C6,0,IF(14>=C6*F6,14,C6*F6)))," ") -> 120.4 | M6: =IFERROR((IF(0=K6*C6,0,IF(14>=K6*C6,14,K6*C6)))," ") -> 147.84 | N6: =MAX(L6:M6) -> 147.84
A7: 2 | B7: =IFERROR(VLOOKUP($N$2&"_"&$A7,#REF!,2,0)," ") | C7: =IF(" "=D7," ",IF(0<D7,14)) | D7: =IFERROR(VLOOKUP($N$2&"_"&$A7,#REF!,9,0)," ") | E7: =IFERROR(INDEX(#REF!,MATCH($B7,#REF!,0),9)," ") | F7: =IFERROR(D7*E7," ") | G7: =IFERROR(INDEX(#REF!,MATCH($B7,#REF!,0),10)," ") | H7: =IFERROR(INDEX(#REF!,MATCH($B7,#REF!,0),11)," ") | I7: =IFERROR(INDEX(#REF!,MATCH($B7,#REF!,0),12)," ") | J7: =IFERROR((G7*H7*I7)*0.00022," ") | K7: =IFERROR(J7*D7," ") | L7: =IFERROR((IF(0=F7*C7,0,IF(14>=C7*F7,14,C7*F7)))," ") | M7: =IFERROR((IF(0=K7*C7,0,IF(14>=K7*C7,14,K7*C7)))," ") | N7: =MAX(L7:M7) -> 0
A8: 3 | B8: =IFERROR(VLOOKUP($N$2&"_"&$A8,#REF!,2,0)," ") | C8: =IF(" "=D8," ",IF(0<D8,14)) | D8: =IFERROR(VLOOKUP($N$2&"_"&$A8,#REF!,9,0)," ") | E8: =IFERROR(INDEX(#REF!,MATCH($B8,#REF!,0),9)," ") | F8: =IFERROR(D8*E8," ") | G8: =IFERROR(INDEX(#REF!,MATCH($B8,#REF!,0),10)," ") | H8: =IFERROR(INDEX(#REF!,MATCH($B8,#REF!,0),11)," ") | I8: =IFERROR(INDEX(#REF!,MATCH($B8,#REF!,0),12)," ") | J8: =IFERROR((G8*H8*I8)*0.00022," ") | K8: =IFERROR(J8*D8," ") | L8: =IFERROR((IF(0=F8*C8,0,IF(14>=C8*F8,14,C8*F8)))," ") | M8: =IFERROR((IF(0=K8*C8,0,IF(14>=K8*C8,14,K8*C8)))," ") | N8: =MAX(L8:M8) -> 0
A9: 4 | B9: =IFERROR(VLOOKUP($N$2&"_"&$A9,#REF!,2,0)," ") | C9: =IF(" "=D9," ",IF(0<D9,14)) | D9: =IFERROR(VLOOKUP($N$2&"_"&$A9,#REF!,9,0)," ") | E9: =IFERROR(INDEX(#REF!,MATCH($B9,#REF!,0),9)," ") | F9: =IFERROR(D9*E9," ") | G9: =IFERROR(INDEX(#REF!,MATCH($B9,#REF!,0),10)," ") | H9: =IFERROR(INDEX(#REF!,MATCH($B9,#REF!,0),11)," ") | I9: =IFERROR(INDEX(#REF!,MATCH($B9,#REF!,0),12)," ") | J9: =IFERROR((G9*H9*I9)*0.00022," ") | K9: =IFERROR(J9*D9," ") | L9: =IFERROR((IF(0=F9*C9,0,IF(14>=C9*F9,14,C9*F9)))," ") | M9: =IFERROR((IF(0=K9*C9,0,IF(14>=K9*C9,14,K9*C9)))," ") | N9: =MAX(L9:M9) -> 0
A10: 5 | B10: =IFERROR(VLOOKUP($N$2&"_"&$A10,#REF!,2,0)," ") | C10: =IF(" "=D10," ",IF(0<D10,14)) | D10: =IFERROR(VLOOKUP($N$2&"_"&$A10,#REF!,9,0)," ") | E10: =IFERROR(INDEX(#REF!,MATCH($B10,#REF!,0),9)," ") | F10: =IFERROR(D10*E10," ") | G10: =IFERROR(INDEX(#REF!,MATCH($B10,#REF!,0),10)," ") | H10: =IFERROR(INDEX(#REF!,MATCH($B10,#REF!,0),11)," ") | I10: =IFERROR(INDEX(#REF!,MATCH($B10,#REF!,0),12)," ") | J10: =IFERROR((G10*H10*I10)*0.00022," ") | K10: =IFERROR(J10*D10," ") | L10: =IFERROR((IF(0=F10*C10,0,IF(14>=C10*F10,14,C10*F10)))," ") | M10: =IFERROR((IF(0=K10*C10,0,IF(14>=K10*C10,14,K10*C10)))," ") | N10: =MAX(L10:M10) -> 0
A11: 6 | B11: =IFERROR(VLOOKUP($N$2&"_"&$A11,#REF!,2,0)," ") | C11: =IF(" "=D11," ",IF(0<D11,14)) | D11: =IFERROR(VLOOKUP($N$2&"_"&$A11,#REF!,9,0)," ") | E11: =IFERROR(INDEX(#REF!,MATCH($B11,#REF!,0),9)," ") | F11: =IFERROR(D11*E11," ") | G11: =IFERROR(INDEX(#REF!,MATCH($B11,#REF!,0),10)," ") | H11: =IFERROR(INDEX(#REF!,MATCH($B11,#REF!,0),11)," ") | I11: =IFERROR(INDEX(#REF!,MATCH($B11,#REF!,0),12)," ") | J11: =IFERROR((G11*H11*I11)*0.00022," ") | K11: =IFERROR(J11*D11," ") | L11: =IFERROR((IF(0=F11*C11,0,IF(14>=C11*F11,14,C11*F11)))," ") | M11: =IFERROR((IF(0=K11*C11,0,IF(14>=K11*C11,14,K11*C11)))," ") | N11: =MAX(L11:M11) -> 0
A12: 7 | B12: =IFERROR(VLOOKUP($N$2&"_"&$A12,#REF!,2,0)," ") | C12: =IF(" "=D12," ",IF(0<D12,14)) | D12: =IFERROR(VLOOKUP($N$2&"_"&$A12,#REF!,9,0)," ") | E12: =IFERROR(INDEX(#REF!,MATCH($B12,#REF!,0),9)," ") | F12: =IFERROR(D12*E12," ") | G12: =IFERROR(INDEX(#REF!,MATCH($B12,#REF!,0),10)," ") | H12: =IFERROR(INDEX(#REF!,MATCH($B12,#REF!,0),11)," ") | I12: =IFERROR(INDEX(#REF!,MATCH($B12,#REF!,0),12)," ") | J12: =IFERROR((G12*H12*I12)*0.00022," ") | K12: =IFERROR(J12*D12," ") | L12: =IFERROR((IF(0=F12*C12,0,IF(14>=C12*F12,14,C12*F12)))," ") | M12: =IFERROR((IF(0=K12*C12,0,IF(14>=K12*C12,14,K12*C12)))," ") | N12: =MAX(L12:M12) -> 0
A13: 8 | B13: =IFERROR(VLOOKUP($N$2&"_"&$A13,#REF!,2,0)," ") | C13: =IF(" "=D13," ",IF(0<D13,14)) | D13: =IFERROR(VLOOKUP($N$2&"_"&$A13,#REF!,9,0)," ") | E13: =IFERROR(INDEX(#REF!,MATCH($B13,#REF!,0),9)," ") | F13: =IFERROR(D13*E13," ") | G13: =IFERROR(INDEX(#REF!,MATCH($B13,#REF!,0),10)," ") | H13: =IFERROR(INDEX(#REF!,MATCH($B13,#REF!,0),11)," ") | I13: =IFERROR(INDEX(#REF!,MATCH($B13,#REF!,0),12)," ") | J13: =IFERROR((G13*H13*I13)*0.00022," ") | K13: =IFERROR(J13*D13," ") | L13: =IFERROR((IF(0=F13*C13,0,IF(14>=C13*F13,14,C13*F13)))," ") | M13: =IFERROR((IF(0=K13*C13,0,IF(14>=K13*C13,14,K13*C13)))," ") | N13: =MAX(L13:M13) -> 0
A14: 9 | B14: =IFERROR(VLOOKUP($N$2&"_"&$A14,#REF!,2,0)," ") | C14: =IF(" "=D14," ",IF(0<D14,14)) | D14: =IFERROR(VLOOKUP($N$2&"_"&$A14,#REF!,9,0)," ") | E14: =IFERROR(INDEX(#REF!,MATCH($B14,#REF!,0),9)," ") | F14: =IFERROR(D14*E14," ") | G14: =IFERROR(INDEX(#REF!,MATCH($B14,#REF!,0),10)," ") | H14: =IFERROR(INDEX(#REF!,MATCH($B14,#REF!,0),11)," ") | I14: =IFERROR(INDEX(#REF!,MATCH($B14,#REF!,0),12)," ") | J14: =IFERROR((G14*H14*I14)*0.00022," ") | K14: =IFERROR(J14*D14," ") | L14: =IFERROR((IF(0=F14*C14,0,IF(14>=C14*F14,14,C14*F14)))," ") | M14: =IFERROR((IF(0=K14*C14,0,IF(14>=K14*C14,14,K14*C14)))," ") | N14: =MAX(L14:M14) -> 0
A15: 10 | B15: =IFERROR(VLOOKUP($N$2&"_"&$A15,#REF!,2,0)," ") | C15: =IF(" "=D15," ",IF(0<D15,14)) | D15: =IFERROR(VLOOKUP($N$2&"_"&$A15,#REF!,9,0)," ") | E15: =IFERROR(INDEX(#REF!,MATCH($B15,#REF!,0),9)," ") | F15: =IFERROR(D15*E15," ") | G15: =IFERROR(INDEX(#REF!,MATCH($B15,#REF!,0),10)," ") | H15: =IFERROR(INDEX(#REF!,MATCH($B15,#REF!,0),11)," ") | I15: =IFERROR(INDEX(#REF!,MATCH($B15,#REF!,0),12)," ") | J15: =IFERROR((G15*H15*I15)*0.00022," ") | K15: =IFERROR(J15*D15," ") | L15: =IFERROR((IF(0=F15*C15,0,IF(14>=C15*F15,14,C15*F15)))," ") | M15: =IFERROR((IF(0=K15*C15,0,IF(14>=K15*C15,14,K15*C15)))," ") | N15: =MAX(L15:M15) -> 0
A16: 합 계 | D16: =SUM(D6:D15) -> 1 | F16: =SUM(F6:F15) -> 8.6 | K16: =SUM(K6:K15) -> 10.56
A17: Remark/비 고 | F17: Inland delivery/시내.지방 배송 | L17: 운임 총합 | N17: =SUM(N6:N16) -> 147.84
A18: - 동 가견적 운임의 중량 및 크기는 단순 예상치이므로 최종 책정 방법인 기준인 실측시 금액 차이가 발생 할수 있으니, 참고용으로만 확인 부탁 드립니다. - 운임은 USD 기준이며, 이외 화폐는 가견적 안내시의 환율 기준이므로, 최종 운임 책정시의 환율변동으로 인한 운임 차이가 발생할수 있으니, 참고용으로만 확인 부탁 드립니다. - 변동 유류값으로 인하여 매월 운임의 변동이 있을 수 있으니, 실제 선적 진행 시 꼭! 운임을 재차 확인 하시기 바랍니다. | L18: 할인 | M18: =IFERROR(MID($A$18,FIND(" "&$L$18&" ",$A$18)+4,3)," ") | N18: =IFERROR(N17*M18,0) -> 0
L19: 특별할인 | M19: =IFERROR(MID($A$18,FIND(" "&$L$19&" ",$A$18)+6,3)," ") | N19: =IFERROR(N17*M19,0) -> 0
L20: 세금 계산서(VAT) | M20: =IFERROR(IF(FIND("세금 계산서",$A$18),10%," ")," ") | N20: =IFERROR((N17-N18-N19)*M20,0) -> 0
L21: 최종 청구 금액 | M21: USD | N21: =(N17-N18-N19+N20) -> 147.84
M22: KIP | N22: =ROUNDUP((N21*$W$2),-3) -> 3549000
M23: THB | N23: =ROUNDUP((N21*$W$3),-1) -> 5030
M24: WON | N24: =ROUNDUP((N21*$W$4),-2) -> 228500
A26: * 모든 비용은 회사의 내규 및 각 물품의 중량/크기 실측을 기준으로 청구되며 최소 운임은 $14/kg 입니다.
A27: * 입.출고지를 떠나시기 전 꼭! 고객님 본인 물품 및 개수 확인 부탁 드립니다. 물품이 출고된 이후 LK그룹은 물품의 파손/분실에 대한 어떠한 책임도 없습니다.
A28: * 물품 도착 및 출고 후 특별한 사유 없이 장기 미수취 물품의 경우 보관료등 기타 추가 비용이 발생 할 수 있습니다.
A29: * 물품 출고 후 1주 후부터 보관료(최소 3불/CBM/day)가 발생하며, 특별한 사유 없이 2달 이상 보관 물품들은 임의로 폐기/처분 될 수 있습니다.
A30: 엘케이 (LK)무역 | H30: * 이용해 주셔서 감사합니다. | K30: 고객사 서명
