Workbook

Sheet Row data
B1: LK내부 환율
B2: 화폐 | C2: 기준 환율 | D2: 추가 환율 | E2: 적용 환율
B3: USD-KIP | C3: 23000 | D3: 1000 | E3: =C3+D3 -> 24000
B4: USD-THB | C4: 33 | D4: 1 | E4: =C4+D4 -> 34
B5: USD-WON | C5: 1515 | D5: 30 | E5: =C5+D5 -> 1545
B7: Kg 구간 | C7: 최소값 | D7: 적용 운임
B8: 0~1kg | C8: 0 | D8: 4
B9: 2~5kg | C9: 2 | D9: 2.5
B10: 6~9kg | C10: 6 | D10: 1.5
B11: 10~14kg | C11: 10 | D11: 1.25
B12: 15~17kg | C12: 15 | D12: 1.15
B13: 18~20kg | C13: 18 | D13: 1.13
B14: 21kg 이상 | C14: 21 | D14: 1.1
B17: 한국 세금 계산서 발급시 계좌번호
B18: 경남은행 2070133424601 박성호(엘케이무역)
B20: 일반 입금
B21: 경남은행 571-22-0330221 박성호
B23: 태국-라오스 내륙 xx항차
B24: Total | C24: =SUM('이름(TLxx-xx)'!R1) -> 1
B25: Amount | C25: =SUM('이름(TLxx-xx)'!R2) -> 0
B27: 총 할인 금액 | C27: =#REF!+#REF!+#REF!+#REF! -> #REF!
B30: 현지 발생 비용
B31: 날짜 | C31: 내 용 | D31: 킵
B32: 2024.10.10
B33: 2024.10.11
D36: =SUM(D32:D35) -> 0 | E36: =D36/C4 -> 0
B39: 총 합산 액 | C39: =C25-E36 -> 0

Sheet 수취인 불명 내역
A1: 영수 번호 | B1: 송장 번호 | C1: Remark
A2: LK81 | B2: 5593-8870-9956 | C2: 김인규??
A3: LK82 | B3: 10-2664-5564-6053, 382-7242-2753
A4: LK83 | B4: 5903-7235-0543, 5903-7199-0220
A5: LK84 | B5: 66597-0117-4099 | C5: 이우용??
A6: LK85 | B6: 6856-8748-0750
A7: LK86 | B7: 66017-0128-0372
A8: LK87 | B8: 65689-0106-6533
A9: LK88 | B9: 5796-5801-8672 | C9: 송인호 고객물류로 추정됨 / 박주유 님이 한국에서 보내신 물건으로 추정
A10: LK89 | B10: 5909-8013-8342 | C10: 폼마린??
A11: LK90 | B11: 65129-0112-6372
A12: LK91 | B12: 64134-0322-0901, 64134-0322-0902 | C12: 박주유
A13: LK92 | B13: 6105072440050, 4107032440085, 3132212443441
A14: LK93 | B14: 10-2672-2107-9721, 10-2672-2107-9964, 10-2672-2107-5613, 10-2672-2107-8553, 10-2672-2107-5731 | C14: 박환영??
B15: 2601-402-015153
A16: LK94 | B16: 2484-9497-0570
A17: LK95 | B17: 3647-7561-7276

Sheet 시내, 지방배송
A1: No. | B1: Name | C1: Name | D1: Tel | E1: Local company | F1: Destination Address | G1: Paid by
A2: 1 | B2: 구상채 / Oly | C2: Ku Sang Chae / Oly | D2: 020-5431-3355 020-5486-5440 | E2: HAL | F2: ສາຂາ ບ້ານ ປ່າອອ້ຍ, ຫວ້ຍຊາຍ, ບໍ່ແກ້ວ
E3: ANS
A4: 2 | B4: 김석현 | C4: KIM, Sukhyun | D4: 020-5566-8605 | E4: HAL | F4: Savannaket (ສາຂາ ຕະຫຼາດ ໃຫຍ່)
E5: ANS
A6: 3 | B6: 김영훈/010 2490 9081 | C6: KIM YoungHoon | D6: 020 9637 1027 | E6: HAL | F6: ສາຂາ ຫນອງຂຽວ, ເມືອງງອຍ
E7: ANS
A8: 4 | B8: 김정호 | C8: Mr. KIM Jung Ho | D8: '020-9697-1366 | E8: HAL | F8: Namngam village, paek district, xiengkhuang provice
E9: ANS
A10: 5 | B10: 김창수 | C10: Kim chang soo | D10: 020-5202-6723 | E10: HAL | F10: ແຟຣນຊີບມໍ
E11: ANS
A12: 6 | B12: 나유리 | C12: Ms. NA Yoo Ri | D12: 020-5538-6544 | E12: HAL | F12: LPB province
E13: ANS
A14: 7 | B14: 남미화 | C14: NAM, Mi Hwa | D14: 020 9593 7554 | E14: HAL | F14: ສາຂາ ບ້ານຊຽງມ່ວນ (ຕະຫລາດມືດ), ເມືອງຫລວງພະບາງ, ຫລວງພະບາງ
E15: ANS
A16: 8 | B16: 남윤천 | C16: NAM Yun Cheon | D16: '020-5550-8172 | E16: HAL | F16: ບ້ານມີໄຊ, Paksan, Bolikhamxai
E17: ANS
A18: 9 | B18: 문종곤 | C18: Mr. MOON Joong Gon | D18: '020-9956-0707 | E18: HAL | F18: Pakse city
E19: ANS
A20: 10 | B20: 백원상 | C20: Mr. BAIK woon song | D20: 020-5605-1991 | E20: HAL | F20: ປາຍທາງ xieng mouak village LPB district, LPB province
E21: ANS
A22: 11 | B22: 손사랑 | C22: Mr. SON Sa Rang | D22: 020-5959-1790 | E22: HAL | F22: Luangprabang city
E23: ANS
A24: 12 | B24: 쑤빈 | C24: Soubin | D24: 020-7777-1940 020-528-83018 | E24: HAL | F24: ກາສີ, ຕົວເມືອງກາສີ
E25: ANS
A26: 13 | B26: 우형철 | C26: Mr. WOO Hyung Chu | D26: 020-9505-3052 | E26: HAL | F26: PAKSE km8
E27: ANS
A28: 14 | B28: 윤성식 | C28: Mr. YOON Sung Sik | D28: '020-9604-3012 | E28: HAL | F28: Ban Keun Napheng
E29: ANS
A30: 15 | B30: 곽낭아/이경희 | C30: LEE kyung hee/ຈຳປາລີ | D30: 020-9550-5260 020-9784-4110 | E30: HAL | F30: Oudomxay Muangxay ໜອງແມງດາ
E31: ANS | F31: ສາຂາ ບ້ານບໍ່ ເມືອງໄຊ ແຂວງອຸດົມໄຊ
E32: ບໍລິສັດ ບັນດິດຂົນສົ່ງ (ຊົມພູ) ນະຄອນຫລວງ - ອຸດົມໄຊ 030-5471650, 020-9998-8884, 5547-6377 | F32: ບ້ານບໍ່ ເມືອງໄຊ ແຂວງອຸດົມໄຊ
A33: 16 | B33: 이복희 | C33: LEE Bok Hee | D33: 020-5547-0797 | E33: HAL | F33: ສາຂາ ສຸນັນທາ, Savannaket
E34: ANS
A35: 17 | B35: 이상호 | C35: LEE sang ho | D35: 020-9552-2978 | E35: HAL | F35: ອັດຕາປື ສາມັກຄີໄຊ 1
E36: ANS
A37: 18 | B37: 이우용 | C37: Seevisai Manephong | D37: 020-5847-7710 | E37: HAL | F37: ສາຂາ ຫນອງຂຽວ, ເມືອງງອຍ, ຫລວງພະບາງ
E38: ANS | F38: ສາຂາ ປ່ອງຄຳ ເມືອງຫຼວງພະບາງ ແຂວງຫຼວງພະບາງ
A39: 19 | B39: 이존희 | C39: LEE Jonhee | D39: 020-5625-9292 | E39: HAL | F39: ອັດຕາປື ສາມັກຄີໄຊ 1
E40: ANS
...

Sheet 이름(TLxx-xx)
C1: Thai-Lao Trucking 거래 명세서 | L1: 번호(No.) | M1: LKTL2026xx-xx | R1: =D11 -> 1 | T1: 화폐 | U1: 기준 환율 | V1: 추가 환율 | W1: 적용 환율
A2: 회사명 | B2: 엘케이(LK)무역 | D2: 도착일 | E2: 2026-XX-XX | I2: 고객명/회사명 // 영수 번호 | L2: 고객이름 | R2: =N16 -> 0 | T2: USD-KIP | U2: ='Row data'!C3 -> 23000 | V2: 1000 | W2: =U2+V2 -> 24000
A3: 회사 주소 | B3: 비엔티엔시, 씨싿따낙구, 싸판텅 느아 09, 11번 골목, 엘케이(LK) 빌딩, 1층 LK Trading | T3: USD-THB | U3: ='Row data'!C4 -> 33 | V3: 1 | W3: =U3+V3 -> 34
A4: 전화번호 | B4: 020-9112-6780 | I4: 고객 연락처/회사 연락처 | L4: 전화번호 | T4: USD-WON | U4: ='Row data'!C5 -> 1515 | V4: 30 | W4: =U4+V4 -> 1545
A5: No. | B5: 종류 | C5: 단가 | D5: 수량 | E5: 실제중량(Kg) | F5: 실제중량 합산(kg) | G5: 규격 (cm) | J5: 용적 중량(kg) | K5: 용적중량 합산(Kg) | L5: 실제중량 운임 | M5: 용적중량 운임 | N5: 청구중량 운임
A6: 1 | B6: TL01-01 | C6: =VLOOKUP(MAX(E6,J6),'Row data'!$C$8:$D$14,2,TRUE) -> 4 | D6: 1 | F6: =E6*D6 -> 0 | J6: =(G6*H6*I6)*0.00022 -> 0 | K6: =J6*D6 -> 0 | L6: =(IF(0=F6*C6,0,IF('Row data'!$D$8>=C6*F6,'Row data'!$D$8,C6*F6))) -> 0 | M6: =(IF(0=K6*C6,0,IF('Row data'!$D$8>=K6*C6,'Row data'!$D$8,K6*C6))) -> 0 | N6: =MAX(L6:M6) -> 0
A7: 2
A8: 3
A9: 4
A10: 5
A11: 합 계 | D11: =SUM(D6:D10) -> 1 | F11: =SUM(F6:F10) -> 0 | K11: =SUM(K6:K10) -> 0
A12: Remark/비 고 | F12: Inland delivery/시내.지방 배송 | L12: 운임 총합 | N12: =SUM(N6:N11) -> 0
L13: 할인 | M13: =IFERROR(MID($A$13,FIND(" "&$L$13&" ",$A$13)+4,3)," ") | N13: =IFERROR(N12*M13,0) -> 0
L14: 특별할인 | M14: =IFERROR(MID($A$13,FIND(" "&$L$14&" ",$A$13)+6,3)," ") | N14: =IFERROR(N12*M14,0) -> 0
L15: 세금 계산서(VAT) | M15: =IFERROR(IF(FIND("세금 계산서",$A$13),10%," ")," ") | N15: =IFERROR((N12-N13-N14)*M15,0) -> 0
L16: 최종 청구 금액 | M16: USD | N16: =(N12-N13-N14+N15) -> 0
M17: KIP | N17: =ROUNDUP((N16*$W$2),-3) -> 0
M18: THB | N18: =ROUNDUP((N16*$W$3),-1) -> 0
M19: WON | N19: =ROUNDUP((N16*$W$4),-2) -> 0
A21: * 모든 비용은 회사의 내규 및 각 물품의 중량/크기 실측을 기준으로 청구되며 최소 운임은 $4/kg 이며, 청구중량에 따라 차등 운임이 적용 됩니다.
A22: * 입.출고지를 떠나시기 전 꼭! 고객님 본인 물품 및 개수 확인 부탁 드립니다. 물품이 출고된 이후 LK그룹은 물품의 파손/분실에 대한 어떠한 책임도 없습니다.
A23: * 물품 도착 및 출고 후 특별한 사유 없이 장기 미수취 물품의 경우 보관료등 기타 추가 비용이 발생 할 수 있습니다.
A24: * 물품 출고 후 1주 후부터 보관료(최소 3불/CBM/day)가 발생하며, 특별한 사유 없이 2달 이상 보관 물품들은 임의로 폐기/처분 될 수 있습니다.
A25: 엘케이 (LK)무역 | H25: * 이용해 주셔서 감사합니다. | K25: 고객사 서명

Sheet Sheet1
A1: PSV | C1: 32 | E1: 1.35 | H1: JJ | J1: 32 | L1: 1.35
A2: KG | B2: Rate(THB) | C2: Rate(USD) | D2: per kg(USD) | H2: KG | I2: Rate(THB) | J2: Rate(USD) | K2: per kg(USD)
A3: 0.5 | B3: 50 | C3: =B3/$C$1 -> 1.5625 | D3: =C3/A3 -> 3.125 | E3: =D3*$E$1 -> 4.21875 | H3: 0.5 | I3: 50 | J3: =I3/$J$1 -> 1.5625 | K3: =J3/H3 -> 3.125 | L3: =K3*$L$1 -> 4.21875
A4: 1 | B4: 60 | C4: =B4/$C$1 -> 1.875 | D4: =C4/A4 -> 1.875 | E4: =D4*$E$1 -> 2.53125 | H4: 1 | I4: 70 | J4: =I4/$J$1 -> 2.1875 | K4: =J4/H4 -> 2.1875 | L4: =K4*$L$1 -> 2.953125
A5: 1.5 | B5: 70 | C5: =B5/$C$1 -> 2.1875 | D5: =C5/A5 -> 1.4583333 | E5: =D5*$E$1 -> 1.96875 | H5: 1.5 | I5: 80 | J5: =I5/$J$1 -> 2.5 | K5: =J5/H5 -> 1.6666667 | L5: =K5*$L$1 -> 2.25
A6: 2 | B6: 80 | C6: =B6/$C$1 -> 2.5 | D6: =C6/A6 -> 1.25 | E6: =D6*$E$1 -> 1.6875 | H6: 2 | I6: 90 | J6: =I6/$J$1 -> 2.8125 | K6: =J6/H6 -> 1.40625 | L6: =K6*$L$1 -> 1.8984375
A7: 2.5 | B7: 90 | C7: =B7/$C$1 -> 2.8125 | D7: =C7/A7 -> 1.125 | E7: =D7*$E$1 -> 1.51875 | H7: 2.5 | I7: 100 | J7: =I7/$J$1 -> 3.125 | K7: =J7/H7 -> 1.25 | L7: =K7*$L$1 -> 1.6875
A8: 3 | B8: 120 | C8: =B8/$C$1 -> 3.75 | D8: =C8/A8 -> 1.25 | E8: =D8*$E$1 -> 1.6875 | H8: 3 | I8: 110 | J8: =I8/$J$1 -> 3.4375 | K8: =J8/H8 -> 1.1458333 | L8: =K8*$L$1 -> 1.546875
A9: 4 | B9: 145 | C9: =B9/$C$1 -> 4.53125 | D9: =C9/A9 -> 1.1328125 | E9: =D9*$E$1 -> 1.5292969 | H9: 4 | I9: 125 | J9: =I9/$J$1 -> 3.90625 | K9: =J9/H9 -> 0.9765625 | L9: =K9*$L$1 -> 1.3183594
A10: 5 | B10: 170 | C10: =B10/$C$1 -> 5.3125 | D10: =C10/A10 -> 1.0625 | E10: =D10*$E$1 -> 1.434375 | H10: 5 | I10: 140 | J10: =I10/$J$1 -> 4.375 | K10: =J10/H10 -> 0.875 | L10: =K10*$L$1 -> 1.18125
A11: 6 | B11: 195 | C11: =B11/$C$1 -> 6.09375 | D11: =C11/A11 -> 1.015625 | E11: =D11*$E$1 -> 1.3710938 | H11: 6 | I11: 160 | J11: =I11/$J$1 -> 5 | K11: =J11/H11 -> 0.83333333 | L11: =K11*$L$1 -> 1.125
A12: 7 | B12: 220 | C12: =B12/$C$1 -> 6.875 | D12: =C12/A12 -> 0.98214286 | E12: =D12*$E$1 -> 1.3258929 | H12: 7 | I12: 175 | J12: =I12/$J$1 -> 5.46875 | K12: =J12/H12 -> 0.78125 | L12: =K12*$L$1 -> 1.0546875
A13: 8 | B13: 240 | C13: =B13/$C$1 -> 7.5 | D13: =C13/A13 -> 0.9375 | E13: =D13*$E$1 -> 1.265625 | H13: 8 | I13: 200 | J13: =I13/$J$1 -> 6.25 | K13: =J13/H13 -> 0.78125 | L13: =K13*$L$1 -> 1.0546875
A14: 9 | B14: 265 | C14: =B14/$C$1 -> 8.28125 | D14: =C14/A14 -> 0.92013889 | E14: =D14*$E$1 -> 1.2421875 | H14: 9 | I14: 220 | J14: =I14/$J$1 -> 6.875 | K14: =J14/H14 -> 0.76388889 | L14: =K14*$L$1 -> 1.03125
... A55: 50 | B55: 1040 | C55: =B55/$C$1 -> 32.5 | D55: =C55/A55 -> 0.65 | E55: =D55*$E$1 -> 0.8775 | H55: 50 | I55: 1100 | J55: =I55/$J$1 -> 34.375 | K55: =J55/H55 -> 0.6875 | L55: =K55*$L$1 -> 0.928125

Sheet Sheet2
A1: Kg 구간 | B1: 적용 운임
A2: 0~1kg | B2: 4
A3: 2~5kg | B3: 2.5
A4: 6~9kg | B4: 1.5
A5: 10~14kg | B5: 1.25
A6: 15~17kg | B6: 1.15
A7: 18~20kg | B7: 1.13
A8: 21kg 이상 | B8: 1.1
